Workbook

Sheet BD
S1: Alto : | Y1: H | Z1: =MID(AA1,1,2) -> 22 | AA1: 2200
S2: Ancho : | Y2: W | Z2: =MID(AA2,1,2) -> 72 | AA2: 720
S3: Profundo: | Y3: D | Z3: =MID(AA3,1,2) -> 60 | AA3: 600
S4: IP: | AA4: 30 | AD4: 1 | AE4: 2 | AF4: 3 | AG4: 4 | AH4: 5 | AI4: 6 | AJ4: 7 | AK4: 8 | AL4: 9 | AM4: 10 | AN4: 11 | AO4: 12 | AP4: 13 | AQ4: 14 | AR4: 15 | AS4: 16 | AT4: 17 | AU4: 18 | AV4: 19 | AW4: 20 | AX4: 21 | BH4: Caracteristicas | BL4: HBB | CF4: VBB
B5: Codigo | C5: Categoria | D5: Codigo | E5: SubCodigo1 | F5: SubCodigo2 | G5: Alto | I5: Ancho | K5: Profundo | M5: Criterio1 | N5: Criterio2 | O5: Criterio3 | P5: Criterio4 | Q5: Definición | U5: Categoria | V5: Criterio5 | W5: Criterio1 | X5: Criterio2 | Y5: Criterio3 | Z5: CodigoB | AA5: Codigo | AD5: REFERENCIA | AE5: Info | AG5: Tipo | AH5: Linea | AI5: Orientacion | AJ5: Montaje | AK5: Operacion0 | AL5: Ancho | AM5: Profundo | AN5: Topping | AO5: REFERENCIA | AV5: FM | AW5: PM | AX5: Definicion | BJ5: Icc | BK5: In | BL5: W (mm) | BM5: Codigo | BN5: Interruptor | BO5: 100 A | BP5: 250 A | BQ5: 400 A | BR5: 630 A | BS5: 800 A | BT5: 1000 A | BU5: 1250 A | BV5: 1600 A | BW5: 2000 A | BX5: 2500 A | BY5: 3200 A | BZ5: 4000 A | CF5: L(mm) | CG5: Codigo | CH5: Interruptor | CI5: 100 A | CJ5: 250 A | CK5: 400 A | CL5: 630 A | CM5: 800 A | CN5: 1000 A | CO5: 1250 A | CP5: 1600 A
A6: 1 | B6: =MID(H6,1,2)&MID(J6,1,2)&MID(L6,1,2)&MID(C6,1,2)&MID(M6,1,1)&MID(N6,1,1)&MID(O6,1,1)&MID(P6,1,3) -> 182040Ma | C6: Marco | D6: 017000 | E6: 014000 | F6: 010020 | G6: =IF(H6<>"","H:","") -> H: | H6: 1800 | I6: =IF(J6<>"","W:","") -> W: | J6: 200 | K6: =IF(L6<>"","D:","") -> D: | L6: 400 | Q6: =IF(B6<>"",(C6&M6&N6&O6&P6&" / "&G6&H6&I6&J6&K6&L6&" mm"),"") -> Marco / H:1800W:200D:400 mm | S6: 1.1.1. | T6: Marco | U6: Ma | V6: =Z1&Z2&Z3 -> 227260 | Z6: =V6&U6&MID(W6,1,1)&MID(X6,1,1)&MID(Y6,1,3) -> 227260Ma | AA6: =VLOOKUP(Z6,$B$6:$D$470,3,FALSE) -> 017033 | AD6: =AO6&AP6&AQ6&AR6&AS6&AT6&AN6&AU6 -> IMBVFPW2- | AE6: UF. | AF6: de | AG6: Integrada | AH6: Mini Breaker | AI6: Vertical | AJ6: Fijo | AK6: Palanca | AL6: W:400 | AN6: - | AO6: =MID(AG6,1,1) -> I | AP6: {=IFERROR(_xlfn.IFS(AH6="Mini Breaker ","MB",AH6="GoPact ","GP",AH6="EZC 100 ","EZ1",AH6="EZC 250 ","EZ2",AH6="CVS/NSX 250 ","CV2",AH6="CVS/NSX/EZC 630 ","CV6",AH6="NS 1600 ","NS1",AH6="NW/MTZ 4000 ","NW4",AH6="Conmutador PEQ. ","CP",AH6="Conmutador MED. ","CM",AH6="Conmutador GRA. ","CG",AH6="Contactores ","CK"),"")} -> MB | AQ6: {=_xlfn.IFS(AI6="Horizontal ","H",AI6="Horizontal COMPUESTA ","HC",AI6="Vertical ","V",AI6="Vertical Compacta ","VC",AI6="Vertical Extendida ","VE")} -> V | AR6: =MID(AJ6,1,1) -> F | AS6: =MID(AK6,1,1) -> P | AT6: {=IFERROR(_xlfn.IFS(AL6="W:200 ","W1",AL6="W:400 ","W2",AL6="W:720 ","W3",AL6="W:800 ","W4",AL6="W:1120 ","W5"),"")} -> W2 | AU6: {=IFERROR(_xlfn.IFS(AM6="D:400 ","D1",AM6="D:600 ","D2",AM6="D:1000 ","D3"),"")} | AV6: 021125 | AW6: 024000 | AX6: =AE6&AF6&AH6&AI6&AJ6&AK6&AL6&AM6&AN6 -> UF. de Mini Breaker Vertical Fijo Palanca W:400 - | BB6: =BC6&BD6&BE6&BF6 -> 1AH | BC6: {=_xlfn.IFS(BJ6="10 - 25",1,BJ6="10 - 40",2,BJ6="10 - 65",3,BJ6="10 - 85",4)} -> 1 | BD6: {=_xlfn.IFS(BK6="630","A",BK6="1250","B",BK6="1600","C",BK6="2000","D",BK6="2500","E",BK6="3200","F",BK6="4000","G",BK6="5000","H",BK6="6300","I",BK6="7000","J")} -> A | BE6: H | BF6: {=IFERROR(_xlfn.IFS(BL6="400 + 400","X",BL6="720","Y",BL6="1120","Z"),"")} | BH6: TC | BJ6: 10 - 25 | BK6: 630 | BL6: - | BM6: - | BN6: EZC | BO6: - | BP6: - | BQ6: - | BR6: - | BS6: - | BT6: - | BU6: - | BV6: - | BW6: - | BX6: - | BY6: - | BZ6: - | CB6: =BC6&BD6&CC6&CD6 -> 1AVM | CC6: V | CD6: {=IFERROR(_xlfn.IFS(CF6="1/4","M",CF6="1/2","N",CF6="3/4","O",CF6="1","P"),"")} -> M | CF6: 1/4 | CG6: 037000 | CH6: EZC | CI6: 047001 | CJ6: 047002 | CK6: 047003 | CL6: 047004 | CM6: - | CN6: - | CO6: - | CP6: -
A7: 2 | B7: =MID(H7,1,2)&MID(J7,1,2)&MID(L7,1,2)&MID(C7,1,2)&MID(M7,1,1)&MID(N7,1,1)&MID(O7,1,1)&MID(P7,1,3) -> 182060Ma | C7: Marco | D7: 017001 | E7: 014001 | F7: 010020 | G7: =IF(H7<>"","H:","") -> H: | H7: 1800 | I7: =IF(J7<>"","W:","") -> W: | J7: 200 | K7: =IF(L7<>"","D:","") -> D: | L7: 600 | Q7: =IF(B7<>"",(C7&M7&N7&O7&P7&" / "&G7&H7&I7&J7&K7&L7&" mm"),"") -> Marco / H:1800W:200D:600 mm | S7: 1.1.2. | T7: Puerta/Marco liso | U7: Pu | V7: =Z1&Z2 -> 2272 | W7: Plena | Z7: =V7&U7&MID(W7,1,1)&MID(X7,1,1)&MID(Y7,1,3) -> 2272PuP | AA7: =VLOOKUP(Z7,$B$6:$D$470,3,FALSE) -> 014109 | AD7: =AO7&AP7&AQ7&AR7&AS7&AT7&AN7&AU7 -> IMBVFPW3- | AE7: UF. | AF7: de | AG7: Integrada | AH7: Mini Breaker | AI7: Vertical | AJ7: Fijo | AK7: Palanca | AL7: W:720 | AN7: - | AO7: =MID(AG7,1,1) -> I | AP7: {=IFERROR(_xlfn.IFS(AH7="Mini Breaker ","MB",AH7="GoPact ","GP",AH7="EZC 100 ","EZ1",AH7="EZC 250 ","EZ2",AH7="CVS/NSX 250 ","CV2",AH7="CVS/NSX/EZC 630 ","CV6",AH7="NS 1600 ","NS1",AH7="NW/MTZ 4000 ","NW4",AH7="Conmutador PEQ. ","CP",AH7="Conmutador MED. ","CM",AH7="Conmutador GRA. ","CG",AH7="Contactores ","CK"),"")} -> MB | AQ7: {=_xlfn.IFS(AI7="Horizontal ","H",AI7="Horizontal COMPUESTA ","HC",AI7="Vertical ","V",AI7="Vertical Compacta ","VC",AI7="Vertical Extendida ","VE")} -> V | AR7: =MID(AJ7,1,1) -> F | AS7: =MID(AK7,1,1) -> P | AT7: {=IFERROR(_xlfn.IFS(AL7="W:200 ","W1",AL7="W:400 ","W2",AL7="W:720 ","W3",AL7="W:800 ","W4",AL7="W:1120 ","W5"),"")} -> W3 | AU7: {=IFERROR(_xlfn.IFS(AM7="D:400 ","D1",AM7="D:600 ","D2",AM7="D:1000 ","D3"),"")} | AV7: 021050 | AW7: 024001 | AX7: =AE7&AF7&AH7&AI7&AJ7&AK7&AL7&AM7&AN7 -> UF. de Mini Breaker Vertical Fijo Palanca W:720 - | BB7: =BC7&BD7&BE7&BF7 -> 1AH | BC7: =BC6 -> 1 | BD7: =BD6 -> A | BE7: =BE6 -> H | BF7: {=IFERROR(_xlfn.IFS(BL7="400 + 400","X",BL7="720","Y",BL7="1120","Z"),"")} | BL7: - | BM7: - | BN7: CVS | BO7: - | BP7: - | BQ7: - | BR7: - | BS7: - | BT7: - | BU7: - | BV7: - | BW7: - | BX7: - | BY7: - | BZ7: - | CB7: =BC7&BD7&CC7&CD7 -> 1AVN | CC7: V | CD7: {=IFERROR(_xlfn.IFS(CF7="1/4","M",CF7="1/2","N",CF7="3/4","O",CF7="1","P"),"")} -> N | CF7: 1/2 | CG7: 037001 | CH7: CVS | CI7: 047005 | CJ7: 047006 | CK7: 047007 | CL7: 047008 | CM7: - | CN7: - | CO7: - | CP7: -
A8: 3 | B8: =MID(H8,1,2)&MID(J8,1,2)&MID(L8,1,2)&MID(C8,1,2)&MID(M8,1,1)&MID(N8,1,1)&MID(O8,1,1)&MID(P8,1,3) -> 182010Ma | C8: Marco | D8: 017002 | E8: 014002 | F8: 010020 | G8: =IF(H8<>"","H:","") -> H: | H8: 1800 | I8: =IF(J8<>"","W:","") -> W: | J8: 200 | K8: =IF(L8<>"","D:","") -> D: | L8: 1000 | Q8: =IF(B8<>"",(C8&M8&N8&O8&P8&" / "&G8&H8&I8&J8&K8&L8&" mm"),"") -> Marco / H:1800W:200D:1000 mm | S8: 1.1.3. | T8: Kit paneles laterales | U8: PaL | V8: =Z1&Z3 -> 2260 | W8: Pleno | Z8: =V8&U8&MID(W8,1,1)&MID(X8,1,1)&MID(Y8,1,3) -> 2260PaLP | AA8: =VLOOKUP(Z8,$B$6:$D$470,3,FALSE) -> 014032 | AD8: =AO8&AP8&AQ8&AR8&AS8&AT8&AN8&AU8 -> ICV2VCFPW3- | AE8: UF. | AF8: de | AG8: Integrada | AH8: CVS/NSX 250 | AI8: Vertical Compacta | AJ8: Fijo | AK8: Palanca | AL8: W:720 | AN8: - | AO8: =MID(AG8,1,1) -> I | AP8: {=IFERROR(_xlfn.IFS(AH8="Mini Breaker ","MB",AH8="GoPact ","GP",AH8="EZC 100 ","EZ1",AH8="EZC 250 ","EZ2",AH8="CVS/NSX 250 ","CV2",AH8="CVS/NSX/EZC 630 ","CV6",AH8="NS 1600 ","NS1",AH8="NW/MTZ 4000 ","NW4",AH8="Conmutador PEQ. ","CP",AH8="Conmutador MED. ","CM",AH8="Conmutador GRA. ","CG",AH8="Contactores ","CK"),"")} -> CV2 | AQ8: {=_xlfn.IFS(AI8="Horizontal ","H",AI8="Horizontal COMPUESTA ","HC",AI8="Vertical ","V",AI8="Vertical Compacta ","VC",AI8="Vertical Extendida ","VE")} -> VC | AR8: =MID(AJ8,1,1) -> F | AS8: =MID(AK8,1,1) -> P | AT8: {=IFERROR(_xlfn.IFS(AL8="W:200 ","W1",AL8="W:400 ","W2",AL8="W:720 ","W3",AL8="W:800 ","W4",AL8="W:1120 ","W5"),"")} -> W3 | AU8: {=IFERROR(_xlfn.IFS(AM8="D:400 ","D1",AM8="D:600 ","D2",AM8="D:1000 ","D3"),"")} | AV8: 021058 | AW8: 024002 | AX8: =AE8&AF8&AH8&AI8&AJ8&AK8&AL8&AM8&AN8 -> UF. de CVS/NSX 250 Vertical Compacta Fijo Palanca W:720 - | BB8: =BC8&BD8&BE8&BF8 -> 1AH | BC8: =BC7 -> 1 | BD8: =BD6 -> A | BE8: =BE7 -> H | BF8: {=IFERROR(_xlfn.IFS(BL8="400 + 400","X",BL8="720","Y",BL8="1120","Z"),"")} | BL8: - | BM8: - | BN8: NSX | BO8: - | BP8: - | BQ8: - | BR8: - | BS8: - | BT8: - | BU8: - | BV8: - | BW8: - | BX8: - | BY8: - | BZ8: - | CB8: =BC8&BD8&CC8&CD8 -> 1AVO | CC8: V | CD8: {=IFERROR(_xlfn.IFS(CF8="1/4","M",CF8="1/2","N",CF8="3/4","O",CF8="1","P"),"")} -> O | CF8: 3/4 | CG8: 037002 | CH8: NSX
A9: 4 | B9: =MID(H9,1,2)&MID(J9,1,2)&MID(L9,1,2)&MID(C9,1,2)&MID(M9,1,1)&MID(N9,1,1)&MID(O9,1,1)&MID(P9,1,3) -> 184040Ma | C9: Marco | D9: 017003 | E9: 014000 | F9: 010021 | G9: =IF(H9<>"","H:","") -> H: | H9: 1800 | I9: =IF(J9<>"","W:","") -> W: | J9: 400 | K9: =IF(L9<>"","D:","") -> D: | L9: 400 | Q9: =IF(B9<>"",(C9&M9&N9&O9&P9&" / "&G9&H9&I9&J9&K9&L9&" mm"),"") -> Marco / H:1800W:400D:400 mm | S9: 1.1.4. | T9: Panel posterior | U9: PaP | V9: =Z1&Z2 -> 2272 | W9: Pleno | Z9: =V9&U9&MID(W9,1,1)&MID(X9,1,1)&MID(Y9,1,3) -> 2272PaPP | AA9: =VLOOKUP(Z9,$B$6:$D$470,3,FALSE) -> 014061 | AD9: =AO9&AP9&AQ9&AR9&AS9&AT9&AN9&AU9 -> ICV2VEFPW3- | AE9: UF. | AF9: de | AG9: Integrada | AH9: CVS/NSX 250 | AI9: Vertical Extendida | AJ9: Fijo | AK9: Palanca | AL9: W:720 | AN9: - | AO9: =MID(AG9,1,1) -> I | AP9: {=IFERROR(_xlfn.IFS(AH9="Mini Breaker ","MB",AH9="GoPact ","GP",AH9="EZC 100 ","EZ1",AH9="EZC 250 ","EZ2",AH9="CVS/NSX 250 ","CV2",AH9="CVS/NSX/EZC 630 ","CV6",AH9="NS 1600 ","NS1",AH9="NW/MTZ 4000 ","NW4",AH9="Conmutador PEQ. ","CP",AH9="Conmutador MED. ","CM",AH9="Conmutador GRA. ","CG",AH9="Contactores ","CK"),"")} -> CV2 | AQ9: {=_xlfn.IFS(AI9="Horizontal ","H",AI9="Horizontal COMPUESTA ","HC",AI9="Vertical ","V",AI9="Vertical Compacta ","VC",AI9="Vertical Extendida ","VE")} -> VE | AR9: =MID(AJ9,1,1) -> F | AS9: =MID(AK9,1,1) -> P | AT9: {=IFERROR(_xlfn.IFS(AL9="W:200 ","W1",AL9="W:400 ","W2",AL9="W:720 ","W3",AL9="W:800 ","W4",AL9="W:1120 ","W5"),"")} -> W3 | AU9: {=IFERROR(_xlfn.IFS(AM9="D:400 ","D1",AM9="D:600 ","D2",AM9="D:1000 ","D3"),"")} | AV9: 021099 | AW9: 024003 | AX9: =AE9&AF9&AH9&AI9&AJ9&AK9&AL9&AM9&AN9 -> UF. de CVS/NSX 250 Vertical Extendida Fijo Palanca W:720 - | BB9: =BC9&BD9&BE9&BF9 -> 1AH | BC9: =BC8 -> 1 | BD9: =BD6 -> A | BE9: =BE8 -> H | BF9: {=IFERROR(_xlfn.IFS(BL9="400 + 400","X",BL9="720","Y",BL9="1120","Z"),"")} | BL9: - | BM9: - | BN9: - | BO9: - | BP9: - | BQ9: - | BR9: - | BS9: - | BT9: - | BU9: - | BV9: - | BW9: - | BX9: - | BY9: - | BZ9: - | CB9: =BC9&BD9&CC9&CD9 -> 1AVP | CC9: V | CD9: {=IFERROR(_xlfn.IFS(CF9="1/4","M",CF9="1/2","N",CF9="3/4","O",CF9="1","P"),"")} -> P | CF9: 1 | CG9: 037003 | CH9: - | CI9: - | CJ9: - | CK9: - | CL9: - | CM9: - | CN9: - | CO9: - | CP9: -
A10: 5 | B10: =MID(H10,1,2)&MID(J10,1,2)&MID(L10,1,2)&MID(C10,1,2)&MID(M10,1,1)&MID(N10,1,1)&MID(O10,1,1)&MID(P10,1,3) -> 184060Ma | C10: Marco | D10: 017004 | E10: 014001 | F10: 010021 | G10: =IF(H10<>"","H:","") -> H: | H10: 1800 | I10: =IF(J10<>"","W:","") -> W: | J10: 400 | K10: =IF(L10<>"","D:","") -> D: | L10: 600 | Q10: =IF(B10<>"",(C10&M10&N10&O10&P10&" / "&G10&H10&I10&J10&K10&L10&" mm"),"") -> Marco / H:1800W:400D:600 mm | S10: 1.1.5. | T10: Panel superior | U10: Pa | V10: =Z2&Z3 -> 7260 | W10: Superior | Z10: =V10&U10&MID(W10,1,1)&MID(X10,1,1)&MID(Y10,1,3) -> 7260PaS | AA10: =VLOOKUP(Z10,$B$6:$D$470,3,FALSE) -> 010057 | AD10: =AO10&AP10&AQ10&AR10&AS10&AT10&AN10&AU10 -> ICV2VCFMW3- | AE10: UF. | AF10: de | AG10: Integrada | AH10: CVS/NSX 250 | AI10: Vertical Compacta | AJ10: Fijo | AK10: Motorizado | AL10: W:720 | AN10: - | AO10: =MID(AG10,1,1) -> I | AP10: {=IFERROR(_xlfn.IFS(AH10="Mini Breaker ","MB",AH10="GoPact ","GP",AH10="EZC 100 ","EZ1",AH10="EZC 250 ","EZ2",AH10="CVS/NSX 250 ","CV2",AH10="CVS/NSX/EZC 630 ","CV6",AH10="NS 1600 ","NS1",AH10="NW/MTZ 4000 ","NW4",AH10="Conmutador PEQ. ","CP",AH10="Conmutador MED. ","CM",AH10="Conmutador GRA. ","CG",AH10="Contactores ","CK"),"")} -> CV2 | AQ10: {=_xlfn.IFS(AI10="Horizontal ","H",AI10="Horizontal COMPUESTA ","HC",AI10="Vertical ","V",AI10="Vertical Compacta ","VC",AI10="Vertical Extendida ","VE")} -> VC | AR10: =MID(AJ10,1,1) -> F | AS10: =MID(AK10,1,1) -> M | AT10: {=IFERROR(_xlfn.IFS(AL10="W:200 ","W1",AL10="W:400 ","W2",AL10="W:720 ","W3",AL10="W:800 ","W4",AL10="W:1120 ","W5"),"")} -> W3 | AU10: {=IFERROR(_xlfn.IFS(AM10="D:400 ","D1",AM10="D:600 ","D2",AM10="D:1000 ","D3"),"")} | AV10: 021129 | AW10: 024002 | AX10: =AE10&AF10&AH10&AI10&AJ10&AK10&AL10&AM10&AN10 -> UF. de CVS/NSX 250 Vertical Compacta Fijo Motorizado W:720 - | BB10: =BC10&BD10&BE10&BF10 -> 2BHY | BC10: {=_xlfn.IFS(BJ10="10 - 25",1,BJ10="10 - 40",2,BJ10="10 - 65",3,BJ10="10 - 85",4)} -> 2 | BD10: {=_xlfn.IFS(BK10="630","A",BK10="1250","B",BK10="1600","C",BK10="2000","D",BK10="2500","E",BK10="3200","F",BK10="4000","G",BK10="5000","H",BK10="6300","I",BK10="7000","J")} -> B | BE10: H | BF10: {=IFERROR(_xlfn.IFS(BL10="400 + 400","X",BL10="720","Y",BL10="1120","Z"),"")} -> Y | BH10: TC | BI10: TM | BJ10: 10 - 40 | BK10: 1250 | BL10: 720 | BM10: 038000 | BN10: EZC | BO10: 048001 | BP10: 048002 | BQ10: 048003 | BR10: 048004 | BS10: - | BT10: - | BU10: - | BV10: - | BW10: - | BX10: - | BY10: - | BZ10: - | CB10: =BC10&BD10&CC10&CD10 -> 2BVM | CC10: V | CD10: {=IFERROR(_xlfn.IFS(CF10="1/4","M",CF10="1/2","N",CF10="3/4","O",CF10="1","P"),"")} -> M | CF10: 1/4 | CG10: 037004 | CH10: EZC | CI10: 047009 | CJ10: 047010 | CK10: 047011 | CL10: 047012 | CM10: - | CN10: - | CO10: - | CP10: -
A11: 6 | B11: =MID(H11,1,2)&MID(J11,1,2)&MID(L11,1,2)&MID(C11,1,2)&MID(M11,1,1)&MID(N11,1,1)&MID(O11,1,1)&MID(P11,1,3) -> 184010Ma | C11: Marco | D11: 017005 | E11: 014002 | F11: 010021 | G11: =IF(H11<>"","H:","") -> H: | H11: 1800 | I11: =IF(J11<>"","W:","") -> W: | J11: 400 | K11: =IF(L11<>"","D:","") -> D: | L11: 1000 | Q11: =IF(B11<>"",(C11&M11&N11&O11&P11&" / "&G11&H11&I11&J11&K11&L11&" mm"),"") -> Marco / H:1800W:400D:1000 mm | S11: 1.1.6. | T11: Base inferior | U11: Ba | V11: =Z2&Z3 -> 7260 | W11: Estructural | Z11: =V11&U11&MID(W11,1,1)&MID(X11,1,1)&MID(Y11,1,3) -> 7260BaE | AA11: =VLOOKUP(Z11,$B$6:$D$470,3,FALSE) -> 015007 | AD11: =AO11&AP11&AQ11&AR11&AS11&AT11&AN11&AU11 -> ICV2VEFMW3- | AE11: UF. | AF11: de | AG11: Integrada | AH11: CVS/NSX 250 | AI11: Vertical Extendida | AJ11: Fijo | AK11: Motorizado | AL11: W:720 | AN11: - | AO11: =MID(AG11,1,1) -> I | AP11: {=IFERROR(_xlfn.IFS(AH11="Mini Breaker ","MB",AH11="GoPact ","GP",AH11="EZC 100 ","EZ1",AH11="EZC 250 ","EZ2",AH11="CVS/NSX 250 ","CV2",AH11="CVS/NSX/EZC 630 ","CV6",AH11="NS 1600 ","NS1",AH11="NW/MTZ 4000 ","NW4",AH11="Conmutador PEQ. ","CP",AH11="Conmutador MED. ","CM",AH11="Conmutador GRA. ","CG",AH11="Contactores ","CK"),"")} -> CV2 | AQ11: {=_xlfn.IFS(AI11="Horizontal ","H",AI11="Horizontal COMPUESTA ","HC",AI11="Vertical ","V",AI11="Vertical Compacta ","VC",AI11="Vertical Extendida ","VE")} -> VE | AR11: =MID(AJ11,1,1) -> F | AS11: =MID(AK11,1,1) -> M | AT11: {=IFERROR(_xlfn.IFS(AL11="W:200 ","W1",AL11="W:400 ","W2",AL11="W:720 ","W3",AL11="W:800 ","W4",AL11="W:1120 ","W5"),"")} -> W3 | AU11: {=IFERROR(_xlfn.IFS(AM11="D:400 ","D1",AM11="D:600 ","D2",AM11="D:1000 ","D3"),"")} | AV11: 021130 | AW11: 024003 | AX11: =AE11&AF11&AH11&AI11&AJ11&AK11&AL11&AM11&AN11 -> UF. de CVS/NSX 250 Vertical Extendida Fijo Motorizado W:720 - | BB11: =BC11&BD11&BE11&BF11 -> 2BHZ | BC11: =BC10 -> 2 | BD11: =BD10 -> B | BE11: =BE10 -> H | BF11: {=IFERROR(_xlfn.IFS(BL11="400 + 400","X",BL11="720","Y",BL11="1120","Z"),"")} -> Z | BL11: 1120 | BM11: 038001 | BN11: CVS | BO11: 048005 | BP11: 048006 | BQ11: 048007 | BR11: 048008 | BS11: - | BT11: - | BU11: - | BV11: - | BW11: - | BX11: - | BY11: - | BZ11: - | CB11: =BC11&BD11&CC11&CD11 -> 2BVN | CC11: V | CD11: {=IFERROR(_xlfn.IFS(CF11="1/4","M",CF11="1/2","N",CF11="3/4","O",CF11="1","P"),"")} -> N | CF11: 1/2 | CG11: 037005 | CH11: CVS | CI11: 047013 | CJ11: 047014 | CK11: 047015 | CL11: 047016 | CM11: - | CN11: - | CO11: - | CP11: -
A12: 7 | B12: =MID(H12,1,2)&MID(J12,1,2)&MID(L12,1,2)&MID(C12,1,2)&MID(M12,1,1)&MID(N12,1,1)&MID(O12,1,1)&MID(P12,1,3) -> 187240Ma | C12: Marco | D12: 017006 | E12: 014000 | F12: 010022 | G12: =IF(H12<>"","H:","") -> H: | H12: 1800 | I12: =IF(J12<>"","W:","") -> W: | J12: 720 | K12: =IF(L12<>"","D:","") -> D: | L12: 400 | Q12: =IF(B12<>"",(C12&M12&N12&O12&P12&" / "&G12&H12&I12&J12&K12&L12&" mm"),"") -> Marco / H:1800W:720D:400 mm | S12: 1.1.7. | T12: Kit tapa zocalos laterales | U12: Zo | V12: =Z3 -> 60 | W12: Laterales | Z12: =V12&U12&MID(W12,1,1)&MID(X12,1,1)&MID(Y12,1,3) -> 60ZoL | AA12: =VLOOKUP(Z12,$B$6:$D$470,3,FALSE) -> 010177 | AD12: =AO12&AP12&AQ12&AR12&AS12&AT12&AN12&AU12 -> ICV2VFPW2- | AE12: UF. | AF12: de | AG12: Integrada | AH12: CVS/NSX 250 | AI12: Vertical | AJ12: Fijo | AK12: Palanca | AL12: W:400 | AN12: - | AO12: =MID(AG12,1,1) -> I | AP12: {=IFERROR(_xlfn.IFS(AH12="Mini Breaker ","MB",AH12="GoPact ","GP",AH12="EZC 100 ","EZ1",AH12="EZC 250 ","EZ2",AH12="CVS/NSX 250 ","CV2",AH12="CVS/NSX/EZC 630 ","CV6",AH12="NS 1600 ","NS1",AH12="NW/MTZ 4000 ","NW4",AH12="Conmutador PEQ. ","CP",AH12="Conmutador MED. ","CM",AH12="Conmutador GRA. ","CG",AH12="Contactores ","CK"),"")} -> CV2 | AQ12: {=_xlfn.IFS(AI12="Horizontal ","H",AI12="Horizontal COMPUESTA ","HC",AI12="Vertical ","V",AI12="Vertical Compacta ","VC",AI12="Vertical Extendida ","VE")} -> V | AR12: =MID(AJ12,1,1) -> F | AS12: =MID(AK12,1,1) -> P | AT12: {=IFERROR(_xlfn.IFS(AL12="W:200 ","W1",AL12="W:400 ","W2",AL12="W:720 ","W3",AL12="W:800 ","W4",AL12="W:1120 ","W5"),"")} -> W2 | AU12: {=IFERROR(_xlfn.IFS(AM12="D:400 ","D1",AM12="D:600 ","D2",AM12="D:1000 ","D3"),"")} | AV12: 021133 | AW12: 024004 | AX12: =AE12&AF12&AH12&AI12&AJ12&AK12&AL12&AM12&AN12 -> UF. de CVS/NSX 250 Vertical Fijo Palanca W:400 - | BB12: =BC12&BD12&BE12&BF12 -> 2BHX | BC12: =BC11 -> 2 | BD12: =BD10 -> B | BE12: =BE11 -> H | BF12: {=IFERROR(_xlfn.IFS(BL12="400 + 400","X",BL12="720","Y",BL12="1120","Z"),"")} -> X | BL12: 400 + 400 | BM12: 038002 | BN12: NSX | BO12: 048005 | BP12: 048006 | BQ12: 048007 | BR12: 048008 | BS12: - | BT12: - | BU12: - | BV12: - | BW12: - | BX12: - | BY12: - | BZ12: - | CB12: =BC12&BD12&CC12&CD12 -> 2BVO | CC12: V | CD12: {=IFERROR(_xlfn.IFS(CF12="1/4","M",CF12="1/2","N",CF12="3/4","O",CF12="1","P"),"")} -> O | CF12: 3/4 | CG12: 037006 | CH12: NSX
A13: 8 | B13: =MID(H13,1,2)&MID(J13,1,2)&MID(L13,1,2)&MID(C13,1,2)&MID(M13,1,1)&MID(N13,1,1)&MID(O13,1,1)&MID(P13,1,3) -> 187260Ma | C13: Marco | D13: 017007 | E13: 014001 | F13: 010022 | G13: =IF(H13<>"","H:","") -> H: | H13: 1800 | I13: =IF(J13<>"","W:","") -> W: | J13: 720 | K13: =IF(L13<>"","D:","") -> D: | L13: 600 | Q13: =IF(B13<>"",(C13&M13&N13&O13&P13&" / "&G13&H13&I13&J13&K13&L13&" mm"),"") -> Marco / H:1800W:720D:600 mm | S13: 1.1.8. | T13: Kit tapa zocalos Frontales | U13: Zo | V13: =Z2 -> 72 | W13: Frontales | Z13: =V13&U13&MID(W13,1,1)&MID(X13,1,1)&MID(Y13,1,3) -> 72ZoF | AA13: =VLOOKUP(Z13,$B$6:$D$470,3,FALSE) -> 010178 | AD13: =AO13&AP13&AQ13&AR13&AS13&AT13&AN13&AU13 -> ICV2VFMW2- | AE13: UF. | AF13: de | AG13: Integrada | AH13: CVS/NSX 250 | AI13: Vertical | AJ13: Fijo | AK13: Motorizado | AL13: W:400 | AN13: - | AO13: =MID(AG13,1,1) -> I | AP13: {=IFERROR(_xlfn.IFS(AH13="Mini Breaker ","MB",AH13="GoPact ","GP",AH13="EZC 100 ","EZ1",AH13="EZC 250 ","EZ2",AH13="CVS/NSX 250 ","CV2",AH13="CVS/NSX/EZC 630 ","CV6",AH13="NS 1600 ","NS1",AH13="NW/MTZ 4000 ","NW4",AH13="Conmutador PEQ. ","CP",AH13="Conmutador MED. ","CM",AH13="Conmutador GRA. ","CG",AH13="Contactores ","CK"),"")} -> CV2 | AQ13: {=_xlfn.IFS(AI13="Horizontal ","H",AI13="Horizontal COMPUESTA ","HC",AI13="Vertical ","V",AI13="Vertical Compacta ","VC",AI13="Vertical Extendida ","VE")} -> V | AR13: =MID(AJ13,1,1) -> F | AS13: =MID(AK13,1,1) -> M | AT13: {=IFERROR(_xlfn.IFS(AL13="W:200 ","W1",AL13="W:400 ","W2",AL13="W:720 ","W3",AL13="W:800 ","W4",AL13="W:1120 ","W5"),"")} -> W2 | AU13: {=IFERROR(_xlfn.IFS(AM13="D:400 ","D1",AM13="D:600 ","D2",AM13="D:1000 ","D3"),"")} | AV13: 021134 | AW13: 024004 | AX13: =AE13&AF13&AH13&AI13&AJ13&AK13&AL13&AM13&AN13 -> UF. de CVS/NSX 250 Vertical Fijo Motorizado W:400 - | BB13: =BC13&BD13&BE13&BF13 -> 2BH | BC13: =BC12 -> 2 | BD13: =BD10 -> B | BE13: =BE12 -> H | BF13: {=IFERROR(_xlfn.IFS(BL13="400 + 400","X",BL13="720","Y",BL13="1120","Z"),"")} | BL13: - | BM13: - | BN13: NS | BO13: - | BP13: - | BQ13: - | BR13: - | BS13: 048009 | BT13: 048009 | BU13: 048009 | BV13: - | BW13: - | BX13: - | BY13: - | BZ13: - | CB13: =BC13&BD13&CC13&CD13 -> 2BVP | CC13: V | CD13: {=IFERROR(_xlfn.IFS(CF13="1/4","M",CF13="1/2","N",CF13="3/4","O",CF13="1","P"),"")} -> P | CF13: 1 | CG13: 037007 | CH13: NS | CI13: - | CJ13: - | CK13: - | CL13: - | CM13: 047017 | CN13: 047017 | CO13: 047018 | CP13: -
A14: 9 | B14: =MID(H14,1,2)&MID(J14,1,2)&MID(L14,1,2)&MID(C14,1,2)&MID(M14,1,1)&MID(N14,1,1)&MID(O14,1,1)&MID(P14,1,3) -> 187210Ma | C14: Marco | D14: 017008 | E14: 014002 | F14: 010022 | G14: =IF(H14<>"","H:","") -> H: | H14: 1800 | I14: =IF(J14<>"","W:","") -> W: | J14: 720 | K14: =IF(L14<>"","D:","") -> D: | L14: 1000 | Q14: =IF(B14<>"",(C14&M14&N14&O14&P14&" / "&G14&H14&I14&J14&K14&L14&" mm"),"") -> Marco / H:1800W:720D:1000 mm | S14: 1.1.9. | T14: Pane linferior | U14: Pa | V14: =Z2&Z3 -> 7260 | W14: Inferior | Z14: =V14&U14&MID(W14,1,1)&MID(X14,1,1)&MID(Y14,1,3) -> 7260PaI | AA14: =VLOOKUP(Z14,$B$6:$D$470,3,FALSE) -> 014257 | AD14: =AO14&AP14&AQ14&AR14&AS14&AT14&AN14&AU14 -> ICV2HFPW3- | AE14: UF. | AF14: de | AG14: Integrada | AH14: CVS/NSX 250 | AI14: Horizontal | AJ14: Fijo | AK14: Palanca | AL14: W:720 | AN14: - | AO14: =MID(AG14,1,1) -> I | AP14: {=IFERROR(_xlfn.IFS(AH14="Mini Breaker ","MB",AH14="GoPact ","GP",AH14="EZC 100 ","EZ1",AH14="EZC 250 ","EZ2",AH14="CVS/NSX 250 ","CV2",AH14="CVS/NSX/EZC 630 ","CV6",AH14="NS 1600 ","NS1",AH14="NW/MTZ 4000 ","NW4",AH14="Conmutador PEQ. ","CP",AH14="Conmutador MED. ","CM",AH14="Conmutador GRA. ","CG",AH14="Contactores ","CK"),"")} -> CV2 | AQ14: {=_xlfn.IFS(AI14="Horizontal ","H",AI14="Horizontal COMPUESTA ","HC",AI14="Vertical ","V",AI14="Vertical Compacta ","VC",AI14="Vertical Extendida ","VE")} -> H | AR14: =MID(AJ14,1,1) -> F | AS14: =MID(AK14,1,1) -> P | AT14: {=IFERROR(_xlfn.IFS(AL14="W:200 ","W1",AL14="W:400 ","W2",AL14="W:720 ","W3",AL14="W:800 ","W4",AL14="W:1120 ","W5"),"")} -> W3 | AU14: {=IFERROR(_xlfn.IFS(AM14="D:400 ","D1",AM14="D:600 ","D2",AM14="D:1000 ","D3"),"")} | AV14: 021084 | AW14: 024005 | AX14: =AE14&AF14&AH14&AI14&AJ14&AK14&AL14&AM14&AN14 -> UF. de CVS/NSX 250 Horizontal Fijo Palanca W:720 - | BB14: =BC14&BD14&BE14&BF14 -> 2BH | BC14: =BC13 -> 2 | BD14: =BD10 -> B | BE14: =BE13 -> H | BF14: {=IFERROR(_xlfn.IFS(BL14="400 + 400","X",BL14="720","Y",BL14="1120","Z"),"")} | BL14: - | BM14: - | BN14: NW | BO14: - | BP14: - | BQ14: - | BR14: - | BS14: 048010 | BT14: 048011 | BU14: 048012 | BV14: - | BW14: - | BX14: - | BY14: - | BZ14: - | CB14: =BC14&BD14&CC14&CD14 -> 2BV | CC14: V | CD14: {=IFERROR(_xlfn.IFS(CF14="1/4","M",CF14="1/2","N",CF14="3/4","O",CF14="1","P"),"")} | CF14: - | CG14: - | CH14: - | CI14: - | CJ14: - | CK14: - | CL14: - | CM14: - | CN14: - | CO14: - | CP14: -
A15: 10 | B15: =MID(H15,1,2)&MID(J15,1,2)&MID(L15,1,2)&MID(C15,1,2)&MID(M15,1,1)&MID(N15,1,1)&MID(O15,1,1)&MID(P15,1,3) -> 181140Ma | C15: Marco | D15: 017009 | E15: 014000 | F15: 010024 | G15: =IF(H15<>"","H:","") -> H: | H15: 1800 | I15: =IF(J15<>"","W:","") -> W: | J15: 1120 | K15: =IF(L15<>"","D:","") -> D: | L15: 400 | Q15: =IF(B15<>"",(C15&M15&N15&O15&P15&" / "&G15&H15&I15&J15&K15&L15&" mm"),"") -> Marco / H:1800W:1120D:400 mm | S15: 1.1.10. | T15: Paral interno vertical total | U15: PaIV | V15: =Z1 -> 22 | W15: Total | Z15: =V15&U15&MID(W15,1,1)&MID(X15,1,1)&MID(Y15,1,3) -> 22PaIVT | AA15: =VLOOKUP(Z15,$B$6:$D$470,3,FALSE) -> 014154 | AD15: =AO15&AP15&AQ15&AR15&AS15&AT15&AN15&AU15 -> ICV2HFMW3- | AE15: UF. | AF15: de | AG15: Integrada | AH15: CVS/NSX 250 | AI15: Horizontal | AJ15: Fijo | AK15: Motorizado | AL15: W:720 | AN15: - | AO15: =MID(AG15,1,1) -> I | AP15: {=IFERROR(_xlfn.IFS(AH15="Mini Breaker ","MB",AH15="GoPact ","GP",AH15="EZC 100 ","EZ1",AH15="EZC 250 ","EZ2",AH15="CVS/NSX 250 ","CV2",AH15="CVS/NSX/EZC 630 ","CV6",AH15="NS 1600 ","NS1",AH15="NW/MTZ 4000 ","NW4",AH15="Conmutador PEQ. ","CP",AH15="Conmutador MED. ","CM",AH15="Conmutador GRA. ","CG",AH15="Contactores ","CK"),"")} -> CV2 | AQ15: {=_xlfn.IFS(AI15="Horizontal ","H",AI15="Horizontal COMPUESTA ","HC",AI15="Vertical ","V",AI15="Vertical Compacta ","VC",AI15="Vertical Extendida ","VE")} -> H | AR15: =MID(AJ15,1,1) -> F | AS15: =MID(AK15,1,1) -> M | AT15: {=IFERROR(_xlfn.IFS(AL15="W:200 ","W1",AL15="W:400 ","W2",AL15="W:720 ","W3",AL15="W:800 ","W4",AL15="W:1120 ","W5"),"")} -> W3 | AU15: {=IFERROR(_xlfn.IFS(AM15="D:400 ","D1",AM15="D:600 ","D2",AM15="D:1000 ","D3"),"")} | AV15: 025500 | AW15: 024005 | AX15: =AE15&AF15&AH15&AI15&AJ15&AK15&AL15&AM15&AN15 -> UF. de CVS/NSX 250 Horizontal Fijo Motorizado W:720 - | BB15: =BC15&BD15&BE15&BF15 -> 2CHY | BC15: {=_xlfn.IFS(BJ15="10 - 25",1,BJ15="10 - 40",2,BJ15="10 - 65",3,BJ15="10 - 85",4)} -> 2 | BD15: {=_xlfn.IFS(BK15="630","A",BK15="1250","B",BK15="1600","C",BK15="2000","D",BK15="2500","E",BK15="3200","F",BK15="4000","G",BK15="5000","H",BK15="6300","I",BK15="7000","J")} -> C | BE15: H | BF15: {=IFERROR(_xlfn.IFS(BL15="400 + 400","X",BL15="720","Y",BL15="1120","Z"),"")} -> Y | BJ15: 10 - 40 | BK15: 1600 | BL15: 720 | BM15: 038003 | BN15: EZC | BO15: 048001 | BP15: 048002 | BQ15: 048003 | BR15: 048004 | BS15: - | BT15: - | BU15: - | BV15: - | BW15: - | BX15: - | BY15: - | BZ15: - | CB15: =BC15&BD15&CC15&CD15 -> 2CVM | CC15: V | CD15: {=IFERROR(_xlfn.IFS(CF15="1/4","M",CF15="1/2","N",CF15="3/4","O",CF15="1","P"),"")} -> M | CF15: 1/4 | CG15: 037008 | CH15: EZC | CI15: 047009 | CJ15: 047010 | CK15: 047011 | CL15: 047012 | CM15: - | CN15: - | CO15: - | CP15: -
A16: 11 | B16: =MID(H16,1,2)&MID(J16,1,2)&MID(L16,1,2)&MID(C16,1,2)&MID(M16,1,1)&MID(N16,1,1)&MID(O16,1,1)&MID(P16,1,3) -> 181160Ma | C16: Marco | D16: 017010 | E16: 014001 | F16: 010024 | G16: =IF(H16<>"","H:","") -> H: | H16: 1800 | I16: =IF(J16<>"","W:","") -> W: | J16: 1120 | K16: =IF(L16<>"","D:","") -> D: | L16: 600 | Q16: =IF(B16<>"",(C16&M16&N16&O16&P16&" / "&G16&H16&I16&J16&K16&L16&" mm"),"") -> Marco / H:1800W:1120D:600 mm | S16: 1.1.11. | T16: Paral interno vertical intermedio | U16: PaI | V16: 600 | W16: Vertical | Z16: =MID(V16,1,2)&U16&MID(W16,1,1)&MID(X16,1,1)&MID(Y16,1,3) -> 60PaIV | AA16: =VLOOKUP(Z16,$B$6:$D$470,3,FALSE) -> 014150 | AD16: =AO16&AP16&AQ16&AR16&AS16&AT16&AN16&AU16 -> ICV2HFPW3DPS | AE16: UF. | AF16: de | AG16: Integrada | AH16: CVS/NSX 250 | AI16: Horizontal | AJ16: Fijo | AK16: Palanca | AL16: W:720 | AN16: DPS | AO16: =MID(AG16,1,1) -> I | AP16: {=IFERROR(_xlfn.IFS(AH16="Mini Breaker ","MB",AH16="GoPact ","GP",AH16="EZC 100 ","EZ1",AH16="EZC 250 ","EZ2",AH16="CVS/NSX 250 ","CV2",AH16="CVS/NSX/EZC 630 ","CV6",AH16="NS 1600 ","NS1",AH16="NW/MTZ 4000 ","NW4",AH16="Conmutador PEQ. ","CP",AH16="Conmutador MED. ","CM",AH16="Conmutador GRA. ","CG",AH16="Contactores ","CK"),"")} -> CV2 | AQ16: {=_xlfn.IFS(AI16="Horizontal ","H",AI16="Horizontal COMPUESTA ","HC",AI16="Vertical ","V",AI16="Vertical Compacta ","VC",AI16="Vertical Extendida ","VE")} -> H | AR16: =MID(AJ16,1,1) -> F | AS16: =MID(AK16,1,1) -> P | AT16: {=IFERROR(_xlfn.IFS(AL16="W:200 ","W1",AL16="W:400 ","W2",AL16="W:720 ","W3",AL16="W:800 ","W4",AL16="W:1120 ","W5"),"")} -> W3 | AU16: {=IFERROR(_xlfn.IFS(AM16="D:400 ","D1",AM16="D:600 ","D2",AM16="D:1000 ","D3"),"")} | AV16: 021085 | AW16: 024006 | AX16: =AE16&AF16&AH16&AI16&AJ16&AK16&AL16&AM16&AN16 -> UF. de CVS/NSX 250 Horizontal Fijo Palanca W:720 DPS | BB16: =BC16&BD16&BE16&BF16 -> 2CHZ | BC16: =BC15 -> 2 | BD16: =BD15 -> C | BE16: =BE15 -> H | BF16: {=IFERROR(_xlfn.IFS(BL16="400 + 400","X",BL16="720","Y",BL16="1120","Z"),"")} -> Z | BL16: 1120 | BM16: 038004 | BN16: CVS | BO16: 048005 | BP16: 048006 | BQ16: 048007 | BR16: 048008 | BS16: - | BT16: - | BU16: - | BV16: - | BW16: - | BX16: - | BY16: - | BZ16: - | CB16: =BC16&BD16&CC16&CD16 -> 2CVN | CC16: V | CD16: {=IFERROR(_xlfn.IFS(CF16="1/4","M",CF16="1/2","N",CF16="3/4","O",CF16="1","P"),"")} -> N | CF16: 1/2 | CG16: 037009 | CH16: CVS | CI16: 047013 | CJ16: 047014 | CK16: 047015 | CL16: 047016 | CM16: - | CN16: - | CO16: - | CP16: -
A17: 12 | B17: =MID(H17,1,2)&MID(J17,1,2)&MID(L17,1,2)&MID(C17,1,2)&MID(M17,1,1)&MID(N17,1,1)&MID(O17,1,1)&MID(P17,1,3) -> 181110Ma | C17: Marco | D17: 017011 | E17: 014002 | F17: 010024 | G17: =IF(H17<>"","H:","") -> H: | H17: 1800 | I17: =IF(J17<>"","W:","") -> W: | J17: 1120 | K17: =IF(L17<>"","D:","") -> D: | L17: 1000 | Q17: =IF(B17<>"",(C17&M17&N17&O17&P17&" / "&G17&H17&I17&J17&K17&L17&" mm"),"") -> Marco / H:1800W:1120D:1000 mm | S17: 1.1.12. | T17: Paral interno horizontal | U17: PaI | V17: 600 | W17: Horizontal | Z17: =MID(V17,1,2)&U17&MID(W17,1,1)&MID(X17,1,1)&MID(Y17,1,3) -> 60PaIH | AA17: =VLOOKUP(Z17,$B$6:$D$470,3,FALSE) -> 10285 | AD17: =AO17&AP17&AQ17&AR17&AS17&AT17&AN17&AU17 -> ICV2HFPW3HWA | AE17: UF. | AF17: de | AG17: Integrada | AH17: CVS/NSX 250 | AI17: Horizontal | AJ17: Fijo | AK17: Palanca | AL17: W:720 | AN17: HWA | AO17: =MID(AG17,1,1) -> I | AP17: {=IFERROR(_xlfn.IFS(AH17="Mini Breaker ","MB",AH17="GoPact ","GP",AH17="EZC 100 ","EZ1",AH17="EZC 250 ","EZ2",AH17="CVS/NSX 250 ","CV2",AH17="CVS/NSX/EZC 630 ","CV6",AH17="NS 1600 ","NS1",AH17="NW/MTZ 4000 ","NW4",AH17="Conmutador PEQ. ","CP",AH17="Conmutador MED. ","CM",AH17="Conmutador GRA. ","CG",AH17="Contactores ","CK"),"")} -> CV2 | AQ17: {=_xlfn.IFS(AI17="Horizontal ","H",AI17="Horizontal COMPUESTA ","HC",AI17="Vertical ","V",AI17="Vertical Compacta ","VC",AI17="Vertical Extendida ","VE")} -> H | AR17: =MID(AJ17,1,1) -> F | AS17: =MID(AK17,1,1) -> P | AT17: {=IFERROR(_xlfn.IFS(AL17="W:200 ","W1",AL17="W:400 ","W2",AL17="W:720 ","W3",AL17="W:800 ","W4",AL17="W:1120 ","W5"),"")} -> W3 | AU17: {=IFERROR(_xlfn.IFS(AM17="D:400 ","D1",AM17="D:600 ","D2",AM17="D:1000 ","D3"),"")} | AV17: 021087 | AW17: 024007 | AX17: =AE17&AF17&AH17&AI17&AJ17&AK17&AL17&AM17&AN17 -> UF. de CVS/NSX 250 Horizontal Fijo Palanca W:720 HWA | BB17: =BC17&BD17&BE17&BF17 -> 2CHX | BC17: =BC16 -> 2 | BD17: =BD16 -> C | BE17: =BE16 -> H | BF17: {=IFERROR(_xlfn.IFS(BL17="400 + 400","X",BL17="720","Y",BL17="1120","Z"),"")} -> X | BL17: 400 + 400 | BM17: 038005 | BN17: NSX | BO17: 048005 | BP17: 048006 | BQ17: 048007 | BR17: 048008 | BS17: - | BT17: - | BU17: - | BV17: - | BW17: - | BX17: - | BY17: - | BZ17: - | CB17: =BC17&BD17&CC17&CD17 -> 2CVO | CC17: V | CD17: {=IFERROR(_xlfn.IFS(CF17="1/4","M",CF17="1/2","N",CF17="3/4","O",CF17="1","P"),"")} -> O | CF17: 3/4 | CG17: 037010 | CH17: NSX
A18: 13 | B18: =MID(H18,1,2)&MID(J18,1,2)&MID(L18,1,2)&MID(C18,1,2)&MID(M18,1,1)&MID(N18,1,1)&MID(O18,1,1)&MID(P18,1,3) -> 202040Ma | C18: Marco | D18: 017012 | E18: 014003 | F18: 010020 | G18: =IF(H18<>"","H:","") -> H: | H18: 2000 | I18: =IF(J18<>"","W:","") -> W: | J18: 200 | K18: =IF(L18<>"","D:","") -> D: | L18: 400 | Q18: =IF(B18<>"",(C18&M18&N18&O18&P18&" / "&G18&H18&I18&J18&K18&L18&" mm"),"") -> Marco / H:2000W:200D:400 mm | S18: 1.1.13. | T18: Ducto de cables | U18: DuC | V18: =Z2 -> 72 | Z18: =V18&U18&MID(W18,1,1)&MID(X18,1,1)&MID(Y18,1,3) -> 72DuC | AA18: =VLOOKUP(Z18,$B$6:$D$470,3,FALSE) -> 014301 | AD18: =AO18&AP18&AQ18&AR18&AS18&AT18&AN18&AU18 -> ICV2HCFPW3- | AE18: UF. | AF18: de | AG18: Integrada | AH18: CVS/NSX 250 | AI18: Horizontal COMPUESTA | AJ18: Fijo | AK18: Palanca | AL18: W:720 | AN18: - | AO18: =MID(AG18,1,1) -> I | AP18: {=IFERROR(_xlfn.IFS(AH18="Mini Breaker ","MB",AH18="GoPact ","GP",AH18="EZC 100 ","EZ1",AH18="EZC 250 ","EZ2",AH18="CVS/NSX 250 ","CV2",AH18="CVS/NSX/EZC 630 ","CV6",AH18="NS 1600 ","NS1",AH18="NW/MTZ 4000 ","NW4",AH18="Conmutador PEQ. ","CP",AH18="Conmutador MED. ","CM",AH18="Conmutador GRA. ","CG",AH18="Contactores ","CK"),"")} -> CV2 | AQ18: {=_xlfn.IFS(AI18="Horizontal ","H",AI18="Horizontal COMPUESTA ","HC",AI18="Vertical ","V",AI18="Vertical Compacta ","VC",AI18="Vertical Extendida ","VE")} -> HC | AR18: =MID(AJ18,1,1) -> F | AS18: =MID(AK18,1,1) -> P | AT18: {=IFERROR(_xlfn.IFS(AL18="W:200 ","W1",AL18="W:400 ","W2",AL18="W:720 ","W3",AL18="W:800 ","W4",AL18="W:1120 ","W5"),"")} -> W3 | AU18: {=IFERROR(_xlfn.IFS(AM18="D:400 ","D1",AM18="D:600 ","D2",AM18="D:1000 ","D3"),"")} | AV18: 021061 | AW18: 024005 | AX18: =AE18&AF18&AH18&AI18&AJ18&AK18&AL18&AM18&AN18 -> UF. de CVS/NSX 250 Horizontal COMPUESTA Fijo Palanca W:720 - | BB18: =BC18&BD18&BE18&BF18 -> 2CH | BC18: =BC17 -> 2 | BD18: =BD17 -> C | BE18: =BE17 -> H | BF18: {=IFERROR(_xlfn.IFS(BL18="400 + 400","X",BL18="720","Y",BL18="1120","Z"),"")} | BL18: - | BM18: - | BN18: NS | BO18: - | BP18: - | BQ18: - | BR18: - | BS18: 048009 | BT18: 048009 | BU18: 048009 | BV18: 048013 | BW18: - | BX18: - | BY18: - | BZ18: - | CB18: =BC18&BD18&CC18&CD18 -> 2CVP | CC18: V | CD18: {=IFERROR(_xlfn.IFS(CF18="1/4","M",CF18="1/2","N",CF18="3/4","O",CF18="1","P"),"")} -> P | CF18: 1 | CG18: 037011 | CH18: NS | CI18: - | CJ18: - | CK18: - | CL18: - | CM18: 047017 | CN18: 047017 | CO18: 047018 | CP18: 047019
A19: 14 | B19: =MID(H19,1,2)&MID(J19,1,2)&MID(L19,1,2)&MID(C19,1,2)&MID(M19,1,1)&MID(N19,1,1)&MID(O19,1,1)&MID(P19,1,3) -> 202060Ma | C19: Marco | D19: 017013 | E19: 014004 | F19: 010020 | G19: =IF(H19<>"","H:","") -> H: | H19: 2000 | I19: =IF(J19<>"","W:","") -> W: | J19: 200 | K19: =IF(L19<>"","D:","") -> D: | L19: 600 | Q19: =IF(B19<>"",(C19&M19&N19&O19&P19&" / "&G19&H19&I19&J19&K19&L19&" mm"),"") -> Marco / H:2000W:200D:600 mm | S19: 1.1.14. | T19: Kit union posterior | U19: Ki | W19: Union | Z19: =V19&U19&MID(W19,1,1)&MID(X19,1,1)&MID(Y19,1,3) -> KiU | AA19: =VLOOKUP(Z19,$B$6:$D$470,3,FALSE) -> #N/A | AD19: =AO19&AP19&AQ19&AR19&AS19&AT19&AN19&AU19 -> ICV2HCFMW3- | AE19: UF. | AF19: de | AG19: Integrada | AH19: CVS/NSX 250 | AI19: Horizontal COMPUESTA | AJ19: Fijo | AK19: Motorizado | AL19: W:720 | AN19: - | AO19: =MID(AG19,1,1) -> I | AP19: {=IFERROR(_xlfn.IFS(AH19="Mini Breaker ","MB",AH19="GoPact ","GP",AH19="EZC 100 ","EZ1",AH19="EZC 250 ","EZ2",AH19="CVS/NSX 250 ","CV2",AH19="CVS/NSX/EZC 630 ","CV6",AH19="NS 1600 ","NS1",AH19="NW/MTZ 4000 ","NW4",AH19="Conmutador PEQ. ","CP",AH19="Conmutador MED. ","CM",AH19="Conmutador GRA. ","CG",AH19="Contactores ","CK"),"")} -> CV2 | AQ19: {=_xlfn.IFS(AI19="Horizontal ","H",AI19="Horizontal COMPUESTA ","HC",AI19="Vertical ","V",AI19="Vertical Compacta ","VC",AI19="Vertical Extendida ","VE")} -> HC | AR19: =MID(AJ19,1,1) -> F | AS19: =MID(AK19,1,1) -> M | AT19: {=IFERROR(_xlfn.IFS(AL19="W:200 ","W1",AL19="W:400 ","W2",AL19="W:720 ","W3",AL19="W:800 ","W4",AL19="W:1120 ","W5"),"")} -> W3 | AU19: {=IFERROR(_xlfn.IFS(AM19="D:400 ","D1",AM19="D:600 ","D2",AM19="D:1000 ","D3"),"")} | AV19: 025501 | AW19: 024005 | AX19: =AE19&AF19&AH19&AI19&AJ19&AK19&AL19&AM19&AN19 -> UF. de CVS/NSX 250 Horizontal COMPUESTA Fijo Motorizado W:720 - | BB19: =BC19&BD19&BE19&BF19 -> 2CH | BC19: =BC18 -> 2 | BD19: =BD18 -> C | BE19: =BE18 -> H | BF19: {=IFERROR(_xlfn.IFS(BL19="400 + 400","X",BL19="720","Y",BL19="1120","Z"),"")} | BL19: - | BM19: - | BN19: NW | BO19: - | BP19: - | BQ19: - | BR19: - | BS19: 048010 | BT19: 048011 | BU19: 048012 | BV19: - | BW19: - | BX19: - | BY19: - | BZ19: - | CB19: =BC19&BD19&CC19&CD19 -> 2CV | CC19: V | CD19: {=IFERROR(_xlfn.IFS(CF19="1/4","M",CF19="1/2","N",CF19="3/4","O",CF19="1","P"),"")} | CF19: - | CG19: - | CH19: - | CI19: - | CJ19: - | CK19: - | CL19: - | CM19: - | CN19: - | CO19: - | CP19: -
A20: 15 | B20: =MID(H20,1,2)&MID(J20,1,2)&MID(L20,1,2)&MID(C20,1,2)&MID(M20,1,1)&MID(N20,1,1)&MID(O20,1,1)&MID(P20,1,3) -> 202010Ma | C20: Marco | D20: 017014 | E20: 014005 | F20: 010020 | G20: =IF(H20<>"","H:","") -> H: | H20: 2000 | I20: =IF(J20<>"","W:","") -> W: | J20: 200 | K20: =IF(L20<>"","D:","") -> D: | L20: 1000 | Q20: =IF(B20<>"",(C20&M20&N20&O20&P20&" / "&G20&H20&I20&J20&K20&L20&" mm"),"") -> Marco / H:2000W:200D:1000 mm | S20: 1.1.15. | T20: Segregación frontal* | U20: Se | V20: =Z1&Z2 -> 2272 | W20: Frontales | Z20: =V20&U20&MID(W20,1,1)&MID(X20,1,1)&MID(Y20,1,3) -> 2272SeF | AA20: =VLOOKUP(Z20,$B$6:$D$470,3,FALSE) -> #N/A | AD20: =AO20&AP20&AQ20&AR20&AS20&AT20&AN20&AU20 -> IEZ1VCFPW3- | AE20: UF. | AF20: de | AG20: Integrada | AH20: EZC 100 | AI20: Vertical Compacta | AJ20: Fijo | AK20: Palanca | AL20: W:720 | AN20: - | AO20: =MID(AG20,1,1) -> I | AP20: {=IFERROR(_xlfn.IFS(AH20="Mini Breaker ","MB",AH20="GoPact ","GP",AH20="EZC 100 ","EZ1",AH20="EZC 250 ","EZ2",AH20="CVS/NSX 250 ","CV2",AH20="CVS/NSX/EZC 630 ","CV6",AH20="NS 1600 ","NS1",AH20="NW/MTZ 4000 ","NW4",AH20="Conmutador PEQ. ","CP",AH20="Conmutador MED. ","CM",AH20="Conmutador GRA. ","CG",AH20="Contactores ","CK"),"")} -> EZ1 | AQ20: {=_xlfn.IFS(AI20="Horizontal ","H",AI20="Horizontal COMPUESTA ","HC",AI20="Vertical ","V",AI20="Vertical Compacta ","VC",AI20="Vertical Extendida ","VE")} -> VC | AR20: =MID(AJ20,1,1) -> F | AS20: =MID(AK20,1,1) -> P | AT20: {=IFERROR(_xlfn.IFS(AL20="W:200 ","W1",AL20="W:400 ","W2",AL20="W:720 ","W3",AL20="W:800 ","W4",AL20="W:1120 ","W5"),"")} -> W3 | AU20: {=IFERROR(_xlfn.IFS(AM20="D:400 ","D1",AM20="D:600 ","D2",AM20="D:1000 ","D3"),"")} | AV20: 021102 | AW20: 024008 | AX20: =AE20&AF20&AH20&AI20&AJ20&AK20&AL20&AM20&AN20 -> UF. de EZC 100 Vertical Compacta Fijo Palanca W:720 - | BB20: =BC20&BD20&BE20&BF20 -> 3DHY | BC20: {=_xlfn.IFS(BJ20="10 - 25",1,BJ20="10 - 40",2,BJ20="10 - 65",3,BJ20="10 - 85",4)} -> 3 | BD20: {=_xlfn.IFS(BK20="630","A",BK20="1250","B",BK20="1600","C",BK20="2000","D",BK20="2500","E",BK20="3200","F",BK20="4000","G",BK20="5000","H",BK20="6300","I",BK20="7000","J")} -> D | BE20: H | BF20: {=IFERROR(_xlfn.IFS(BL20="400 + 400","X",BL20="720","Y",BL20="1120","Z"),"")} -> Y | BH20: TM | BJ20: 10 - 65 | BK20: 2000 | BL20: 720 | BM20: 038006 | BN20: - | BO20: - | BP20: - | BQ20: - | BR20: - | BS20: - | BT20: - | BU20: - | BV20: - | BW20: - | BX20: - | BY20: - | BZ20: - | CB20: =BC20&BD20&CC20&CD20 -> 3DVM | CC20: V | CD20: {=IFERROR(_xlfn.IFS(CF20="1/4","M",CF20="1/2","N",CF20="3/4","O",CF20="1","P"),"")} -> M | CF20: 1/4 | CG20: 037012 | CH20: EZC | CI20: 047020 | CJ20: 047021 | CK20: 047022 | CL20: 047023 | CM20: - | CN20: - | CO20: - | CP20: -
A21: 16 | B21: =MID(H21,1,2)&MID(J21,1,2)&MID(L21,1,2)&MID(C21,1,2)&MID(M21,1,1)&MID(N21,1,1)&MID(O21,1,1)&MID(P21,1,3) -> 204040Ma | C21: Marco | D21: 017015 | E21: 014003 | F21: 010021 | G21: =IF(H21<>"","H:","") -> H: | H21: 2000 | I21: =IF(J21<>"","W:","") -> W: | J21: 400 | K21: =IF(L21<>"","D:","") -> D: | L21: 400 | Q21: =IF(B21<>"",(C21&M21&N21&O21&P21&" / "&G21&H21&I21&J21&K21&L21&" mm"),"") -> Marco / H:2000W:400D:400 mm | AD21: =AO21&AP21&AQ21&AR21&AS21&AT21&AN21&AU21 -> IEZ1VEFPW3- | AE21: UF. | AF21: de | AG21: Integrada | AH21: EZC 100 | AI21: Vertical Extendida | AJ21: Fijo | AK21: Palanca | AL21: W:720 | AN21: - | AO21: =MID(AG21,1,1) -> I | AP21: {=IFERROR(_xlfn.IFS(AH21="Mini Breaker ","MB",AH21="GoPact ","GP",AH21="EZC 100 ","EZ1",AH21="EZC 250 ","EZ2",AH21="CVS/NSX 250 ","CV2",AH21="CVS/NSX/EZC 630 ","CV6",AH21="NS 1600 ","NS1",AH21="NW/MTZ 4000 ","NW4",AH21="Conmutador PEQ. ","CP",AH21="Conmutador MED. ","CM",AH21="Conmutador GRA. ","CG",AH21="Contactores ","CK"),"")} -> EZ1 | AQ21: {=_xlfn.IFS(AI21="Horizontal ","H",AI21="Horizontal COMPUESTA ","HC",AI21="Vertical ","V",AI21="Vertical Compacta ","VC",AI21="Vertical Extendida ","VE")} -> VE | AR21: =MID(AJ21,1,1) -> F | AS21: =MID(AK21,1,1) -> P | AT21: {=IFERROR(_xlfn.IFS(AL21="W:200 ","W1",AL21="W:400 ","W2",AL21="W:720 ","W3",AL21="W:800 ","W4",AL21="W:1120 ","W5"),"")} -> W3 | AU21: {=IFERROR(_xlfn.IFS(AM21="D:400 ","D1",AM21="D:600 ","D2",AM21="D:1000 ","D3"),"")} | AV21: 021104 | AW21: 024009 | AX21: =AE21&AF21&AH21&AI21&AJ21&AK21&AL21&AM21&AN21 -> UF. de EZC 100 Vertical Extendida Fijo Palanca W:720 - | BB21: =BC21&BD21&BE21&BF21 -> 3DHZ | BC21: =BC20 -> 3 | BD21: =BD20 -> D | BE21: =BE20 -> H | BF21: {=IFERROR(_xlfn.IFS(BL21="400 + 400","X",BL21="720","Y",BL21="1120","Z"),"")} -> Z | BL21: 1120 | BM21: 038007 | BN21: - | BO21: - | BP21: - | BQ21: - | BR21: - | BS21: - | BT21: - | BU21: - | BV21: - | BW21: - | BX21: - | BY21: - | BZ21: - | CB21: =BC21&BD21&CC21&CD21 -> 3DVN | CC21: V | CD21: {=IFERROR(_xlfn.IFS(CF21="1/4","M",CF21="1/2","N",CF21="3/4","O",CF21="1","P"),"")} -> N | CF21: 1/2 | CG21: 037013 | CH21: CVS | CI21: 047024 | CJ21: 047025 | CK21: 047026 | CL21: 047027 | CM21: - | CN21: - | CO21: - | CP21: -
A22: 17 | B22: =MID(H22,1,2)&MID(J22,1,2)&MID(L22,1,2)&MID(C22,1,2)&MID(M22,1,1)&MID(N22,1,1)&MID(O22,1,1)&MID(P22,1,3) -> 204060Ma | C22: Marco | D22: 017016 | E22: 014004 | F22: 010021 | G22: =IF(H22<>"","H:","") -> H: | H22: 2000 | I22: =IF(J22<>"","W:","") -> W: | J22: 400 | K22: =IF(L22<>"","D:","") -> D: | L22: 600 | Q22: =IF(B22<>"",(C22&M22&N22&O22&P22&" / "&G22&H22&I22&J22&K22&L22&" mm"),"") -> Marco / H:2000W:400D:600 mm | S22: 1.2.1. | T22: Hablador | Z22: =V22&U22&MID(W22,1,1)&MID(X22,1,1)&MID(Y22,1,3) | AA22: SinReferencia | AD22: =AO22&AP22&AQ22&AR22&AS22&AT22&AN22&AU22 -> IEZ1HFPW3- | AE22: UF. | AF22: de | AG22: Integrada | AH22: EZC 100 | AI22: Horizontal | AJ22: Fijo | AK22: Palanca | AL22: W:720 | AN22: - | AO22: =MID(AG22,1,1) -> I | AP22: {=IFERROR(_xlfn.IFS(AH22="Mini Breaker ","MB",AH22="GoPact ","GP",AH22="EZC 100 ","EZ1",AH22="EZC 250 ","EZ2",AH22="CVS/NSX 250 ","CV2",AH22="CVS/NSX/EZC 630 ","CV6",AH22="NS 1600 ","NS1",AH22="NW/MTZ 4000 ","NW4",AH22="Conmutador PEQ. ","CP",AH22="Conmutador MED. ","CM",AH22="Conmutador GRA. ","CG",AH22="Contactores ","CK"),"")} -> EZ1 | AQ22: {=_xlfn.IFS(AI22="Horizontal ","H",AI22="Horizontal COMPUESTA ","HC",AI22="Vertical ","V",AI22="Vertical Compacta ","VC",AI22="Vertical Extendida ","VE")} -> H | AR22: =MID(AJ22,1,1) -> F | AS22: =MID(AK22,1,1) -> P | AT22: {=IFERROR(_xlfn.IFS(AL22="W:200 ","W1",AL22="W:400 ","W2",AL22="W:720 ","W3",AL22="W:800 ","W4",AL22="W:1120 ","W5"),"")} -> W3 | AU22: {=IFERROR(_xlfn.IFS(AM22="D:400 ","D1",AM22="D:600 ","D2",AM22="D:1000 ","D3"),"")} | AV22: 021075 | AW22: 024010 | AX22: =AE22&AF22&AH22&AI22&AJ22&AK22&AL22&AM22&AN22 -> UF. de EZC 100 Horizontal Fijo Palanca W:720 - | BB22: =BC22&BD22&BE22&BF22 -> 3DH | BC22: =BC21 -> 3 | BD22: =BD21 -> D | BE22: =BE21 -> H | BF22: {=IFERROR(_xlfn.IFS(BL22="400 + 400","X",BL22="720","Y",BL22="1120","Z"),"")} | BL22: - | BM22: - | BN22: - | BO22: - | BP22: - | BQ22: - | BR22: - | BS22: - | BT22: - | BU22: - | BV22: - | BW22: - | BX22: - | BY22: - | BZ22: - | CB22: =BC22&BD22&CC22&CD22 -> 3DVO | CC22: V | CD22: {=IFERROR(_xlfn.IFS(CF22="1/4","M",CF22="1/2","N",CF22="3/4","O",CF22="1","P"),"")} -> O | CF22: 3/4 | CG22: 037014 | CH22: NSX
A23: 18 | B23: =MID(H23,1,2)&MID(J23,1,2)&MID(L23,1,2)&MID(C23,1,2)&MID(M23,1,1)&MID(N23,1,1)&MID(O23,1,1)&MID(P23,1,3) -> 204010Ma | C23: Marco | D23: 017017 | E23: 014005 | F23: 010021 | G23: =IF(H23<>"","H:","") -> H: | H23: 2000 | I23: =IF(J23<>"","W:","") -> W: | J23: 400 | K23: =IF(L23<>"","D:","") -> D: | L23: 1000 | Q23: =IF(B23<>"",(C23&M23&N23&O23&P23&" / "&G23&H23&I23&J23&K23&L23&" mm"),"") -> Marco / H:2000W:400D:1000 mm | S23: 1.2.2. | T23: Kit de cancamos | U23: CaE | Z23: =V23&U23&MID(W23,1,1)&MID(X23,1,1)&MID(Y23,1,3) -> CaE | AA23: =VLOOKUP(Z23,$B$6:$D$470,3,FALSE) -> 014501 | AD23: =AO23&AP23&AQ23&AR23&AS23&AT23&AN23&AU23 -> IEZ1HFPW3DPS | AE23: UF. | AF23: de | AG23: Integrada | AH23: EZC 100 | AI23: Horizontal | AJ23: Fijo | AK23: Palanca | AL23: W:720 | AN23: DPS | AO23: =MID(AG23,1,1) -> I | AP23: {=IFERROR(_xlfn.IFS(AH23="Mini Breaker ","MB",AH23="GoPact ","GP",AH23="EZC 100 ","EZ1",AH23="EZC 250 ","EZ2",AH23="CVS/NSX 250 ","CV2",AH23="CVS/NSX/EZC 630 ","CV6",AH23="NS 1600 ","NS1",AH23="NW/MTZ 4000 ","NW4",AH23="Conmutador PEQ. ","CP",AH23="Conmutador MED. ","CM",AH23="Conmutador GRA. ","CG",AH23="Contactores ","CK"),"")} -> EZ1 | AQ23: {=_xlfn.IFS(AI23="Horizontal ","H",AI23="Horizontal COMPUESTA ","HC",AI23="Vertical ","V",AI23="Vertical Compacta ","VC",AI23="Vertical Extendida ","VE")} -> H | AR23: =MID(AJ23,1,1) -> F | AS23: =MID(AK23,1,1) -> P | AT23: {=IFERROR(_xlfn.IFS(AL23="W:200 ","W1",AL23="W:400 ","W2",AL23="W:720 ","W3",AL23="W:800 ","W4",AL23="W:1120 ","W5"),"")} -> W3 | AU23: {=IFERROR(_xlfn.IFS(AM23="D:400 ","D1",AM23="D:600 ","D2",AM23="D:1000 ","D3"),"")} | AV23: 021055 | AW23: 024011 | AX23: =AE23&AF23&AH23&AI23&AJ23&AK23&AL23&AM23&AN23 -> UF. de EZC 100 Horizontal Fijo Palanca W:720 DPS | BB23: =BC23&BD23&BE23&BF23 -> 3DH | BC23: =BC22 -> 3 | BD23: =BD22 -> D | BE23: =BE22 -> H | BF23: {=IFERROR(_xlfn.IFS(BL23="400 + 400","X",BL23="720","Y",BL23="1120","Z"),"")} | BL23: - | BM23: - | BN23: - | BO23: - | BP23: - | BQ23: - | BR23: - | BS23: - | BT23: - | BU23: - | BV23: - | BW23: - | BX23: - | BY23: - | BZ23: - | CB23: =BC23&BD23&CC23&CD23 -> 3DVP | CC23: V | CD23: {=IFERROR(_xlfn.IFS(CF23="1/4","M",CF23="1/2","N",CF23="3/4","O",CF23="1","P"),"")} -> P | CF23: 1 | CG23: 037015 | CH23: NS | CI23: - | CJ23: - | CK23: - | CL23: - | CM23: 047028 | CN23: 047028 | CO23: 047029 | CP23: 047030
A24: 19 | B24: =MID(H24,1,2)&MID(J24,1,2)&MID(L24,1,2)&MID(C24,1,2)&MID(M24,1,1)&MID(N24,1,1)&MID(O24,1,1)&MID(P24,1,3) -> 207240Ma | C24: Marco | D24: 017018 | E24: 014003 | F24: 010022 | G24: =IF(H24<>"","H:","") -> H: | H24: 2000 | I24: =IF(J24<>"","W:","") -> W: | J24: 720 | K24: =IF(L24<>"","D:","") -> D: | L24: 400 | Q24: =IF(B24<>"",(C24&M24&N24&O24&P24&" / "&G24&H24&I24&J24&K24&L24&" mm"),"") -> Marco / H:2000W:720D:400 mm | S24: 1.2.3. | T24: Angulo de izaje | U24: AnI | Z24: =V24&U24&MID(W24,1,1)&MID(X24,1,1)&MID(Y24,1,3) -> AnI | AA24: =VLOOKUP(Z24,$B$6:$D$470,3,FALSE) -> 014502 | AD24: =AO24&AP24&AQ24&AR24&AS24&AT24&AN24&AU24 -> IEZ1HFPW3HWA | AE24: UF. | AF24: de | AG24: Integrada | AH24: EZC 100 | AI24: Horizontal | AJ24: Fijo | AK24: Palanca | AL24: W:720 | AN24: HWA | AO24: =MID(AG24,1,1) -> I | AP24: {=IFERROR(_xlfn.IFS(AH24="Mini Breaker ","MB",AH24="GoPact ","GP",AH24="EZC 100 ","EZ1",AH24="EZC 250 ","EZ2",AH24="CVS/NSX 250 ","CV2",AH24="CVS/NSX/EZC 630 ","CV6",AH24="NS 1600 ","NS1",AH24="NW/MTZ 4000 ","NW4",AH24="Conmutador PEQ. ","CP",AH24="Conmutador MED. ","CM",AH24="Conmutador GRA. ","CG",AH24="Contactores ","CK"),"")} -> EZ1 | AQ24: {=_xlfn.IFS(AI24="Horizontal ","H",AI24="Horizontal COMPUESTA ","HC",AI24="Vertical ","V",AI24="Vertical Compacta ","VC",AI24="Vertical Extendida ","VE")} -> H | AR24: =MID(AJ24,1,1) -> F | AS24: =MID(AK24,1,1) -> P | AT24: {=IFERROR(_xlfn.IFS(AL24="W:200 ","W1",AL24="W:400 ","W2",AL24="W:720 ","W3",AL24="W:800 ","W4",AL24="W:1120 ","W5"),"")} -> W3 | AU24: {=IFERROR(_xlfn.IFS(AM24="D:400 ","D1",AM24="D:600 ","D2",AM24="D:1000 ","D3"),"")} | AV24: 021076 | AW24: 024012 | AX24: =AE24&AF24&AH24&AI24&AJ24&AK24&AL24&AM24&AN24 -> UF. de EZC 100 Horizontal Fijo Palanca W:720 HWA | BB24: =BC24&BD24&BE24&BF24 -> 3DH | BC24: =BC23 -> 3 | BD24: =BD23 -> D | BE24: =BE23 -> H | BF24: {=IFERROR(_xlfn.IFS(BL24="400 + 400","X",BL24="720","Y",BL24="1120","Z"),"")} | BN24: NW | BO24: - | BP24: - | BQ24: - | BR24: - | BS24: 048014 | BT24: 048015 | BU24: 048016 | BV24: 048017 | BW24: 048018 | BX24: - | BY24: - | BZ24: - | CB24: =BC24&BD24&CC24&CD24 -> 3DV | CC24: V | CD24: {=IFERROR(_xlfn.IFS(CF24="1/4","M",CF24="1/2","N",CF24="3/4","O",CF24="1","P"),"")} | CF24: - | CG24: - | CH24: - | CI24: - | CJ24: - | CK24: - | CL24: - | CM24: - | CN24: - | CO24: - | CP24: -
A25: 20 | B25: =MID(H25,1,2)&MID(J25,1,2)&MID(L25,1,2)&MID(C25,1,2)&MID(M25,1,1)&MID(N25,1,1)&MID(O25,1,1)&MID(P25,1,3) -> 207260Ma | C25: Marco | D25: 017019 | E25: 014004 | F25: 010022 | G25: =IF(H25<>"","H:","") -> H: | H25: 2000 | I25: =IF(J25<>"","W:","") -> W: | J25: 720 | K25: =IF(L25<>"","D:","") -> D: | L25: 600 | Q25: =IF(B25<>"",(C25&M25&N25&O25&P25&" / "&G25&H25&I25&J25&K25&L25&" mm"),"") -> Marco / H:2000W:720D:600 mm | S25: 1.2.4. | T25: Grua | Z25: =V25&U25&MID(W25,1,1)&MID(X25,1,1)&MID(Y25,1,3) | AA25: SinReferencia | AD25: =AO25&AP25&AQ25&AR25&AS25&AT25&AN25&AU25 -> IEZ2VCFPW3- | AE25: UF. | AF25: de | AG25: Integrada | AH25: EZC 250 | AI25: Vertical Compacta | AJ25: Fijo | AK25: Palanca | AL25: W:720 | AN25: - | AO25: =MID(AG25,1,1) -> I | AP25: {=IFERROR(_xlfn.IFS(AH25="Mini Breaker ","MB",AH25="GoPact ","GP",AH25="EZC 100 ","EZ1",AH25="EZC 250 ","EZ2",AH25="CVS/NSX 250 ","CV2",AH25="CVS/NSX/EZC 630 ","CV6",AH25="NS 1600 ","NS1",AH25="NW/MTZ 4000 ","NW4",AH25="Conmutador PEQ. ","CP",AH25="Conmutador MED. ","CM",AH25="Conmutador GRA. ","CG",AH25="Contactores ","CK"),"")} -> EZ2 | AQ25: {=_xlfn.IFS(AI25="Horizontal ","H",AI25="Horizontal COMPUESTA ","HC",AI25="Vertical ","V",AI25="Vertical Compacta ","VC",AI25="Vertical Extendida ","VE")} -> VC | AR25: =MID(AJ25,1,1) -> F | AS25: =MID(AK25,1,1) -> P | AT25: {=IFERROR(_xlfn.IFS(AL25="W:200 ","W1",AL25="W:400 ","W2",AL25="W:720 ","W3",AL25="W:800 ","W4",AL25="W:1120 ","W5"),"")} -> W3 | AU25: {=IFERROR(_xlfn.IFS(AM25="D:400 ","D1",AM25="D:600 ","D2",AM25="D:1000 ","D3"),"")} | AV25: 021106 | AW25: 024013 | AX25: =AE25&AF25&AH25&AI25&AJ25&AK25&AL25&AM25&AN25 -> UF. de EZC 250 Vertical Compacta Fijo Palanca W:720 - | BB25: =BC25&BD25&BE25&BF25 -> 3EHY | BC25: {=_xlfn.IFS(BJ25="10 - 25",1,BJ25="10 - 40",2,BJ25="10 - 65",3,BJ25="10 - 85",4)} -> 3 | BD25: {=_xlfn.IFS(BK25="630","A",BK25="1250","B",BK25="1600","C",BK25="2000","D",BK25="2500","E",BK25="3200","F",BK25="4000","G",BK25="5000","H",BK25="6300","I",BK25="7000","J")} -> E | BE25: H | BF25: {=IFERROR(_xlfn.IFS(BL25="400 + 400","X",BL25="720","Y",BL25="1120","Z"),"")} -> Y | BJ25: 10 - 65 | BK25: 2500 | BL25: 720 | BM25: 038008 | BN25: - | BO25: - | BP25: - | BQ25: - | BR25: - | BS25: - | BT25: - | BU25: - | BV25: - | BW25: - | BX25: - | BY25: - | BZ25: - | CB25: =BC25&BD25&CC25&CD25 -> 3EVM | CC25: V | CD25: {=IFERROR(_xlfn.IFS(CF25="1/4","M",CF25="1/2","N",CF25="3/4","O",CF25="1","P"),"")} -> M | CF25: 1/4 | CG25: 037016 | CH25: EZC | CI25: 047020 | CJ25: 047021 | CK25: 047022 | CL25: 047023 | CM25: - | CN25: - | CO25: - | CP25: -
A26: 21 | B26: =MID(H26,1,2)&MID(J26,1,2)&MID(L26,1,2)&MID(C26,1,2)&MID(M26,1,1)&MID(N26,1,1)&MID(O26,1,1)&MID(P26,1,3) -> 207210Ma | C26: Marco | D26: 017020 | E26: 014005 | F26: 010022 | G26: =IF(H26<>"","H:","") -> H: | H26: 2000 | I26: =IF(J26<>"","W:","") -> W: | J26: 720 | K26: =IF(L26<>"","D:","") -> D: | L26: 1000 | Q26: =IF(B26<>"",(C26&M26&N26&O26&P26&" / "&G26&H26&I26&J26&K26&L26&" mm"),"") -> Marco / H:2000W:720D:1000 mm | AD26: =AO26&AP26&AQ26&AR26&AS26&AT26&AN26&AU26 -> IEZ2VEFPW3- | AE26: UF. | AF26: de | AG26: Integrada | AH26: EZC 250 | AI26: Vertical Extendida | AJ26: Fijo | AK26: Palanca | AL26: W:720 | AN26: - | AO26: =MID(AG26,1,1) -> I | AP26: {=IFERROR(_xlfn.IFS(AH26="Mini Breaker ","MB",AH26="GoPact ","GP",AH26="EZC 100 ","EZ1",AH26="EZC 250 ","EZ2",AH26="CVS/NSX 250 ","CV2",AH26="CVS/NSX/EZC 630 ","CV6",AH26="NS 1600 ","NS1",AH26="NW/MTZ 4000 ","NW4",AH26="Conmutador PEQ. ","CP",AH26="Conmutador MED. ","CM",AH26="Conmutador GRA. ","CG",AH26="Contactores ","CK"),"")} -> EZ2 | AQ26: {=_xlfn.IFS(AI26="Horizontal ","H",AI26="Horizontal COMPUESTA ","HC",AI26="Vertical ","V",AI26="Vertical Compacta ","VC",AI26="Vertical Extendida ","VE")} -> VE | AR26: =MID(AJ26,1,1) -> F | AS26: =MID(AK26,1,1) -> P | AT26: {=IFERROR(_xlfn.IFS(AL26="W:200 ","W1",AL26="W:400 ","W2",AL26="W:720 ","W3",AL26="W:800 ","W4",AL26="W:1120 ","W5"),"")} -> W3 | AU26: {=IFERROR(_xlfn.IFS(AM26="D:400 ","D1",AM26="D:600 ","D2",AM26="D:1000 ","D3"),"")} | AV26: 021108 | AW26: 024014 | AX26: =AE26&AF26&AH26&AI26&AJ26&AK26&AL26&AM26&AN26 -> UF. de EZC 250 Vertical Extendida Fijo Palanca W:720 - | BB26: =BC26&BD26&BE26&BF26 -> 3EHZ | BC26: =BC25 -> 3 | BD26: =BD25 -> E | BE26: =BE25 -> H | BF26: {=IFERROR(_xlfn.IFS(BL26="400 + 400","X",BL26="720","Y",BL26="1120","Z"),"")} -> Z | BL26: 1120 | BM26: 038009 | BN26: - | BO26: - | BP26: - | BQ26: - | BR26: - | BS26: - | BT26: - | BU26: - | BV26: - | BW26: - | BX26: - | BY26: - | BZ26: - | CB26: =BC26&BD26&CC26&CD26 -> 3EVN | CC26: V | CD26: {=IFERROR(_xlfn.IFS(CF26="1/4","M",CF26="1/2","N",CF26="3/4","O",CF26="1","P"),"")} -> N | CF26: 1/2 | CG26: 037017 | CH26: CVS | CI26: 047024 | CJ26: 047025 | CK26: 047026 | CL26: 047027 | CM26: - | CN26: - | CO26: - | CP26: -
A27: 22 | B27: =MID(H27,1,2)&MID(J27,1,2)&MID(L27,1,2)&MID(C27,1,2)&MID(M27,1,1)&MID(N27,1,1)&MID(O27,1,1)&MID(P27,1,3) -> 208060Ma | C27: Marco | D27: 017021 | E27: 014004 | F27: 010023 | G27: =IF(H27<>"","H:","") -> H: | H27: 2000 | I27: =IF(J27<>"","W:","") -> W: | J27: 800 | K27: =IF(L27<>"","D:","") -> D: | L27: 600 | Q27: =IF(B27<>"",(C27&M27&N27&O27&P27&" / "&G27&H27&I27&J27&K27&L27&" mm"),"") -> Marco / H:2000W:800D:600 mm | S27: 1.3.1. | T27: Cubierta para modulo | AA27: SinReferencia | AD27: =AO27&AP27&AQ27&AR27&AS27&AT27&AN27&AU27 -> IEZ2HFPW3- | AE27: UF. | AF27: de | AG27: Integrada | AH27: EZC 250 | AI27: Horizontal | AJ27: Fijo | AK27: Palanca | AL27: W:720 | AN27: - | AO27: =MID(AG27,1,1) -> I | AP27: {=IFERROR(_xlfn.IFS(AH27="Mini Breaker ","MB",AH27="GoPact ","GP",AH27="EZC 100 ","EZ1",AH27="EZC 250 ","EZ2",AH27="CVS/NSX 250 ","CV2",AH27="CVS/NSX/EZC 630 ","CV6",AH27="NS 1600 ","NS1",AH27="NW/MTZ 4000 ","NW4",AH27="Conmutador PEQ. ","CP",AH27="Conmutador MED. ","CM",AH27="Conmutador GRA. ","CG",AH27="Contactores ","CK"),"")} -> EZ2 | AQ27: {=_xlfn.IFS(AI27="Horizontal ","H",AI27="Horizontal COMPUESTA ","HC",AI27="Vertical ","V",AI27="Vertical Compacta ","VC",AI27="Vertical Extendida ","VE")} -> H | AR27: =MID(AJ27,1,1) -> F | AS27: =MID(AK27,1,1) -> P | AT27: {=IFERROR(_xlfn.IFS(AL27="W:200 ","W1",AL27="W:400 ","W2",AL27="W:720 ","W3",AL27="W:800 ","W4",AL27="W:1120 ","W5"),"")} -> W3 | AU27: {=IFERROR(_xlfn.IFS(AM27="D:400 ","D1",AM27="D:600 ","D2",AM27="D:1000 ","D3"),"")} | AV27: 021078 | AW27: 024015 | AX27: =AE27&AF27&AH27&AI27&AJ27&AK27&AL27&AM27&AN27 -> UF. de EZC 250 Horizontal Fijo Palanca W:720 - | BB27: =BC27&BD27&BE27&BF27 -> 3EH | BC27: =BC26 -> 3 | BD27: =BD26 -> E | BE27: =BE26 -> H | BF27: {=IFERROR(_xlfn.IFS(BL27="400 + 400","X",BL27="720","Y",BL27="1120","Z"),"")} | BL27: - | BM27: - | BN27: - | BO27: - | BP27: - | BQ27: - | BR27: - | BS27: - | BT27: - | BU27: - | BV27: - | BW27: - | BX27: - | BY27: - | BZ27: - | CB27: =BC27&BD27&CC27&CD27 -> 3EVO | CC27: V | CD27: {=IFERROR(_xlfn.IFS(CF27="1/4","M",CF27="1/2","N",CF27="3/4","O",CF27="1","P"),"")} -> O | CF27: 3/4 | CG27: 037018 | CH27: NSX
A28: 23 | B28: =MID(H28,1,2)&MID(J28,1,2)&MID(L28,1,2)&MID(C28,1,2)&MID(M28,1,1)&MID(N28,1,1)&MID(O28,1,1)&MID(P28,1,3) -> 208010Ma | C28: Marco | D28: 017022 | E28: 014005 | F28: 010023 | G28: =IF(H28<>"","H:","") -> H: | H28: 2000 | I28: =IF(J28<>"","W:","") -> W: | J28: 800 | K28: =IF(L28<>"","D:","") -> D: | L28: 1000 | Q28: =IF(B28<>"",(C28&M28&N28&O28&P28&" / "&G28&H28&I28&J28&K28&L28&" mm"),"") -> Marco / H:2000W:800D:1000 mm | S28: 1.3.2. | T28: Cubierta para ventilación | AA28: SinReferencia | AD28: =AO28&AP28&AQ28&AR28&AS28&AT28&AN28&AU28 -> IEZ2HFPW3DPS | AE28: UF. | AF28: de | AG28: Integrada | AH28: EZC 250 | AI28: Horizontal | AJ28: Fijo | AK28: Palanca | AL28: W:720 | AN28: DPS | AO28: =MID(AG28,1,1) -> I | AP28: {=IFERROR(_xlfn.IFS(AH28="Mini Breaker ","MB",AH28="GoPact ","GP",AH28="EZC 100 ","EZ1",AH28="EZC 250 ","EZ2",AH28="CVS/NSX 250 ","CV2",AH28="CVS/NSX/EZC 630 ","CV6",AH28="NS 1600 ","NS1",AH28="NW/MTZ 4000 ","NW4",AH28="Conmutador PEQ. ","CP",AH28="Conmutador MED. ","CM",AH28="Conmutador GRA. ","CG",AH28="Contactores ","CK"),"")} -> EZ2 | AQ28: {=_xlfn.IFS(AI28="Horizontal ","H",AI28="Horizontal COMPUESTA ","HC",AI28="Vertical ","V",AI28="Vertical Compacta ","VC",AI28="Vertical Extendida ","VE")} -> H | AR28: =MID(AJ28,1,1) -> F | AS28: =MID(AK28,1,1) -> P | AT28: {=IFERROR(_xlfn.IFS(AL28="W:200 ","W1",AL28="W:400 ","W2",AL28="W:720 ","W3",AL28="W:800 ","W4",AL28="W:1120 ","W5"),"")} -> W3 | AU28: {=IFERROR(_xlfn.IFS(AM28="D:400 ","D1",AM28="D:600 ","D2",AM28="D:1000 ","D3"),"")} | AV28: 021080 | AW28: 024016 | AX28: =AE28&AF28&AH28&AI28&AJ28&AK28&AL28&AM28&AN28 -> UF. de EZC 250 Horizontal Fijo Palanca W:720 DPS | BB28: =BC28&BD28&BE28&BF28 -> 3EH | BC28: =BC27 -> 3 | BD28: =BD27 -> E | BE28: =BE27 -> H | BF28: {=IFERROR(_xlfn.IFS(BL28="400 + 400","X",BL28="720","Y",BL28="1120","Z"),"")} | BL28: - | BM28: - | BN28: - | BO28: - | BP28: - | BQ28: - | BR28: - | BS28: - | BT28: - | BU28: - | BV28: - | BW28: - | BX28: - | BY28: - | BZ28: - | CB28: =BC28&BD28&CC28&CD28 -> 3EVP | CC28: V | CD28: {=IFERROR(_xlfn.IFS(CF28="1/4","M",CF28="1/2","N",CF28="3/4","O",CF28="1","P"),"")} -> P | CF28: 1 | CG28: 037019 | CH28: NS | CI28: - | CJ28: - | CK28: - | CL28: - | CM28: 047028 | CN28: 047028 | CO28: 047029 | CP28: 047030
A29: 24 | B29: =MID(H29,1,2)&MID(J29,1,2)&MID(L29,1,2)&MID(C29,1,2)&MID(M29,1,1)&MID(N29,1,1)&MID(O29,1,1)&MID(P29,1,3) -> 201140Ma | C29: Marco | D29: 017023 | E29: 014003 | F29: 010024 | G29: =IF(H29<>"","H:","") -> H: | H29: 2000 | I29: =IF(J29<>"","W:","") -> W: | J29: 1120 | K29: =IF(L29<>"","D:","") -> D: | L29: 400 | Q29: =IF(B29<>"",(C29&M29&N29&O29&P29&" / "&G29&H29&I29&J29&K29&L29&" mm"),"") -> Marco / H:2000W:1120D:400 mm | S29: 1.4.1. | T29: Cubierta de ventilación | AA29: SinReferencia | AD29: =AO29&AP29&AQ29&AR29&AS29&AT29&AN29&AU29 -> ICV6VFPW3- | AE29: UF. | AF29: de | AG29: Integrada | AH29: CVS/NSX/EZC 630 | AI29: Vertical | AJ29: Fijo | AK29: Palanca | AL29: W:720 | AN29: - | AO29: =MID(AG29,1,1) -> I | AP29: {=IFERROR(_xlfn.IFS(AH29="Mini Breaker ","MB",AH29="GoPact ","GP",AH29="EZC 100 ","EZ1",AH29="EZC 250 ","EZ2",AH29="CVS/NSX 250 ","CV2",AH29="CVS/NSX/EZC 630 ","CV6",AH29="NS 1600 ","NS1",AH29="NW/MTZ 4000 ","NW4",AH29="Conmutador PEQ. ","CP",AH29="Conmutador MED. ","CM",AH29="Conmutador GRA. ","CG",AH29="Contactores ","CK"),"")} -> CV6 | AQ29: {=_xlfn.IFS(AI29="Horizontal ","H",AI29="Horizontal COMPUESTA ","HC",AI29="Vertical ","V",AI29="Vertical Compacta ","VC",AI29="Vertical Extendida ","VE")} -> V | AR29: =MID(AJ29,1,1) -> F | AS29: =MID(AK29,1,1) -> P | AT29: {=IFERROR(_xlfn.IFS(AL29="W:200 ","W1",AL29="W:400 ","W2",AL29="W:720 ","W3",AL29="W:800 ","W4",AL29="W:1120 ","W5"),"")} -> W3 | AU29: {=IFERROR(_xlfn.IFS(AM29="D:400 ","D1",AM29="D:600 ","D2",AM29="D:1000 ","D3"),"")} | AV29: 025505 | AW29: 024017 | AX29: =AE29&AF29&AH29&AI29&AJ29&AK29&AL29&AM29&AN29 -> UF. de CVS/NSX/EZC 630 Vertical Fijo Palanca W:720 - | BB29: =BC29&BD29&BE29&BF29 -> 3EH | BC29: =BC28 -> 3 | BD29: =BD28 -> E | BE29: =BE28 -> H | BF29: {=IFERROR(_xlfn.IFS(BL29="400 + 400","X",BL29="720","Y",BL29="1120","Z"),"")} | BN29: NW | BO29: - | BP29: - | BQ29: - | BR29: - | BS29: 048014 | BT29: 048015 | BU29: 048016 | BV29: 048017 | BW29: 048018 | BX29: 048019 | BY29: - | BZ29: - | CB29: =BC29&BD29&CC29&CD29 -> 3EV | CC29: V | CD29: {=IFERROR(_xlfn.IFS(CF29="1/4","M",CF29="1/2","N",CF29="3/4","O",CF29="1","P"),"")} | CF29: - | CG29: - | CH29: - | CI29: - | CJ29: - | CK29: - | CL29: - | CM29: - | CN29: - | CO29: - | CP29: -
