Workbook

Sheet BD
S1: Alto : | Y1: H | Z1: =MID(AA1,1,2) -> 22 | AA1: 2200
S2: Ancho : | Y2: W | Z2: =MID(AA2,1,2) -> 72 | AA2: 720
S3: Profundo: | Y3: D | Z3: =MID(AA3,1,2) -> 60 | AA3: 600
S4: IP: | AA4: 30
B5: Codigo | C5: Categoria | D5: Codigo | E5: SubCodigo1 | F5: SubCodigo2 | G5: Alto | I5: Ancho | K5: Profundo | M5: Criterio1 | N5: Criterio2 | O5: Criterio3 | P5: Criterio4 | Q5: Definición | U5: Categoria | V5: Criterio5 | W5: Criterio1 | X5: Criterio2 | Y5: Criterio3 | Z5: CodigoB | AA5: Codigo
A6: 1 | B6: =MID(H6,1,2)&MID(J6,1,2)&MID(L6,1,2)&MID(C6,1,2)&MID(M6,1,1)&MID(N6,1,1)&MID(O6,1,1)&MID(P6,1,3) -> 182040Ma | C6: Marco | D6: 017000 | E6: 014000 | F6: 010020 | G6: =IF(H6<>"","H:","") -> H: | H6: 1800 | I6: =IF(J6<>"","W:","") -> W: | J6: 200 | K6: =IF(L6<>"","D:","") -> D: | L6: 400 | Q6: =IF(B6<>"",(C6&M6&N6&O6&P6&" / "&G6&H6&I6&J6&K6&L6&" mm"),"") -> Marco / H:1800W:200D:400 mm | S6: 1.1.1. | T6: Marco | U6: Ma | V6: =Z1&Z2&Z3 -> 227260 | Z6: =V6&U6&MID(W6,1,1)&MID(X6,1,1)&MID(Y6,1,3) -> 227260Ma | AA6: =VLOOKUP(Z6,$B$6:$D$426,3,FALSE) -> 017033
A7: 2 | B7: =MID(H7,1,2)&MID(J7,1,2)&MID(L7,1,2)&MID(C7,1,2)&MID(M7,1,1)&MID(N7,1,1)&MID(O7,1,1)&MID(P7,1,3) -> 182060Ma | C7: Marco | D7: 017001 | E7: 014001 | F7: 010020 | G7: =IF(H7<>"","H:","") -> H: | H7: 1800 | I7: =IF(J7<>"","W:","") -> W: | J7: 200 | K7: =IF(L7<>"","D:","") -> D: | L7: 600 | Q7: =IF(B7<>"",(C7&M7&N7&O7&P7&" / "&G7&H7&I7&J7&K7&L7&" mm"),"") -> Marco / H:1800W:200D:600 mm | S7: 1.1.2. | T7: Puerta/Marco liso | U7: Pu | V7: =Z1&Z2 -> 2272 | W7: Plena | Z7: =V7&U7&MID(W7,1,1)&MID(X7,1,1)&MID(Y7,1,3) -> 2272PuP | AA7: =VLOOKUP(Z7,$B$6:$D$426,3,FALSE) -> 014109
A8: 3 | B8: =MID(H8,1,2)&MID(J8,1,2)&MID(L8,1,2)&MID(C8,1,2)&MID(M8,1,1)&MID(N8,1,1)&MID(O8,1,1)&MID(P8,1,3) -> 182010Ma | C8: Marco | D8: 017002 | E8: 014002 | F8: 010020 | G8: =IF(H8<>"","H:","") -> H: | H8: 1800 | I8: =IF(J8<>"","W:","") -> W: | J8: 200 | K8: =IF(L8<>"","D:","") -> D: | L8: 1000 | Q8: =IF(B8<>"",(C8&M8&N8&O8&P8&" / "&G8&H8&I8&J8&K8&L8&" mm"),"") -> Marco / H:1800W:200D:1000 mm | S8: 1.1.3. | T8: Kit paneles laterales | U8: PaL | V8: =Z1&Z3 -> 2260 | W8: Corte | X8: Sencillo | Y8: _NP | Z8: =V8&U8&MID(W8,1,1)&MID(X8,1,1)&MID(Y8,1,3) -> 2260PaLCS_NP | AA8: =VLOOKUP(Z8,$B$6:$D$426,3,FALSE) -> 014620
A9: 4 | B9: =MID(H9,1,2)&MID(J9,1,2)&MID(L9,1,2)&MID(C9,1,2)&MID(M9,1,1)&MID(N9,1,1)&MID(O9,1,1)&MID(P9,1,3) -> 184040Ma | C9: Marco | D9: 017003 | E9: 014000 | F9: 010021 | G9: =IF(H9<>"","H:","") -> H: | H9: 1800 | I9: =IF(J9<>"","W:","") -> W: | J9: 400 | K9: =IF(L9<>"","D:","") -> D: | L9: 400 | Q9: =IF(B9<>"",(C9&M9&N9&O9&P9&" / "&G9&H9&I9&J9&K9&L9&" mm"),"") -> Marco / H:1800W:400D:400 mm | S9: 1.1.4. | T9: Panel posterior | U9: PaP | V9: =Z1&Z2 -> 2272 | W9: Pleno | Z9: =V9&U9&MID(W9,1,1)&MID(X9,1,1)&MID(Y9,1,3) -> 2272PaPP | AA9: =VLOOKUP(Z9,$B$6:$D$426,3,FALSE) -> 014061
A10: 5 | B10: =MID(H10,1,2)&MID(J10,1,2)&MID(L10,1,2)&MID(C10,1,2)&MID(M10,1,1)&MID(N10,1,1)&MID(O10,1,1)&MID(P10,1,3) -> 184060Ma | C10: Marco | D10: 017004 | E10: 014001 | F10: 010021 | G10: =IF(H10<>"","H:","") -> H: | H10: 1800 | I10: =IF(J10<>"","W:","") -> W: | J10: 400 | K10: =IF(L10<>"","D:","") -> D: | L10: 600 | Q10: =IF(B10<>"",(C10&M10&N10&O10&P10&" / "&G10&H10&I10&J10&K10&L10&" mm"),"") -> Marco / H:1800W:400D:600 mm | S10: 1.1.5. | T10: Panel superior | U10: Pa | V10: =Z2&Z3 -> 7260 | W10: Superior | Z10: =V10&U10&MID(W10,1,1)&MID(X10,1,1)&MID(Y10,1,3) -> 7260PaS | AA10: =VLOOKUP(Z10,$B$6:$D$426,3,FALSE) -> 010057
A11: 6 | B11: =MID(H11,1,2)&MID(J11,1,2)&MID(L11,1,2)&MID(C11,1,2)&MID(M11,1,1)&MID(N11,1,1)&MID(O11,1,1)&MID(P11,1,3) -> 184010Ma | C11: Marco | D11: 017005 | E11: 014002 | F11: 010021 | G11: =IF(H11<>"","H:","") -> H: | H11: 1800 | I11: =IF(J11<>"","W:","") -> W: | J11: 400 | K11: =IF(L11<>"","D:","") -> D: | L11: 1000 | Q11: =IF(B11<>"",(C11&M11&N11&O11&P11&" / "&G11&H11&I11&J11&K11&L11&" mm"),"") -> Marco / H:1800W:400D:1000 mm | S11: 1.1.6. | T11: Base inferior | U11: Ba | V11: =Z2&Z3 -> 7260 | W11: Estructural | Z11: =V11&U11&MID(W11,1,1)&MID(X11,1,1)&MID(Y11,1,3) -> 7260BaE | AA11: =VLOOKUP(Z11,$B$6:$D$426,3,FALSE) -> 015007
A12: 7 | B12: =MID(H12,1,2)&MID(J12,1,2)&MID(L12,1,2)&MID(C12,1,2)&MID(M12,1,1)&MID(N12,1,1)&MID(O12,1,1)&MID(P12,1,3) -> 187240Ma | C12: Marco | D12: 017006 | E12: 014000 | F12: 010022 | G12: =IF(H12<>"","H:","") -> H: | H12: 1800 | I12: =IF(J12<>"","W:","") -> W: | J12: 720 | K12: =IF(L12<>"","D:","") -> D: | L12: 400 | Q12: =IF(B12<>"",(C12&M12&N12&O12&P12&" / "&G12&H12&I12&J12&K12&L12&" mm"),"") -> Marco / H:1800W:720D:400 mm | S12: 1.1.7. | T12: Kit tapa zocalos laterales | U12: Zo | V12: =Z3 -> 60 | W12: Laterales | Z12: =V12&U12&MID(W12,1,1)&MID(X12,1,1)&MID(Y12,1,3) -> 60ZoL | AA12: =VLOOKUP(Z12,$B$6:$D$426,3,FALSE) -> 010177
A13: 8 | B13: =MID(H13,1,2)&MID(J13,1,2)&MID(L13,1,2)&MID(C13,1,2)&MID(M13,1,1)&MID(N13,1,1)&MID(O13,1,1)&MID(P13,1,3) -> 187260Ma | C13: Marco | D13: 017007 | E13: 014001 | F13: 010022 | G13: =IF(H13<>"","H:","") -> H: | H13: 1800 | I13: =IF(J13<>"","W:","") -> W: | J13: 720 | K13: =IF(L13<>"","D:","") -> D: | L13: 600 | Q13: =IF(B13<>"",(C13&M13&N13&O13&P13&" / "&G13&H13&I13&J13&K13&L13&" mm"),"") -> Marco / H:1800W:720D:600 mm | S13: 1.1.8. | T13: Kit tapa zocalos Frontales | U13: Zo | V13: =Z2 -> 72 | W13: Frontales | Z13: =V13&U13&MID(W13,1,1)&MID(X13,1,1)&MID(Y13,1,3) -> 72ZoF | AA13: =VLOOKUP(Z13,$B$6:$D$426,3,FALSE) -> 010178
A14: 9 | B14: =MID(H14,1,2)&MID(J14,1,2)&MID(L14,1,2)&MID(C14,1,2)&MID(M14,1,1)&MID(N14,1,1)&MID(O14,1,1)&MID(P14,1,3) -> 187210Ma | C14: Marco | D14: 017008 | E14: 014002 | F14: 010022 | G14: =IF(H14<>"","H:","") -> H: | H14: 1800 | I14: =IF(J14<>"","W:","") -> W: | J14: 720 | K14: =IF(L14<>"","D:","") -> D: | L14: 1000 | Q14: =IF(B14<>"",(C14&M14&N14&O14&P14&" / "&G14&H14&I14&J14&K14&L14&" mm"),"") -> Marco / H:1800W:720D:1000 mm | S14: 1.1.9. | T14: Pane linferior | U14: Pa | V14: =Z2&Z3 -> 7260 | W14: Inferior | Z14: =V14&U14&MID(W14,1,1)&MID(X14,1,1)&MID(Y14,1,3) -> 7260PaI | AA14: =VLOOKUP(Z14,$B$6:$D$426,3,FALSE) -> 014257
A15: 10 | B15: =MID(H15,1,2)&MID(J15,1,2)&MID(L15,1,2)&MID(C15,1,2)&MID(M15,1,1)&MID(N15,1,1)&MID(O15,1,1)&MID(P15,1,3) -> 181140Ma | C15: Marco | D15: 017009 | E15: 014000 | F15: 010024 | G15: =IF(H15<>"","H:","") -> H: | H15: 1800 | I15: =IF(J15<>"","W:","") -> W: | J15: 1120 | K15: =IF(L15<>"","D:","") -> D: | L15: 400 | Q15: =IF(B15<>"",(C15&M15&N15&O15&P15&" / "&G15&H15&I15&J15&K15&L15&" mm"),"") -> Marco / H:1800W:1120D:400 mm | S15: 1.1.10. | T15: Paral interno vertical total | U15: PaIV | V15: =Z1 -> 22 | W15: Total | Z15: =V15&U15&MID(W15,1,1)&MID(X15,1,1)&MID(Y15,1,3) -> 22PaIVT | AA15: =VLOOKUP(Z15,$B$6:$D$426,3,FALSE) -> 014154
A16: 11 | B16: =MID(H16,1,2)&MID(J16,1,2)&MID(L16,1,2)&MID(C16,1,2)&MID(M16,1,1)&MID(N16,1,1)&MID(O16,1,1)&MID(P16,1,3) -> 181160Ma | C16: Marco | D16: 017010 | E16: 014001 | F16: 010024 | G16: =IF(H16<>"","H:","") -> H: | H16: 1800 | I16: =IF(J16<>"","W:","") -> W: | J16: 1120 | K16: =IF(L16<>"","D:","") -> D: | L16: 600 | Q16: =IF(B16<>"",(C16&M16&N16&O16&P16&" / "&G16&H16&I16&J16&K16&L16&" mm"),"") -> Marco / H:1800W:1120D:600 mm | S16: 1.1.11. | T16: Paral interno vertical intermedio | U16: PaI | V16: 600 | W16: Vertical | Z16: =MID(V16,1,2)&U16&MID(W16,1,1)&MID(X16,1,1)&MID(Y16,1,3) -> 60PaIV | AA16: =VLOOKUP(Z16,$B$6:$D$426,3,FALSE) -> 014150
A17: 12 | B17: =MID(H17,1,2)&MID(J17,1,2)&MID(L17,1,2)&MID(C17,1,2)&MID(M17,1,1)&MID(N17,1,1)&MID(O17,1,1)&MID(P17,1,3) -> 181110Ma | C17: Marco | D17: 017011 | E17: 014002 | F17: 010024 | G17: =IF(H17<>"","H:","") -> H: | H17: 1800 | I17: =IF(J17<>"","W:","") -> W: | J17: 1120 | K17: =IF(L17<>"","D:","") -> D: | L17: 1000 | Q17: =IF(B17<>"",(C17&M17&N17&O17&P17&" / "&G17&H17&I17&J17&K17&L17&" mm"),"") -> Marco / H:1800W:1120D:1000 mm | S17: 1.1.12. | T17: Paral interno horizontal | U17: PaI | V17: 600 | W17: Horizontal | Z17: =MID(V17,1,2)&U17&MID(W17,1,1)&MID(X17,1,1)&MID(Y17,1,3) -> 60PaIH | AA17: =VLOOKUP(Z17,$B$6:$D$426,3,FALSE) -> 10285
A18: 13 | B18: =MID(H18,1,2)&MID(J18,1,2)&MID(L18,1,2)&MID(C18,1,2)&MID(M18,1,1)&MID(N18,1,1)&MID(O18,1,1)&MID(P18,1,3) -> 202040Ma | C18: Marco | D18: 017012 | E18: 014003 | F18: 010020 | G18: =IF(H18<>"","H:","") -> H: | H18: 2000 | I18: =IF(J18<>"","W:","") -> W: | J18: 200 | K18: =IF(L18<>"","D:","") -> D: | L18: 400 | Q18: =IF(B18<>"",(C18&M18&N18&O18&P18&" / "&G18&H18&I18&J18&K18&L18&" mm"),"") -> Marco / H:2000W:200D:400 mm | S18: 1.1.13. | T18: Ducto de cables | U18: DuC | V18: =Z2 -> 72 | Z18: =V18&U18&MID(W18,1,1)&MID(X18,1,1)&MID(Y18,1,3) -> 72DuC | AA18: =VLOOKUP(Z18,$B$6:$D$426,3,FALSE) -> 014301
A19: 14 | B19: =MID(H19,1,2)&MID(J19,1,2)&MID(L19,1,2)&MID(C19,1,2)&MID(M19,1,1)&MID(N19,1,1)&MID(O19,1,1)&MID(P19,1,3) -> 202060Ma | C19: Marco | D19: 017013 | E19: 014004 | F19: 010020 | G19: =IF(H19<>"","H:","") -> H: | H19: 2000 | I19: =IF(J19<>"","W:","") -> W: | J19: 200 | K19: =IF(L19<>"","D:","") -> D: | L19: 600 | Q19: =IF(B19<>"",(C19&M19&N19&O19&P19&" / "&G19&H19&I19&J19&K19&L19&" mm"),"") -> Marco / H:2000W:200D:600 mm | S19: 1.1.14. | T19: Kit union posterior | U19: Ki | W19: Union | X19: Posterior | Z19: =V19&U19&MID(W19,1,1)&MID(X19,1,1)&MID(Y19,1,3) -> KiUP | AA19: =VLOOKUP(Z19,$B$6:$D$426,3,FALSE) -> 012000
A20: 15 | B20: =MID(H20,1,2)&MID(J20,1,2)&MID(L20,1,2)&MID(C20,1,2)&MID(M20,1,1)&MID(N20,1,1)&MID(O20,1,1)&MID(P20,1,3) -> 202010Ma | C20: Marco | D20: 017014 | E20: 014005 | F20: 010020 | G20: =IF(H20<>"","H:","") -> H: | H20: 2000 | I20: =IF(J20<>"","W:","") -> W: | J20: 200 | K20: =IF(L20<>"","D:","") -> D: | L20: 1000 | Q20: =IF(B20<>"",(C20&M20&N20&O20&P20&" / "&G20&H20&I20&J20&K20&L20&" mm"),"") -> Marco / H:2000W:200D:1000 mm | S20: 1.1.15. | T20: Segregación frontal* | U20: Se | V20: =Z1&Z2 -> 2272 | W20: Frontales | Z20: =V20&U20&MID(W20,1,1)&MID(X20,1,1)&MID(Y20,1,3) -> 2272SeF | AA20: =VLOOKUP(Z20,$B$6:$D$426,3,FALSE) -> #N/A
A21: 16 | B21: =MID(H21,1,2)&MID(J21,1,2)&MID(L21,1,2)&MID(C21,1,2)&MID(M21,1,1)&MID(N21,1,1)&MID(O21,1,1)&MID(P21,1,3) -> 204040Ma | C21: Marco | D21: 017015 | E21: 014003 | F21: 010021 | G21: =IF(H21<>"","H:","") -> H: | H21: 2000 | I21: =IF(J21<>"","W:","") -> W: | J21: 400 | K21: =IF(L21<>"","D:","") -> D: | L21: 400 | Q21: =IF(B21<>"",(C21&M21&N21&O21&P21&" / "&G21&H21&I21&J21&K21&L21&" mm"),"") -> Marco / H:2000W:400D:400 mm
A22: 17 | B22: =MID(H22,1,2)&MID(J22,1,2)&MID(L22,1,2)&MID(C22,1,2)&MID(M22,1,1)&MID(N22,1,1)&MID(O22,1,1)&MID(P22,1,3) -> 204060Ma | C22: Marco | D22: 017016 | E22: 014004 | F22: 010021 | G22: =IF(H22<>"","H:","") -> H: | H22: 2000 | I22: =IF(J22<>"","W:","") -> W: | J22: 400 | K22: =IF(L22<>"","D:","") -> D: | L22: 600 | Q22: =IF(B22<>"",(C22&M22&N22&O22&P22&" / "&G22&H22&I22&J22&K22&L22&" mm"),"") -> Marco / H:2000W:400D:600 mm | S22: 1.2.1. | T22: Hablador | Z22: =V22&U22&MID(W22,1,1)&MID(X22,1,1)&MID(Y22,1,3) | AA22: SinReferencia
A23: 18 | B23: =MID(H23,1,2)&MID(J23,1,2)&MID(L23,1,2)&MID(C23,1,2)&MID(M23,1,1)&MID(N23,1,1)&MID(O23,1,1)&MID(P23,1,3) -> 204010Ma | C23: Marco | D23: 017017 | E23: 014005 | F23: 010021 | G23: =IF(H23<>"","H:","") -> H: | H23: 2000 | I23: =IF(J23<>"","W:","") -> W: | J23: 400 | K23: =IF(L23<>"","D:","") -> D: | L23: 1000 | Q23: =IF(B23<>"",(C23&M23&N23&O23&P23&" / "&G23&H23&I23&J23&K23&L23&" mm"),"") -> Marco / H:2000W:400D:1000 mm | S23: 1.2.2. | T23: Kit de cancamos | U23: CaE | Z23: =V23&U23&MID(W23,1,1)&MID(X23,1,1)&MID(Y23,1,3) -> CaE | AA23: =VLOOKUP(Z23,$B$6:$D$426,3,FALSE) -> 014501
A24: 19 | B24: =MID(H24,1,2)&MID(J24,1,2)&MID(L24,1,2)&MID(C24,1,2)&MID(M24,1,1)&MID(N24,1,1)&MID(O24,1,1)&MID(P24,1,3) -> 207240Ma | C24: Marco | D24: 017018 | E24: 014003 | F24: 010022 | G24: =IF(H24<>"","H:","") -> H: | H24: 2000 | I24: =IF(J24<>"","W:","") -> W: | J24: 720 | K24: =IF(L24<>"","D:","") -> D: | L24: 400 | Q24: =IF(B24<>"",(C24&M24&N24&O24&P24&" / "&G24&H24&I24&J24&K24&L24&" mm"),"") -> Marco / H:2000W:720D:400 mm | S24: 1.2.3. | T24: Angulo de izaje | U24: AnI | Z24: =V24&U24&MID(W24,1,1)&MID(X24,1,1)&MID(Y24,1,3) -> AnI | AA24: =VLOOKUP(Z24,$B$6:$D$426,3,FALSE) -> 014502
A25: 20 | B25: =MID(H25,1,2)&MID(J25,1,2)&MID(L25,1,2)&MID(C25,1,2)&MID(M25,1,1)&MID(N25,1,1)&MID(O25,1,1)&MID(P25,1,3) -> 207260Ma | C25: Marco | D25: 017019 | E25: 014004 | F25: 010022 | G25: =IF(H25<>"","H:","") -> H: | H25: 2000 | I25: =IF(J25<>"","W:","") -> W: | J25: 720 | K25: =IF(L25<>"","D:","") -> D: | L25: 600 | Q25: =IF(B25<>"",(C25&M25&N25&O25&P25&" / "&G25&H25&I25&J25&K25&L25&" mm"),"") -> Marco / H:2000W:720D:600 mm | S25: 1.2.4. | T25: Grua | Z25: =V25&U25&MID(W25,1,1)&MID(X25,1,1)&MID(Y25,1,3) | AA25: SinReferencia
A26: 21 | B26: =MID(H26,1,2)&MID(J26,1,2)&MID(L26,1,2)&MID(C26,1,2)&MID(M26,1,1)&MID(N26,1,1)&MID(O26,1,1)&MID(P26,1,3) -> 207210Ma | C26: Marco | D26: 017020 | E26: 014005 | F26: 010022 | G26: =IF(H26<>"","H:","") -> H: | H26: 2000 | I26: =IF(J26<>"","W:","") -> W: | J26: 720 | K26: =IF(L26<>"","D:","") -> D: | L26: 1000 | Q26: =IF(B26<>"",(C26&M26&N26&O26&P26&" / "&G26&H26&I26&J26&K26&L26&" mm"),"") -> Marco / H:2000W:720D:1000 mm
A27: 22 | B27: =MID(H27,1,2)&MID(J27,1,2)&MID(L27,1,2)&MID(C27,1,2)&MID(M27,1,1)&MID(N27,1,1)&MID(O27,1,1)&MID(P27,1,3) -> 208060Ma | C27: Marco | D27: 017021 | E27: 014004 | F27: 010023 | G27: =IF(H27<>"","H:","") -> H: | H27: 2000 | I27: =IF(J27<>"","W:","") -> W: | J27: 800 | K27: =IF(L27<>"","D:","") -> D: | L27: 600 | Q27: =IF(B27<>"",(C27&M27&N27&O27&P27&" / "&G27&H27&I27&J27&K27&L27&" mm"),"") -> Marco / H:2000W:800D:600 mm | S27: 1.3.1. | T27: Cubierta para modulo | AA27: SinReferencia
A28: 23 | B28: =MID(H28,1,2)&MID(J28,1,2)&MID(L28,1,2)&MID(C28,1,2)&MID(M28,1,1)&MID(N28,1,1)&MID(O28,1,1)&MID(P28,1,3) -> 208010Ma | C28: Marco | D28: 017022 | E28: 014005 | F28: 010023 | G28: =IF(H28<>"","H:","") -> H: | H28: 2000 | I28: =IF(J28<>"","W:","") -> W: | J28: 800 | K28: =IF(L28<>"","D:","") -> D: | L28: 1000 | Q28: =IF(B28<>"",(C28&M28&N28&O28&P28&" / "&G28&H28&I28&J28&K28&L28&" mm"),"") -> Marco / H:2000W:800D:1000 mm | S28: 1.3.2. | T28: Cubierta para ventilación | AA28: SinReferencia
A29: 24 | B29: =MID(H29,1,2)&MID(J29,1,2)&MID(L29,1,2)&MID(C29,1,2)&MID(M29,1,1)&MID(N29,1,1)&MID(O29,1,1)&MID(P29,1,3) -> 201140Ma | C29: Marco | D29: 017023 | E29: 014003 | F29: 010024 | G29: =IF(H29<>"","H:","") -> H: | H29: 2000 | I29: =IF(J29<>"","W:","") -> W: | J29: 1120 | K29: =IF(L29<>"","D:","") -> D: | L29: 400 | Q29: =IF(B29<>"",(C29&M29&N29&O29&P29&" / "&G29&H29&I29&J29&K29&L29&" mm"),"") -> Marco / H:2000W:1120D:400 mm | S29: 1.4.1. | T29: Cubierta de ventilación | AA29: SinReferencia
A30: 25 | B30: =MID(H30,1,2)&MID(J30,1,2)&MID(L30,1,2)&MID(C30,1,2)&MID(M30,1,1)&MID(N30,1,1)&MID(O30,1,1)&MID(P30,1,3) -> 201160Ma | C30: Marco | D30: 017024 | E30: 014004 | F30: 010024 | G30: =IF(H30<>"","H:","") -> H: | H30: 2000 | I30: =IF(J30<>"","W:","") -> W: | J30: 1120 | K30: =IF(L30<>"","D:","") -> D: | L30: 600 | Q30: =IF(B30<>"",(C30&M30&N30&O30&P30&" / "&G30&H30&I30&J30&K30&L30&" mm"),"") -> Marco / H:2000W:1120D:600 mm | S30: 1.4.2. | T30: Segregación | AA30: SinReferencia
A31: 26 | B31: =MID(H31,1,2)&MID(J31,1,2)&MID(L31,1,2)&MID(C31,1,2)&MID(M31,1,1)&MID(N31,1,1)&MID(O31,1,1)&MID(P31,1,3) -> 201110Ma | C31: Marco | D31: 017025 | E31: 014005 | F31: 010024 | G31: =IF(H31<>"","H:","") -> H: | H31: 2000 | I31: =IF(J31<>"","W:","") -> W: | J31: 1120 | K31: =IF(L31<>"","D:","") -> D: | L31: 1000 | Q31: =IF(B31<>"",(C31&M31&N31&O31&P31&" / "&G31&H31&I31&J31&K31&L31&" mm"),"") -> Marco / H:2000W:1120D:1000 mm
A32: 27 | B32: =MID(H32,1,2)&MID(J32,1,2)&MID(L32,1,2)&MID(C32,1,2)&MID(M32,1,1)&MID(N32,1,1)&MID(O32,1,1)&MID(P32,1,3) -> 222040Ma | C32: Marco | D32: 017026 | E32: 014006 | F32: 010020 | G32: =IF(H32<>"","H:","") -> H: | H32: 2200 | I32: =IF(J32<>"","W:","") -> W: | J32: 200 | K32: =IF(L32<>"","D:","") -> D: | L32: 400 | Q32: =IF(B32<>"",(C32&M32&N32&O32&P32&" / "&G32&H32&I32&J32&K32&L32&" mm"),"") -> Marco / H:2200W:200D:400 mm | S32: 1.5.1. | T32: Cubierta de ventilación | Z32: =V32&U32&MID(W32,1,1)&MID(X32,1,1)&MID(Y32,1,3) | AA32: =VLOOKUP(Z32,$B$6:$D$426,3,FALSE) -> 0
A33: 28 | B33: =MID(H33,1,2)&MID(J33,1,2)&MID(L33,1,2)&MID(C33,1,2)&MID(M33,1,1)&MID(N33,1,1)&MID(O33,1,1)&MID(P33,1,3) -> 222060Ma | C33: Marco | D33: 017027 | E33: 014007 | F33: 010020 | G33: =IF(H33<>"","H:","") -> H: | H33: 2200 | I33: =IF(J33<>"","W:","") -> W: | J33: 200 | K33: =IF(L33<>"","D:","") -> D: | L33: 600 | Q33: =IF(B33<>"",(C33&M33&N33&O33&P33&" / "&G33&H33&I33&J33&K33&L33&" mm"),"") -> Marco / H:2200W:200D:600 mm | S33: 1.5.2. | T33: Accesorio de poste | AA33: SinReferencia
A34: 29 | B34: =MID(H34,1,2)&MID(J34,1,2)&MID(L34,1,2)&MID(C34,1,2)&MID(M34,1,1)&MID(N34,1,1)&MID(O34,1,1)&MID(P34,1,3) -> 222010Ma | C34: Marco | D34: 017028 | E34: 014008 | F34: 010020 | G34: =IF(H34<>"","H:","") -> H: | H34: 2200 | I34: =IF(J34<>"","W:","") -> W: | J34: 200 | K34: =IF(L34<>"","D:","") -> D: | L34: 1000 | Q34: =IF(B34<>"",(C34&M34&N34&O34&P34&" / "&G34&H34&I34&J34&K34&L34&" mm"),"") -> Marco / H:2200W:200D:1000 mm | S34: 1.5.3. | T34: Accesorio de muro | AA34: SinReferencia
A35: 30 | B35: =MID(H35,1,2)&MID(J35,1,2)&MID(L35,1,2)&MID(C35,1,2)&MID(M35,1,1)&MID(N35,1,1)&MID(O35,1,1)&MID(P35,1,3) -> 224040Ma | C35: Marco | D35: 017029 | E35: 014006 | F35: 010021 | G35: =IF(H35<>"","H:","") -> H: | H35: 2200 | I35: =IF(J35<>"","W:","") -> W: | J35: 400 | K35: =IF(L35<>"","D:","") -> D: | L35: 400 | Q35: =IF(B35<>"",(C35&M35&N35&O35&P35&" / "&G35&H35&I35&J35&K35&L35&" mm"),"") -> Marco / H:2200W:400D:400 mm | S35: 1.5.4. | T35: Segregación | AA35: SinReferencia
A36: 31 | B36: =MID(H36,1,2)&MID(J36,1,2)&MID(L36,1,2)&MID(C36,1,2)&MID(M36,1,1)&MID(N36,1,1)&MID(O36,1,1)&MID(P36,1,3) -> 224060Ma | C36: Marco | D36: 017030 | E36: 014007 | F36: 010021 | G36: =IF(H36<>"","H:","") -> H: | H36: 2200 | I36: =IF(J36<>"","W:","") -> W: | J36: 400 | K36: =IF(L36<>"","D:","") -> D: | L36: 600 | Q36: =IF(B36<>"",(C36&M36&N36&O36&P36&" / "&G36&H36&I36&J36&K36&L36&" mm"),"") -> Marco / H:2200W:400D:600 mm | S36: 1.6.1. | T36: Placa para modulo | U36: PlM | W36: Grande | Z36: =V36&U36&MID(W36,1,1)&MID(X36,1,1)&MID(Y36,1,3) -> PlMG | AA36: =VLOOKUP(Z36,$B$6:$D$426,3,FALSE) -> 013202
A37: 32 | B37: =MID(H37,1,2)&MID(J37,1,2)&MID(L37,1,2)&MID(C37,1,2)&MID(M37,1,1)&MID(N37,1,1)&MID(O37,1,1)&MID(P37,1,3) -> 224010Ma | C37: Marco | D37: 017031 | E37: 014008 | F37: 010021 | G37: =IF(H37<>"","H:","") -> H: | H37: 2200 | I37: =IF(J37<>"","W:","") -> W: | J37: 400 | K37: =IF(L37<>"","D:","") -> D: | L37: 1000 | Q37: =IF(B37<>"",(C37&M37&N37&O37&P37&" / "&G37&H37&I37&J37&K37&L37&" mm"),"") -> Marco / H:2200W:400D:1000 mm | S37: 1.6.2. | T37: Tapa del modulo | U37: TaM | W37: PM6 | Z37: =V37&U37&MID(W37,1,3)&MID(X37,1,3)&MID(Y37,1,3) -> TaMPM6 | AA37: =VLOOKUP(Z37,$B$6:$D$426,3,FALSE) -> 012111
A38: 33 | B38: =MID(H38,1,2)&MID(J38,1,2)&MID(L38,1,2)&MID(C38,1,2)&MID(M38,1,1)&MID(N38,1,1)&MID(O38,1,1)&MID(P38,1,3) -> 227240Ma | C38: Marco | D38: 017032 | E38: 014006 | F38: 010022 | G38: =IF(H38<>"","H:","") -> H: | H38: 2200 | I38: =IF(J38<>"","W:","") -> W: | J38: 720 | K38: =IF(L38<>"","D:","") -> D: | L38: 400 | Q38: =IF(B38<>"",(C38&M38&N38&O38&P38&" / "&G38&H38&I38&J38&K38&L38&" mm"),"") -> Marco / H:2200W:720D:400 mm
A39: 34 | B39: =MID(H39,1,2)&MID(J39,1,2)&MID(L39,1,2)&MID(C39,1,2)&MID(M39,1,1)&MID(N39,1,1)&MID(O39,1,1)&MID(P39,1,3) -> 227260Ma | C39: Marco | D39: 017033 | E39: 014007 | F39: 010022 | G39: =IF(H39<>"","H:","") -> H: | H39: 2200 | I39: =IF(J39<>"","W:","") -> W: | J39: 720 | K39: =IF(L39<>"","D:","") -> D: | L39: 600 | Q39: =IF(B39<>"",(C39&M39&N39&O39&P39&" / "&G39&H39&I39&J39&K39&L39&" mm"),"") -> Marco / H:2200W:720D:600 mm
A40: 35 | B40: =MID(H40,1,2)&MID(J40,1,2)&MID(L40,1,2)&MID(C40,1,2)&MID(M40,1,1)&MID(N40,1,1)&MID(O40,1,1)&MID(P40,1,3) -> 227210Ma | C40: Marco | D40: 017034 | E40: 014008 | F40: 010022 | G40: =IF(H40<>"","H:","") -> H: | H40: 2200 | I40: =IF(J40<>"","W:","") -> W: | J40: 720 | K40: =IF(L40<>"","D:","") -> D: | L40: 1000 | Q40: =IF(B40<>"",(C40&M40&N40&O40&P40&" / "&G40&H40&I40&J40&K40&L40&" mm"),"") -> Marco / H:2200W:720D:1000 mm
...

Sheet Portada
C1: Alto : | I1: H | J1: =MID(K1,1,2) -> 20 | K1: 2000
C2: Ancho : | I2: W | J2: =MID(K2,1,2) -> 72 | K2: 720
C3: Profundo: | I3: D | J3: =MID(K3,1,2) -> 60 | K3: 600
C4: IP: | K4: 30
E5: Categoria | F5: Criterio5 | G5: Criterio1 | H5: Criterio2 | I5: Criterio3 | J5: CodigoB | K5: Codigo
C6: 1.1.1. | D6: Marco | E6: Ma | F6: =J1&J2&J3 -> 207260 | J6: =F6&E6&MID(G6,1,1)&MID(H6,1,1)&MID(I6,1,3) -> 207260Ma | K6: =VLOOKUP(J6,BD!$B$6:$F$426,3,FALSE) -> 017019 | M6: Puerta | O6: Panel Lateral | Q6: Panel Posterior
C7: 1.1.2. | D7: Puerta/Marco liso | E7: Pu | F7: =J1&J2 -> 2072 | G7: Vidrio | J7: =F7&E7&MID(G7,1,1)&MID(H7,1,1)&MID(I7,1,3) -> 2072PuV | K7: =VLOOKUP(J7,BD!$B$6:$F$426,3,FALSE) -> 014689 | M7: Plena | O7: Plena | Q7: Pleno
C8: 1.1.3. | D8: Kit paneles laterales | E8: PaL | F8: =J1&J3 -> 2060 | G8: Corte | H8: Sencillo | I8: _NP | J8: =F8&E8&MID(G8,1,1)&MID(H8,1,1)&MID(I8,1,3) -> 2060PaLCS_NP | K8: =VLOOKUP(J8,BD!$B$6:$F$426,3,FALSE) -> 014617 | M8: Vidrio
C9: 1.1.4. | D9: Panel posterior | E9: PaP | F9: =J1&J2 -> 2072 | G9: Corte | H9: Doble | I9: _SE | J9: =F9&E9&MID(G9,1,1)&MID(H9,1,1)&MID(I9,1,3) -> 2072PaPCD_SE | K9: =VLOOKUP(J9,BD!$B$6:$F$426,3,FALSE) -> 014512 | M9: Corte Sencillo | N9: _SE | O9: Corte Sencillo | P9: _SE | Q9: Corte Sencillo | R9: _SE
C10: 1.1.5. | D10: Panel superior | E10: Pa | F10: =J2&J3 -> 7260 | G10: Superior | J10: =F10&E10&MID(G10,1,1)&MID(H10,1,1)&MID(I10,1,3) -> 7260PaS | K10: =VLOOKUP(J10,BD!$B$6:$F$426,3,FALSE) -> 010057 | N10: _NP | P10: _NP | R10: _NP
C11: 1.1.6. | D11: Base inferior | E11: Ba | F11: =J2&J3 -> 7260 | G11: Estructural | J11: =F11&E11&MID(G11,1,1)&MID(H11,1,1)&MID(I11,1,3) -> 7260BaE | K11: =VLOOKUP(J11,BD!$B$6:$F$426,3,FALSE) -> 015007 | N11: _NM | P11: _NM | R11: _NM
C12: 1.1.7. | D12: Kit tapa zocalos laterales | E12: Zo | F12: =J3 -> 60 | G12: Laterales | J12: =F12&E12&MID(G12,1,1)&MID(H12,1,1)&MID(I12,1,3) -> 60ZoL | K12: =VLOOKUP(J12,BD!$B$6:$F$426,3,FALSE) -> 010177 | N12: _NG | P12: _NG | R12: _NG
C13: 1.1.8. | D13: Kit tapa zocalos Frontales | E13: Zo | F13: =J2 -> 72 | G13: Frontales | J13: =F13&E13&MID(G13,1,1)&MID(H13,1,1)&MID(I13,1,3) -> 72ZoF | K13: =VLOOKUP(J13,BD!$B$6:$F$426,3,FALSE) -> 010178 | M13: Corte Doble | N13: _SE | Q13: Corte Doble | R13: _SE
C14: 1.1.9. | D14: Pane linferior | E14: Pa | F14: =J2&J3 -> 7260 | G14: Inferior | J14: =F14&E14&MID(G14,1,1)&MID(H14,1,1)&MID(I14,1,3) -> 7260PaI | K14: =VLOOKUP(J14,BD!$B$6:$F$426,3,FALSE) -> 014257 | N14: _NP | R14: _NP
C15: 1.1.10. | D15: Paral interno vertical total | E15: PaIV | F15: =J1 -> 20 | G15: Total | J15: =F15&E15&MID(G15,1,1)&MID(H15,1,1)&MID(I15,1,3) -> 20PaIVT | K15: =VLOOKUP(J15,BD!$B$6:$F$426,3,FALSE) -> 014153 | N15: _NM | R15: _NM
C16: 1.1.11. | D16: Paral interno vertical intermedio | E16: PaI | F16: 600 | G16: Vertical | J16: =MID(F16,1,2)&E16&MID(G16,1,1)&MID(H16,1,1)&MID(I16,1,3) -> 60PaIV | K16: =VLOOKUP(J16,BD!$B$6:$F$426,3,FALSE) -> 014150 | N16: _NG | R16: _NG
C17: 1.1.12. | D17: Paral interno horizontal | E17: PaI | F17: 600 | G17: Horizontal | J17: =MID(F17,1,2)&E17&MID(G17,1,1)&MID(H17,1,1)&MID(I17,1,3) -> 60PaIH | K17: =VLOOKUP(J17,BD!$B$6:$F$426,3,FALSE) -> 10285 | M17: Corte Placa | N17: _Pe
C18: 1.1.13. | D18: Ducto de cables | E18: DuC | F18: =J2 -> 72 | J18: =F18&E18&MID(G18,1,1)&MID(H18,1,1)&MID(I18,1,3) -> 72DuC | K18: =VLOOKUP(J18,BD!$B$6:$F$426,3,FALSE) -> 014301 | N18: _Me
C19: 1.1.14. | D19: Kit union posterior | E19: Ki | G19: Union | H19: Posterior | J19: =F19&E19&MID(G19,1,1)&MID(H19,1,1)&MID(I19,1,3) -> KiUP | K19: =VLOOKUP(J19,BD!$B$6:$F$426,3,FALSE) -> 012000 | N19: _Gr
C20: 1.1.15. | D20: Segregación frontal* | E20: Se | F20: =J1&J2 -> 2072 | G20: Frontales | J20: =F20&E20&MID(G20,1,1)&MID(H20,1,1)&MID(I20,1,3) -> 2072SeF | K20: =VLOOKUP(J20,BD!$B$6:$F$426,3,FALSE) -> #N/A
C22: 1.2.1. | D22: Hablador | J22: =F22&E22&MID(G22,1,1)&MID(H22,1,1)&MID(I22,1,3) | K22: SinReferencia
C23: 1.2.2. | D23: Kit de cancamos | E23: CaE | J23: =F23&E23&MID(G23,1,1)&MID(H23,1,1)&MID(I23,1,3) -> CaE | K23: =VLOOKUP(J23,BD!$B$6:$F$426,3,FALSE) -> 014501
C24: 1.2.3. | D24: Angulo de izaje | E24: AnI | J24: =F24&E24&MID(G24,1,1)&MID(H24,1,1)&MID(I24,1,3) -> AnI | K24: =VLOOKUP(J24,BD!$B$6:$F$426,3,FALSE) -> 014502
C25: 1.2.4. | D25: Grua | J25: =F25&E25&MID(G25,1,1)&MID(H25,1,1)&MID(I25,1,3) | K25: SinReferencia
C27: 1.3.1. | D27: Cubierta para modulo | K27: SinReferencia
C28: 1.3.2. | D28: Cubierta para ventilación | K28: SinReferencia
C29: 1.4.1. | D29: Cubierta de ventilación | K29: SinReferencia
C30: 1.4.2. | D30: Segregación | K30: SinReferencia
C32: 1.5.1. | D32: Cubierta de ventilación | J32: =F32&E32&MID(G32,1,1)&MID(H32,1,1)&MID(I32,1,3) | K32: =VLOOKUP(J32,BD!$B$6:$F$426,3,FALSE) -> 0
C33: 1.5.2. | D33: Accesorio de poste | K33: SinReferencia
C34: 1.5.3. | D34: Accesorio de muro | K34: SinReferencia
C35: 1.5.4. | D35: Segregación | K35: SinReferencia
C36: 1.6.1. | D36: Placa para modulo | E36: PlM | G36: Grande | J36: =F36&E36&MID(G36,1,1)&MID(H36,1,1)&MID(I36,1,3) -> PlMG | K36: =VLOOKUP(J36,BD!$B$6:$F$426,3,FALSE) -> 013202
C37: 1.6.2. | D37: Tapa del modulo | E37: TaM | G37: PM6 | J37: =F37&E37&MID(G37,1,3)&MID(H37,1,3)&MID(I37,1,3) -> TaMPM6 | K37: =VLOOKUP(J37,BD!$B$6:$F$426,3,FALSE) -> 012111

Sheet Formato
B2: Alto : | D2: 2000 | E2: =MID(D2,1,2) -> 20 | I2: Codigo de pedido
B3: Ancho : | D3: 720 | E3: =MID(D3,1,2) -> 72
B4: Profundo: | D4: 600 | E4: =MID(D4,1,2) -> 60
B5: IP: | D5: 30
B6: 1.1.1. | C6: Marco | E6: =E2&E3&E4 -> 207260 | F6: Ma | H6: =E6&F6&G6 -> 207260Ma | I6: =IFERROR(VLOOKUP(H6,BD!$B$6:$F$426,3,FALSE),"") -> 017019
B7: 1.1.2. | C7: Puerta/Marco liso | D7: CortePlacaGrande | E7: =E2&E3 -> 2072 | F7: Pu | G7: {=_xlfn.IFS(D7="Plena","P",D7="CortePlacaPequeña","CP_Pe",D7="CortePlacaMediana","CP_ME",D7="CortePlacaGrande","CP_Gr",D7="CorteSencillo_Schneider","CS_SE",D7="CorteSencilloNatural_Pequeño","CS_NP",D7="CorteSencilloNatural_Mediano","CS_NM",D7="CorteSencilloNatural_Grande","CS_NG",D7="CorteDoble_Schneider","CD_SE",D7="CorteDobleNatural_Pequeño","CD_NP",D7="CorteDobleNatural_Mediano","CD_NM",D7="CorteDobleNatural_Grande","CD_NG",D7="Vidrio","V",D7="MarcoLiso","MaL")} -> CP_Gr | H7: =IF(G7="MaL",E7&G7,E7&F7&G7) -> 2072PuCP_Gr | I7: =IFERROR(VLOOKUP(H7,BD!$B$6:$F$426,3,FALSE),"") -> 014116 | R7: Plena | S7: P | T7: Pleno | V7: Pleno
B8: 1.1.3. | C8: Kit paneles laterales | D8: Pleno | E8: =E2&E4 -> 2060 | F8: PaL | G8: {=_xlfn.IFS(D8="Pleno","P",D8="CorteSencillo_Schneider","CS_SE",D8="CorteSencilloNatural_Pequeño","CS_NP",D8="CorteSencilloNatural_Mediano","CS_NM",D8="CorteSencilloNatural_Grande","CS_NG")} -> P | H8: =E8&F8&G8 -> 2060PaLP | I8: =IFERROR(VLOOKUP(H8,BD!$B$6:$F$426,3,FALSE),"") -> 014029 | R8: CortePlacaPequeña | S8: CP_Pe | T8: CorteSencillo_Schneider | U8: CS_SE | V8: CorteSencillo_Schneider | W8: CS_SE
B9: 1.1.4. | C9: Panel posterior | D9: Pleno | E9: =E2&E3 -> 2072 | F9: PaP | G9: {=_xlfn.IFS(D9="Pleno","P",D9="CorteSencillo_Schneider","CS_SE",D9="CorteSencilloNatural_Pequeño","CS_NP",D9="CorteSencilloNatural_Mediano","CS_NM",D9="CorteSencilloNatural_Grande","CS_NG",D9="CorteDoble_Schneider","CD_SE",D9="CorteDobleNatural_Pequeño","CD_NP",D9="CorteDobleNatural_Mediano","CD_NM",D9="CorteDobleNatural_Grande","CD_NG")} -> P | H9: =E9&F9&G9 -> 2072PaPP | I9: =IFERROR(VLOOKUP(H9,BD!$B$6:$F$426,3,FALSE),"") -> 014056 | R9: CortePlacaMediana | S9: CP_ME | T9: CorteSencilloNatural_Pequeño | U9: CS_NP | V9: CorteSencilloNatural_Pequeño | W9: CS_NP
B10: 1.1.5. | C10: Panel superior | E10: =E3&E4 -> 7260 | F10: PaS | H10: =E10&F10&G10 -> 7260PaS | I10: =IFERROR(VLOOKUP(H10,BD!$B$6:$F$426,3,FALSE),"") -> 010057 | R10: CortePlacaGrande | S10: CP_Gr | T10: CorteSencilloNatural_Mediano | U10: CS_NM | V10: CorteSencilloNatural_Mediano | W10: CS_NM
B11: 1.1.6. | C11: Base inferior | D11: Zocalo | E11: =E3&E4 -> 7260 | F11: Ba | G11: {=_xlfn.IFS(D11="Zocalo","Z",D11="Estructural","E",D11="Estructural_H400mm","EH4")} -> Z | H11: =E11&F11&G11 -> 7260BaZ | I11: =IFERROR(IF(D11="Zocalo",VLOOKUP(J11,BD!$B$6:$F$426,3,FALSE),VLOOKUP(H11,BD!$B$6:$F$426,3,FALSE)),"") -> 014500 | J11: =IF(D11="Zocalo",(F11&G11),"") -> BaZ | R11: CorteSencillo_Schneider | S11: CS_SE | T11: CorteSencilloNatural_Grande | U11: CS_NG | V11: CorteSencilloNatural_Grande | W11: CS_NG
B12: 1.1.7. | C12: Kit tapa zocalos laterales | E12: =E4 -> 60 | F12: ZoL | H12: =E12&F12&G12 -> 60ZoL | I12: =IFERROR(VLOOKUP(H12,BD!$B$6:$F$426,3,FALSE),"") -> 010177 | R12: CorteSencilloNatural_Pequeño | S12: CS_NP | V12: CorteDoble_Schneider | W12: CD_SE
B13: 1.1.8. | C13: Kit tapa zocalos Frontales | E13: =E3 -> 72 | F13: ZoF | H13: =E13&F13&G13 -> 72ZoF | I13: =IFERROR(VLOOKUP(H13,BD!$B$6:$F$426,3,FALSE),"") -> 010178 | R13: CorteSencilloNatural_Mediano | S13: CS_NM | V13: CorteDobleNatural_Pequeño | W13: CD_NP
B14: 1.1.9. | C14: Pane linferior | E14: =E3&E4 -> 7260 | F14: PaI | H14: =E14&F14&G14 -> 7260PaI | I14: =IFERROR(VLOOKUP(H14,BD!$B$6:$F$426,3,FALSE),"") -> 014257 | R14: CorteSencilloNatural_Grande | S14: CS_NG | V14: CorteDobleNatural_Mediano | W14: CD_NM
B15: 1.1.10. | C15: Paral interno vertical total | E15: =E2 -> 20 | F15: PaIVT | H15: =E15&F15&G15 -> 20PaIVT | I15: =IFERROR(VLOOKUP(H15,BD!$B$6:$F$426,3,FALSE),"") -> 014153 | R15: CorteDoble_Schneider | S15: CD_SE | V15: CorteDobleNatural_Grande | W15: CD_NG
B16: 1.1.11. | C16: Paral interno vertical intermedio | F16: PaIVI | H16: =E16&F16&G16 -> PaIVI | I16: =IFERROR(VLOOKUP(H16,BD!$B$6:$F$426,3,FALSE),"") | R16: CorteDobleNatural_Pequeño | S16: CD_NP
B17: 1.1.12. | C17: Paral interno horizontal | E17: =E4 -> 60 | F17: PaIH | H17: =E17&F17&G17 -> 60PaIH | I17: =IFERROR(VLOOKUP(H17,BD!$B$6:$F$426,3,FALSE),"") -> 10285 | R17: CorteDobleNatural_Mediano | S17: CD_NM
B18: 1.1.13. | C18: Ducto de cables | E18: =E3 -> 72 | F18: DuC | H18: =E18&F18&G18 -> 72DuC | I18: =IFERROR(VLOOKUP(H18,BD!$B$6:$F$426,3,FALSE),"") -> 014301 | R18: CorteDobleNatural_Grande | S18: CD_NG
B19: 1.1.14. | C19: Kit union posterior | D19: Si | F19: KiUP | H19: =E19&F19&G19 -> KiUP | I19: =IF(D19="Si",VLOOKUP(H19,BD!$B$6:$F$426,3,FALSE),"") -> 012000 | R19: Vidrio | S19: V
B20: 1.1.15. | C20: Segregación frontal* | E20: =E2&E3 -> 2072 | F20: SeF | H20: =E20&F20&G20 -> 2072SeF | I20: =IFERROR(VLOOKUP(H20,BD!$B$6:$F$426,3,FALSE),"") | R20: MarcoLiso | S20: MaL
B22: 1.2.1. | C22: Hablador | H22: =E22&F22&G22 | I22: SinReferencia
B23: 1.2.2. | C23: Kit de cancamos | D23: Si | F23: CaE | H23: =E23&F23&G23 -> CaE | I23: =IF(D23="Si",VLOOKUP(H23,BD!$B$6:$F$426,3,FALSE),"") -> 014501
B24: 1.2.3. | C24: Angulo de izaje | D24: No | F24: AnI | H24: =E24&F24&G24 -> AnI | I24: =IF(D24="Si",VLOOKUP(H24,BD!$B$6:$F$426,3,FALSE),"")
B25: 1.2.4. | C25: Grua | H25: =E25&F25&G25 | I25: SinReferencia
B26: 1.2.5. | C26: Techo | H26: =E26&F26&G26 | I26: SinReferencia
B28: 1.3.1. | C28: Cubierta para modulo | I28: SinReferencia
B29: 1.3.2. | C29: Cubierta para ventilación | I29: SinReferencia
B30: 1.4.1. | C30: Cubierta de ventilación | I30: SinReferencia
B31: 1.4.2. | C31: Segregación | I31: SinReferencia
B33: 1.5.1. | C33: Cubierta de ventilación | H33: - | I33: =IFERROR(VLOOKUP(H33,BD!$B$6:$F$426,3,FALSE),"")
B34: 1.5.2. | C34: Accesorio de poste | I34: SinReferencia
B35: 1.5.3. | C35: Accesorio de muro | I35: SinReferencia
B36: 1.5.4. | C36: Segregación | I36: SinReferencia
B37: 1.6.1. | C37: Placa para modulo | D37: Grande | F37: PlM | G37: {=_xlfn.IFS(D37="Pequeña","P",D37="Mediana","M",D37="Grande","G")} -> G | H37: =E37&F37&G37 -> PlMG | I37: =IFERROR(VLOOKUP(H37,BD!$B$6:$F$426,3,FALSE),"") -> 013202
B38: 1.6.2. | C38: Tapa del modulo | D38: ATS | F38: TaM | G38: {=_xlfn.IFS(D38="ATS","ATS",D38="PM + 6 Perforaciones","PM6")} -> ATS | H38: =E38&F38&G38 -> TaMATS | I38: =IFERROR(VLOOKUP(H38,BD!$B$6:$F$426,3,FALSE),"") -> 012110

Sheet ANEXOS
B1: #VALUE!
AG2: © Industrias CTS S.A.S. – Todos los derechos reservados. Prohíbida su reproducción sin autorización expresa de la compañía.
AN18: #VALUE!
AG40: © Industrias CTS S.A.S. – Todos los derechos reservados. Prohíbida su reproducción sin autorización expresa de la compañía.
C42: #VALUE! | BG42: #VALUE!
F43: T-Power NEO | AJ43: T-Power NEO
F44: Catalogo de Producto | AJ44: Catalogo de Producto
AF45: © Industrias CTS S.A.S. – Todos los derechos reservados. Prohíbida su reproducción sin autorización expresa de la compañía.
B46: B | D46: Envolventes | AH46: Envolventes | BI46: B
E47: T-Power NEO | AH47: T-Power NEO
C49: Caracteristicas | M49: Marco | P49: Puerta Plena | S49: Panel Lateral | V49: Panel Posterior | Y49: Panel Superior | AB49: Base Inferior | AG49: Kit Zocalo | AJ49: Tapa Zocalo Lateral | AM49: Tapa Zocalo Frontal | AP49: Panel Inferior | AS49: Paral interno Vertical | AV49: Paral Iterno Horizontal | AY49: Ducto de cables | BB49: Kit Union Posterior | BE49: Segregacion Frontal Barraje
C50: +NB | D50: 200 mm | F50: +NL | G50: 800 mm | J50: H1 | K50: 1800 mm | M50: #VALUE! | P50: #VALUE! | S50: #VALUE! | V50: #VALUE! | Y50: #VALUE! | AB50: #VALUE! | AJ50: #VALUE! | AM50: #VALUE! | AP50: #VALUE! | AS50: #VALUE! | AV50: #VALUE! | AY50: #VALUE! | BF50: #VALUE!
C51: +NI | D51: 400 mm | F51: +NE* | G51: 1120 mm | J51: H2 | K51: 2000 mm
C52: +NE | D52: 720 mm | J52: H3 | K52: 2200 mm
B53: D1 = 400 mm | C53: +NB | E53: Columna de Barraje (VBB) | L53: H1 | M53: 017000 | P53: 014100 | Q53: 014100 | R53: 014100 | S53: 014025 | T53: 014025 | U53: 014025 | V53: 014050 | W53: 014050 | X53: 014050 | Y53: 010050 | Z53: 010050 | AA53: 010050 | AB53: 150000 | AC53: 150000 | AD53: 150000 | AG53: 14500 | AH53: 14500 | AI53: 14500 | AJ53: 010176 | AK53: 010176 | AL53: 010176 | AM53: 010175 | AN53: 010175 | AO53: 010175 | AP53: 014250 | AQ53: 014250 | AR53: 014250 | AS53: 014152 | AT53: 014152 | AU53: 014152 | AV53: - | AY53: - | AZ53: - | BA53: - | BB53: 12000 | BC53: 12000 | BD53: 12000 | BE53: Pte | BH53: H1 | BI53: D1 = 400 mm
L54: H2 | M54: 017012 | P54: 014103 | Q54: 014103 | R54: 014103 | S54: 014028 | T54: 014028 | U54: 014028 | V54: 014054 | W54: 014054 | X54: 014054 | Y54: 010050 | Z54: 010050 | AA54: 010050 | AB54: 150000 | AC54: 150000 | AD54: 150000 | AG54: 14500 | AH54: 14500 | AI54: 14500 | AJ54: 010176 | AK54: 010176 | AL54: 010176 | AM54: 010175 | AN54: 010175 | AO54: 010175 | AP54: 014250 | AQ54: 014250 | AR54: 014250 | AS54: 014153 | AT54: 014153 | AU54: 014153 | AV54: - | AY54: - | AZ54: - | BA54: - | BB54: 12000 | BC54: 12000 | BD54: 12000 | BE54: Pte | BH54: H2
L55: H3 | M55: 017026 | P55: 014107 | Q55: 014107 | R55: 014107 | S55: 014031 | T55: 014031 | U55: 014031 | V55: 014059 | W55: 014059 | X55: 014059 | Y55: 010050 | Z55: 010050 | AA55: 010050 | AB55: 150000 | AC55: 150000 | AD55: 150000 | AG55: 14500 | AH55: 14500 | AI55: 14500 | AJ55: 010176 | AK55: 010176 | AL55: 010176 | AM55: 010175 | AN55: 010175 | AO55: 010175 | AP55: 014250 | AQ55: 014250 | AR55: 014250 | AS55: 014154 | AT55: 014154 | AU55: 014154 | AV55: - | AY55: - | AZ55: - | BA55: - | BB55: 12000 | BC55: 12000 | BD55: 12000 | BE55: Pte | BH55: H3
C56: +NI | E56: Columna de Integración | L56: H1 | M56: 017001 | P56: 014101 | Q56: 014101 | R56: 014101 | S56: 014025 | T56: 014025 | U56: 014025 | V56: 014051 | W56: 014051 | X56: 014051 | Y56: 010053 | Z56: 010053 | AA56: 010053 | AB56: 150003 | AC56: 150003 | AD56: 150003 | AG56: 14500 | AH56: 14500 | AI56: 14500 | AJ56: 010176 | AK56: 010176 | AL56: 010176 | AM56: 010176 | AN56: 010176 | AO56: 010176 | AP56: 014253 | AQ56: 014253 | AR56: 014253 | AS56: 014152 | AT56: 014152 | AU56: 014152 | AV56: - | AY56: 014300 | AZ56: 014300 | BA56: 014300 | BB56: 12000 | BC56: 12000 | BD56: 12000 | BE56: Pte | BH56: H1
L57: H2 | M57: 017013 | P57: 014104 | Q57: 014104 | R57: 014104 | S57: 014028 | T57: 014028 | U57: 014028 | V57: 014055 | W57: 014055 | X57: 014055 | Y57: 010053 | Z57: 010053 | AA57: 010053 | AB57: 150003 | AC57: 150003 | AD57: 150003 | AG57: 14500 | AH57: 14500 | AI57: 14500 | AJ57: 010176 | AK57: 010176 | AL57: 010176 | AM57: 010176 | AN57: 010176 | AO57: 010176 | AP57: 014253 | AQ57: 014253 | AR57: 014253 | AS57: 014153 | AT57: 014153 | AU57: 014153 | AV57: - | AY57: 014300 | AZ57: 014300 | BA57: 014300 | BB57: 12000 | BC57: 12000 | BD57: 12000 | BE57: Pte | BH57: H2
L58: H3 | M58: 017027 | P58: 014108 | Q58: 014108 | R58: 014108 | S58: 014031 | T58: 014031 | U58: 014031 | V58: 014060 | W58: 014060 | X58: 014060 | Y58: 010053 | Z58: 010053 | AA58: 010053 | AB58: 150003 | AC58: 150003 | AD58: 150003 | AG58: 14500 | AH58: 14500 | AI58: 14500 | AJ58: 010176 | AK58: 010176 | AL58: 010176 | AM58: 010176 | AN58: 010176 | AO58: 010176 | AP58: 014253 | AQ58: 014253 | AR58: 014253 | AS58: 014154 | AT58: 014154 | AU58: 014154 | AV58: - | AY58: 014300 | AZ58: 014300 | BA58: 014300 | BB58: 12000 | BC58: 12000 | BD58: 12000 | BE58: Pte | BH58: H3
C59: +NE | E59: Columna de Equipos | L59: H1 | M59: 017002 | P59: 014102 | Q59: 014102 | R59: 014102 | S59: 014025 | T59: 014025 | U59: 014025 | V59: 014052 | W59: 014052 | X59: 014052 | Y59: 010056 | Z59: 010056 | AA59: 010056 | AB59: 150006 | AC59: 150006 | AD59: 150006 | AE59: © Industrias CTS S.A.S. – Todos los derechos reservados. Prohíbida su reproducción sin autorización expresa de la compañía. | AG59: 14500 | AH59: 14500 | AI59: 14500 | AJ59: 010176 | AK59: 010176 | AL59: 010176 | AM59: 010178 | AN59: 010178 | AO59: 010178 | AP59: 014256 | AQ59: 014256 | AR59: 014256 | AS59: 014152 | AT59: 014152 | AU59: 014152 | AV59: - | AY59: 014301 | AZ59: 014301 | BA59: 014301 | BB59: 12000 | BC59: 12000 | BD59: 12000 | BE59: - | BH59: H1
L60: H2 | M60: 017014 | P60: 014105 | Q60: 014105 | R60: 014105 | S60: 014028 | T60: 014028 | U60: 014028 | V60: 014056 | W60: 014056 | X60: 014056 | Y60: 010056 | Z60: 010056 | AA60: 010056 | AB60: 150006 | AC60: 150006 | AD60: 150006 | AG60: 14500 | AH60: 14500 | AI60: 14500 | AJ60: 010176 | AK60: 010176 | AL60: 010176 | AM60: 010178 | AN60: 010178 | AO60: 010178 | AP60: 014256 | AQ60: 014256 | AR60: 014256 | AS60: 014153 | AT60: 014153 | AU60: 014153 | AV60: - | AY60: 014301 | AZ60: 014301 | BA60: 014301 | BB60: 12000 | BC60: 12000 | BD60: 12000 | BE60: - | BH60: H2
L61: H3 | M61: 017028 | P61: 014109 | Q61: 014109 | R61: 014109 | S61: 014031 | T61: 014031 | U61: 014031 | V61: 014061 | W61: 014061 | X61: 014061 | Y61: 010056 | Z61: 010056 | AA61: 010056 | AB61: 150006 | AC61: 150006 | AD61: 150006 | AG61: 14500 | AH61: 14500 | AI61: 14500 | AJ61: 010176 | AK61: 010176 | AL61: 010176 | AM61: 010178 | AN61: 010178 | AO61: 010178 | AP61: 014256 | AQ61: 014256 | AR61: 014256 | AS61: 014154 | AT61: 014154 | AU61: 014154 | AV61: - | AY61: 014301 | AZ61: 014301 | BA61: 014301 | BB61: 12000 | BC61: 12000 | BD61: 12000 | BE61: - | BH61: H3
B62: D2 = 600 mm | C62: +NB | E62: Columna de Barraje (VBB) | L62: H1 | M62: 017004 | N62: 017004 | O62: 017004 | P62: 014100 | Q62: 014100 | R62: 014100 | S62: 014026 | T62: 014026 | U62: 014026 | V62: 014050 | W62: 014050 | X62: 014050 | Y62: 010051 | Z62: 010051 | AA62: 010051 | AB62: 150001 | AC62: 150001 | AD62: 150001 | AG62: 14500 | AH62: 14500 | AI62: 14500 | AJ62: 010177 | AK62: 010177 | AL62: 010177 | AM62: 010175 | AN62: 010175 | AO62: 010175 | AP62: 014251 | AQ62: 014251 | AR62: 014251 | AS62: 014152 | AT62: 014152 | AU62: 014152 | AV62: 10185 | AW62: 10185 | AX62: 10185 | AY62: - | AZ62: - | BA62: - | BB62: 12000 | BC62: 12000 | BD62: 12000 | BE62: Pte | BH62: H1 | BI62: D2 =600 mm
L63: H2 | M63: 017016 | N63: 017016 | O63: 017016 | P63: 014103 | Q63: 014103 | R63: 014103 | S63: 014029 | T63: 014029 | U63: 014029 | V63: 014054 | W63: 014054 | X63: 014054 | Y63: 010051 | Z63: 010051 | AA63: 010051 | AB63: 150001 | AC63: 150001 | AD63: 150001 | AG63: 14500 | AH63: 14500 | AI63: 14500 | AJ63: 010177 | AK63: 010177 | AL63: 010177 | AM63: 010175 | AN63: 010175 | AO63: 010175 | AP63: 014251 | AQ63: 014251 | AR63: 014251 | AS63: 014153 | AT63: 014153 | AU63: 014153 | AV63: 10185 | AW63: 10185 | AX63: 10185 | AY63: - | AZ63: - | BA63: - | BB63: 12000 | BC63: 12000 | BD63: 12000 | BE63: Pte | BH63: H2
L64: H3 | M64: 017030 | N64: 017030 | O64: 017030 | P64: 014107 | Q64: 014107 | R64: 014107 | S64: 014032 | T64: 014032 | U64: 014032 | V64: 014059 | W64: 014059 | X64: 014059 | Y64: 010051 | Z64: 010051 | AA64: 010051 | AB64: 150001 | AC64: 150001 | AD64: 150001 | AG64: 14500 | AH64: 14500 | AI64: 14500 | AJ64: 010177 | AK64: 010177 | AL64: 010177 | AM64: 010175 | AN64: 010175 | AO64: 010175 | AP64: 014251 | AQ64: 014251 | AR64: 014251 | AS64: 014154 | AT64: 014154 | AU64: 014154 | AV64: 10185 | AW64: 10185 | AX64: 10185 | AY64: - | AZ64: - | BA64: - | BB64: 12000 | BC64: 12000 | BD64: 12000 | BE64: Pte | BH64: H3
C65: +NI | E65: Columna de Integración | L65: H1 | M65: 017005 | N65: 017005 | O65: 017005 | P65: 014101 | Q65: 014101 | R65: 014101 | S65: 014026 | T65: 014026 | U65: 014026 | V65: 014051 | W65: 014051 | X65: 014051 | Y65: 010054 | Z65: 010054 | AA65: 010054 | AB65: 150004 | AC65: 150004 | AD65: 150004 | AG65: 14500 | AH65: 14500 | AI65: 14500 | AJ65: 010177 | AK65: 010177 | AL65: 010177 | AM65: 010176 | AN65: 010176 | AO65: 010176 | AP65: 014254 | AQ65: 014254 | AR65: 014254 | AS65: 014152 | AT65: 014152 | AU65: 014152 | AV65: 10185 | AW65: 10185 | AX65: 10185 | AY65: 014300 | AZ65: 014300 | BA65: 014300 | BB65: 12000 | BC65: 12000 | BD65: 12000 | BE65: Pte | BH65: H1
L66: H2 | M66: 017017 | N66: 017017 | O66: 017017 | P66: 014104 | Q66: 014104 | R66: 014104 | S66: 014029 | T66: 014029 | U66: 014029 | V66: 014055 | W66: 014055 | X66: 014055 | Y66: 010054 | Z66: 010054 | AA66: 010054 | AB66: 150004 | AC66: 150004 | AD66: 150004 | AG66: 14500 | AH66: 14500 | AI66: 14500 | AJ66: 010177 | AK66: 010177 | AL66: 010177 | AM66: 010176 | AN66: 010176 | AO66: 010176 | AP66: 014254 | AQ66: 014254 | AR66: 014254 | AS66: 014153 | AT66: 014153 | AU66: 014153 | AV66: 10185 | AW66: 10185 | AX66: 10185 | AY66: 014300 | AZ66: 014300 | BA66: 014300 | BB66: 12000 | BC66: 12000 | BD66: 12000 | BE66: Pte | BH66: H2
L67: H3 | M67: 017031 | N67: 017031 | O67: 017031 | P67: 014108 | Q67: 014108 | R67: 014108 | S67: 014032 | T67: 014032 | U67: 014032 | V67: 014060 | W67: 014060 | X67: 014060 | Y67: 010054 | Z67: 010054 | AA67: 010054 | AB67: 150004 | AC67: 150004 | AD67: 150004 | AG67: 14500 | AH67: 14500 | AI67: 14500 | AJ67: 010177 | AK67: 010177 | AL67: 010177 | AM67: 010176 | AN67: 010176 | AO67: 010176 | AP67: 014254 | AQ67: 014254 | AR67: 014254 | AS67: 014154 | AT67: 014154 | AU67: 014154 | AV67: 10185 | AW67: 10185 | AX67: 10185 | AY67: 014300 | AZ67: 014300 | BA67: 014300 | BB67: 12000 | BC67: 12000 | BD67: 12000 | BE67: Pte | BH67: H3
C68: +NE | E68: Columna de Equipos | L68: H1 | M68: 017006 | N68: 017006 | O68: 017006 | P68: 014102 | Q68: 014102 | R68: 014102 | S68: 014026 | T68: 014026 | U68: 014026 | V68: 014052 | W68: 014052 | X68: 014052 | Y68: 010057 | Z68: 010057 | AA68: 010057 | AB68: 150007 | AC68: 150007 | AD68: 150007 | AG68: 14500 | AH68: 14500 | AI68: 14500 | AJ68: 010177 | AK68: 010177 | AL68: 010177 | AM68: 010178 | AN68: 010178 | AO68: 010178 | AP68: 014257 | AQ68: 014257 | AR68: 014257 | AS68: 014152 | AT68: 014152 | AU68: 014152 | AV68: 10185 | AW68: 10185 | AX68: 10185 | AY68: 014301 | AZ68: 014301 | BA68: 014301 | BB68: 12000 | BC68: 12000 | BD68: 12000 | BE68: - | BH68: H1
L69: H2 | M69: 017018 | N69: 017018 | O69: 017018 | P69: 014105 | Q69: 014105 | R69: 014105 | S69: 014029 | T69: 014029 | U69: 014029 | V69: 014056 | W69: 014056 | X69: 014056 | Y69: 010057 | Z69: 010057 | AA69: 010057 | AB69: 150007 | AC69: 150007 | AD69: 150007 | AG69: 14500 | AH69: 14500 | AI69: 14500 | AJ69: 010177 | AK69: 010177 | AL69: 010177 | AM69: 010178 | AN69: 010178 | AO69: 010178 | AP69: 014257 | AQ69: 014257 | AR69: 014257 | AS69: 014153 | AT69: 014153 | AU69: 014153 | AV69: 10185 | AW69: 10185 | AX69: 10185 | AY69: 014301 | AZ69: 014301 | BA69: 014301 | BB69: 12000 | BC69: 12000 | BD69: 12000 | BE69: - | BH69: H2
L70: H3 | M70: 017032 | N70: 017032 | O70: 017032 | P70: 014109 | Q70: 014109 | R70: 014109 | S70: 014032 | T70: 014032 | U70: 014032 | V70: 014061 | W70: 014061 | X70: 014061 | Y70: 010057 | Z70: 010057 | AA70: 010057 | AB70: 150007 | AC70: 150007 | AD70: 150007 | AG70: 14500 | AH70: 14500 | AI70: 14500 | AJ70: 010177 | AK70: 010177 | AL70: 010177 | AM70: 010178 | AN70: 010178 | AO70: 010178 | AP70: 014257 | AQ70: 014257 | AR70: 014257 | AS70: 014154 | AT70: 014154 | AU70: 014154 | AV70: 10185 | AW70: 10185 | AX70: 10185 | AY70: 014301 | AZ70: 014301 | BA70: 014301 | BB70: 12000 | BC70: 12000 | BD70: 12000 | BE70: - | BH70: H3
C71: +NL | E71: Columna de automatizacion industrial (T-Power Logic) | L71: H1 | M71: - | N71: - | O71: - | P71: - | Q71: - | R71: - | S71: 014026 | T71: 014026 | U71: 014026 | V71: - | W71: - | X71: - | Y71: 010060 | Z71: 010060 | AA71: 010060 | AB71: 150009 | AC71: 150009 | AD71: 150009 | AG71: 14500 | AH71: 14500 | AI71: 14500 | AJ71: 010177 | AK71: 010177 | AL71: 010177 | AM71: 010179 | AN71: 010179 | AO71: 010179 | AP71: 014259 | AQ71: 014259 | AR71: 014259 | AS71: 014152 | AT71: 014152 | AU71: 014152 | AV71: 10185 | AW71: 10185 | AX71: 10185 | AY71: 014302 | AZ71: 014302 | BA71: 014302 | BB71: 12000 | BC71: 12000 | BD71: 12000 | BE71: - | BF71: - | BG71: - | BH71: H1
L72: H2 | M72: 017019 | N72: 017019 | O72: 017019 | P72: 014106 | Q72: 014106 | R72: 014106 | S72: 014029 | T72: 014029 | U72: 014029 | V72: 014057 | W72: 014057 | X72: 014057 | Y72: 010060 | Z72: 010060 | AA72: 010060 | AB72: 150009 | AC72: 150009 | AD72: 150009 | AG72: 14500 | AH72: 14500 | AI72: 14500 | AJ72: 010177 | AK72: 010177 | AL72: 010177 | AM72: 010179 | AN72: 010179 | AO72: 010179 | AP72: 014259 | AQ72: 014259 | AR72: 014259 | AS72: 014153 | AT72: 014153 | AU72: 014153 | AV72: 10185 | AW72: 10185 | AX72: 10185 | AY72: 014302 | AZ72: 014302 | BA72: 014302 | BB72: 12000 | BC72: 12000 | BD72: 12000 | BE72: - | BF72: - | BG72: - | BH72: H2
L73: H3 | M73: 017033 | N73: 017033 | O73: 017033 | P73: 014110 | Q73: 014110 | R73: 014110 | S73: 014032 | T73: 014032 | U73: 014032 | V73: 014062 | W73: 014062 | X73: 014062 | Y73: 010060 | Z73: 010060 | AA73: 010060 | AB73: 150009 | AC73: 150009 | AD73: 150009 | AG73: 14500 | AH73: 14500 | AI73: 14500 | AJ73: 010177 | AK73: 010177 | AL73: 010177 | AM73: 010179 | AN73: 010179 | AO73: 010179 | AP73: 014259 | AQ73: 014259 | AR73: 014259 | AS73: 014154 | AT73: 014154 | AU73: 014154 | AV73: 10185 | AW73: 10185 | AX73: 10185 | AY73: 014302 | AZ73: 014302 | BA73: 014302 | BB73: 12000 | BC73: 12000 | BD73: 12000 | BE73: - | BF73: - | BG73: - | BH73: H3
B74: D3 = 1000 mm | C74: +NB | E74: Columna de Barraje (VBB) | L74: H1 | M74: 017008 | N74: 017008 | O74: 017008 | P74: 014100 | Q74: 014100 | R74: 014100 | S74: 014027 | T74: 014027 | U74: 014027 | V74: 014050 | W74: 014050 | X74: 014050 | Y74: 010052 | Z74: 010052 | AA74: 010052 | AB74: 150002 | AC74: 150002 | AD74: 150002 | AG74: 14500 | AH74: 14500 | AI74: 14500 | AJ74: 010180 | AK74: 010180 | AL74: 010180 | AM74: 010175 | AN74: 010175 | AO74: 010175 | AP74: 014252 | AQ74: 014252 | AR74: 014252 | AS74: 014152 | AT74: 014152 | AU74: 014152 | AV74: 10186 | AW74: 10186 | AX74: 10186 | AY74: - | AZ74: - | BA74: - | BB74: 12000 | BC74: 12000 | BD74: 12000 | BE74: Pte | BF74: - | BG74: - | BH74: H1 | BI74: D3 = 1000 mm
L75: H2 | M75: 017021 | N75: 017021 | O75: 017021 | P75: 014103 | Q75: 014103 | R75: 014103 | S75: 014030 | T75: 014030 | U75: 014030 | V75: 014054 | W75: 014054 | X75: 014054 | Y75: 010052 | Z75: 010052 | AA75: 010052 | AB75: 150002 | AC75: 150002 | AD75: 150002 | AG75: 14500 | AH75: 14500 | AI75: 14500 | AJ75: 010180 | AK75: 010180 | AL75: 010180 | AM75: 010175 | AN75: 010175 | AO75: 010175 | AP75: 014252 | AQ75: 014252 | AR75: 014252 | AS75: 014153 | AT75: 014153 | AU75: 014153 | AV75: 10186 | AW75: 10186 | AX75: 10186 | AY75: - | AZ75: - | BA75: - | BB75: 12000 | BC75: 12000 | BD75: 12000 | BE75: Pte | BF75: - | BG75: - | BH75: H2
L76: H3 | M76: 017035 | N76: 017035 | O76: 017035 | P76: 014107 | Q76: 014107 | R76: 014107 | S76: 014033 | T76: 014033 | U76: 014033 | V76: 014059 | W76: 014059 | X76: 014059 | Y76: 010052 | Z76: 010052 | AA76: 010052 | AB76: 150002 | AC76: 150002 | AD76: 150002 | AG76: 14500 | AH76: 14500 | AI76: 14500 | AJ76: 010180 | AK76: 010180 | AL76: 010180 | AM76: 010175 | AN76: 010175 | AO76: 010175 | AP76: 014252 | AQ76: 014252 | AR76: 014252 | AS76: 014154 | AT76: 014154 | AU76: 014154 | AV76: 10186 | AW76: 10186 | AX76: 10186 | AY76: - | AZ76: - | BA76: - | BB76: 12000 | BC76: 12000 | BD76: 12000 | BE76: Pte | BF76: - | BG76: - | BH76: H3
C77: +NI | E77: Columna de Integración | L77: H1 | M77: 017009 | N77: 017009 | O77: 017009 | P77: 014101 | Q77: 014101 | R77: 014101 | S77: 014027 | T77: 014027 | U77: 014027 | V77: 014051 | W77: 014051 | X77: 014051 | Y77: 010055 | Z77: 010055 | AA77: 010055 | AB77: 150005 | AC77: 150005 | AD77: 150005 | AG77: 14500 | AH77: 14500 | AI77: 14500 | AJ77: 010180 | AK77: 010180 | AL77: 010180 | AM77: 010176 | AN77: 010176 | AO77: 010176 | AP77: 014255 | AQ77: 014255 | AR77: 014255 | AS77: 014152 | AT77: 014152 | AU77: 014152 | AV77: 10186 | AW77: 10186 | AX77: 10186 | AY77: 014300 | AZ77: 014300 | BA77: 014300 | BB77: 12000 | BC77: 12000 | BD77: 12000 | BE77: Pte | BF77: - | BG77: - | BH77: H1
L78: H2 | M78: 017022 | N78: 017022 | O78: 017022 | P78: 014104 | Q78: 014104 | R78: 014104 | S78: 014030 | T78: 014030 | U78: 014030 | V78: 014055 | W78: 014055 | X78: 014055 | Y78: 010055 | Z78: 010055 | AA78: 010055 | AB78: 150005 | AC78: 150005 | AD78: 150005 | AG78: 14500 | AH78: 14500 | AI78: 14500 | AJ78: 010180 | AK78: 010180 | AL78: 010180 | AM78: 010176 | AN78: 010176 | AO78: 010176 | AP78: 014255 | AQ78: 014255 | AR78: 014255 | AS78: 014153 | AT78: 014153 | AU78: 014153 | AV78: 10186 | AW78: 10186 | AX78: 10186 | AY78: 014300 | AZ78: 014300 | BA78: 014300 | BB78: 12000 | BC78: 12000 | BD78: 12000 | BE78: Pte | BF78: - | BG78: - | BH78: H2
...

Sheet Formatos2
B2: Barraje principal
B3: Área
B4: 3.1 Barraje principal | C4: 3.1.1. Cubiculo
C5: 3.1.2. Código
B6: Frame
B7: 3.2 Barra de tierra | C7: 3.2.1. Cubiculo
C8: 3.2.2. Código
B9: 3.3 Barra de neutro | C9: 3.3.1. Cubiculo
C10: 3.3.2. Código
B13: Etiquetas envolventes
B14: ÁREA
B15: 2.1 Identificación | C15: 2.1.1 Placa de datos (1-5)
C16: 2.1.2. Ident. columna (6)
C17: 2.1.3. Enumeración columna (7)
C18: 2.1.4. Codigo QR (8-9)
B19: 2.2 Avisos | C19: 2.2.1. Riesgo eléctrico (11-13)
C20: 2.2.2. Descarga Eléctrica (14-16)
C21: 2.2.3. Precauciones antes de energizar (17)
C22: 2.2.4. Control de producción (18)
C23: 2.2.5. Control de Mtto preventivo (19)
C24: 2.2.6. Nivel de tension (20)
B25: 2.3 Logos | C25: 2.3.1. Logo del producto(21-22)
C26: 2.3.2. Logo del cliente(23)
C27: 2.3.3. Logo del fabricante(24-25)
B28: 2.4 Instructivos | C28: 2.4.1. Mimico de operación (26)
C29: 2.4.2. Manipulación gavetas(27)
C30: 2.4.3 Arco eléctrico (28)
B31: 2.5 Requerimiento del cliente | C31: 2.5.1 Nombre del tablero
C32: 2.5.2 Cuadro de cargas
C33: 2.5.3 Nímero de columnas
B36: Etiquetas cubiculos
B37: Cubículo | C37: APE | E37: Observaciones | F37: DET | H37: LDP | I37: Observaciones
C38: Código | D38: Cantidad | F38: Código | G38: Cantidad
