Workbook
Name ATS_400: #REF!
Name ATS_720: #REF!
Name U100X400: #REF!
Name U100X720: #REF!
Name U150X400: #REF!
Name U150X720: #REF!
Name U200X400: #REF!
Name U200X720: #REF!
Name U250X400: #REF!
Name U250X720: #REF!
Name U400X400: #REF!
Name U400X720: #REF!
Name UCVS100X720H: #REF!
Name UCVS100X720VC: #REF!
Name UCVS100X720VE: #REF!
Name UNS1600X720VC: #REF!
Name UNSX100X720H: #REF!
Name UNSX100X720VC: #REF!
Name UNSX100X720VE: #REF!
Name UPGoPact100X720: #REF!
Name UPGoPact250X720H: #REF!
Name UPNSX100X720H: #REF!

Sheet INICIO
GW4: #VALUE!

Sheet BD
S1: Alto : | Y1: H | Z1: =MID(AA1,1,2) -> 22 | AA1: 2200
S2: Ancho : | Y2: W | Z2: =MID(AA2,1,2) -> 72 | AA2: 720
S3: Profundo: | Y3: D | Z3: =MID(AA3,1,2) -> 60 | AA3: 600
S4: IP: | AA4: 30 | AD4: 1 | AE4: 2 | AF4: 3 | AG4: 4 | AH4: 5 | AI4: 6 | AJ4: 7 | AK4: 8 | AL4: 9 | AM4: 10 | AN4: 11 | AO4: 12 | AP4: 13 | AQ4: 14 | AR4: 15 | AS4: 16 | AT4: 17 | AU4: 18 | AV4: 19 | AW4: 20 | AX4: 21 | AY4: 22 | BL4: Caracteristicas | BP4: HBB | CJ4: VBB | DD4: 1
B5: Codigo | C5: Categoria | G5: Alto | I5: Ancho | K5: Profundo | M5: Criterio1 | N5: Criterio2 | O5: Criterio3 | P5: Criterio4 | Q5: Definición | U5: Categoria | V5: Criterio5 | W5: Criterio1 | X5: Criterio2 | Y5: Criterio3 | Z5: CodigoB | AA5: Codigo | AD5: REFERENCIA | AE5: Info | AG5: Tipo | AH5: Linea | AI5: Orientacion | AJ5: Montaje | AK5: Operacion0 | AL5: Ancho | AM5: Profundo | AN5: Topping | AO5: REFERENCIA | AV5: FM | AW5: PM | AX5: UM | AY5: Definicion | BN5: Icc | BO5: In | BP5: W (mm) | BQ5: Codigo | BR5: Interruptor | BS5: 100 A | BT5: 250 A | BU5: 400 A | BV5: 630 A | BW5: 800 A | BX5: 1000 A | BY5: 1250 A | BZ5: 1600 A | CA5: 2000 A | CB5: 2500 A | CC5: 3200 A | CD5: 4000 A | CJ5: L(mm) | CK5: Codigo | CL5: Interruptor | CM5: 100 A | CN5: 250 A | CO5: 400 A | CP5: 630 A | CQ5: 800 A | CR5: 1000 A | CS5: 1250 A | CT5: 1600 A | DD5: Codigo | DF5: SubCodigo1 | DH5: SubCodigo2
A6: 1 | B6: =MID(H6,1,2)&MID(J6,1,2)&MID(L6,1,2)&MID(C6,1,2)&MID(M6,1,1)&MID(N6,1,1)&MID(O6,1,1)&MID(P6,1,3) -> 182040Ma | C6: Marco | D6: 1017000 | E6: 1014000 | F6: 1010020 | G6: =IF(H6<>"","H:","") -> H: | H6: 1800 | I6: =IF(J6<>"","W:","") -> W: | J6: 200 | K6: =IF(L6<>"","D:","") -> D: | L6: 400 | Q6: =IF(B6<>"",(C6&M6&N6&O6&P6&" / "&G6&H6&I6&J6&K6&L6&" mm"),"") -> Marco / H:1800W:200D:400 mm | S6: 1.1.1. | T6: Marco | U6: Ma | V6: =Z1&Z2&Z3 -> 227260 | Z6: =V6&U6&MID(W6,1,1)&MID(X6,1,1)&MID(Y6,1,3) -> 227260Ma | AA6: =VLOOKUP(Z6,$B$6:$D$526,3,FALSE) -> 1017033 | AD6: =AO6&AP6&AQ6&AR6&AS6&AT6&AN6&AU6 -> IMBVFPW2- | AE6: UF. | AF6: de | AG6: Integrada | AH6: Mini Breaker | AI6: Vertical | AJ6: Fijo | AK6: Palanca | AL6: W:400 | AN6: - | AO6: =MID(AG6,1,1) -> I | AP6: {=IFERROR(_xlfn.IFS(AH6="Mini Breaker ","MB",AH6="GoPact ","GP",AH6="EZC 100 ","EZ1",AH6="EZC 250 ","EZ2",AH6="CVS/NSX 250 ","CV2",AH6="CVS/NSX/EZC 630 ","CV6",AH6="NS 1600 ","NS1",AH6="NW/MTZ 4000 ","NW4",AH6="Conmutador PEQ. ","CP",AH6="Conmutador MED. ","CM",AH6="Conmutador GRA. ","CG",AH6="Contactores ","CK"),"")} -> MB | AQ6: {=_xlfn.IFS(AI6="Horizontal ","H",AI6="Horizontal COMPUESTA ","HC",AI6="Vertical ","V",AI6="Vertical Compacta ","VC",AI6="Vertical Extendida ","VE")} -> V | AR6: =MID(AJ6,1,1) -> F | AS6: =MID(AK6,1,1) -> P | AT6: {=IFERROR(_xlfn.IFS(AL6="W:200 ","W1",AL6="W:400 ","W2",AL6="W:720 ","W3",AL6="W:800 ","W4",AL6="W:1120 ","W5"),"")} -> W2 | AU6: {=IFERROR(_xlfn.IFS(AM6="D:400 ","D1",AM6="D:600 ","D2",AM6="D:1000 ","D3"),"")} | AV6: 021125 | AW6: 024000 | AX6: 4 | AY6: =AE6&AF6&AH6&AI6&AJ6&AK6&AL6&AM6&AN6 -> UF. de Mini Breaker Vertical Fijo Palanca W:400 - | BF6: =BG6&BH6&BI6&BJ6 -> 1AH | BG6: {=_xlfn.IFS(BN6="10 - 25",1,BN6="10 - 40",2,BN6="10 - 65",3,BN6="10 - 85",4)} -> 1 | BH6: {=_xlfn.IFS(BO6="630","A",BO6="1250","B",BO6="1600","C",BO6="2000","D",BO6="2500","E",BO6="3200","F",BO6="4000","G",BO6="5000","H",BO6="6300","I",BO6="7000","J")} -> A | BI6: H | BJ6: {=IFERROR(_xlfn.IFS(BP6="400 + 400","X",BP6="720","Y",BP6="1120","Z"),"")} | BL6: TC | BN6: 10 - 25 | BO6: 630 | BP6: - | BQ6: - | BR6: EZC | BS6: - | BT6: - | BU6: - | BV6: - | BW6: - | BX6: - | BY6: - | BZ6: - | CA6: - | CB6: - | CC6: - | CD6: - | CF6: =BG6&BH6&CG6&CH6 -> 1AVM | CG6: V | CH6: {=IFERROR(_xlfn.IFS(CJ6="1/4","M",CJ6="1/2","N",CJ6="3/4","O",CJ6="1","P"),"")} -> M | CJ6: 1/4 | CK6: 037000 | CL6: EZC | CM6: 047001 | CN6: 047002 | CO6: 047003 | CP6: 047004 | CQ6: - | CR6: - | CS6: - | CT6: - | DD6: 017000 | DE6: =IF(DD6<>"",$DD$4&DD6,"") -> 1017000 | DF6: 014000 | DG6: =IF(DF6<>"",$DD$4&DF6,"") -> 1014000 | DH6: 010020 | DI6: =IF(DH6<>"",$DD$4&DH6,"") -> 1010020
A7: 2 | B7: =MID(H7,1,2)&MID(J7,1,2)&MID(L7,1,2)&MID(C7,1,2)&MID(M7,1,1)&MID(N7,1,1)&MID(O7,1,1)&MID(P7,1,3) -> 182060Ma | C7: Marco | D7: 1017001 | E7: 1014001 | F7: 1010020 | G7: =IF(H7<>"","H:","") -> H: | H7: 1800 | I7: =IF(J7<>"","W:","") -> W: | J7: 200 | K7: =IF(L7<>"","D:","") -> D: | L7: 600 | Q7: =IF(B7<>"",(C7&M7&N7&O7&P7&" / "&G7&H7&I7&J7&K7&L7&" mm"),"") -> Marco / H:1800W:200D:600 mm | S7: 1.1.2. | T7: Puerta/Marco liso | U7: Pu | V7: =Z1&Z2 -> 2272 | W7: Plena | Z7: =V7&U7&MID(W7,1,1)&MID(X7,1,1)&MID(Y7,1,3) -> 2272PuP | AA7: =VLOOKUP(Z7,$B$6:$D$526,3,FALSE) -> 1014109 | AD7: =AO7&AP7&AQ7&AR7&AS7&AT7&AN7&AU7 -> IMBVFPW3- | AE7: UF. | AF7: de | AG7: Integrada | AH7: Mini Breaker | AI7: Vertical | AJ7: Fijo | AK7: Palanca | AL7: W:720 | AN7: - | AO7: =MID(AG7,1,1) -> I | AP7: {=IFERROR(_xlfn.IFS(AH7="Mini Breaker ","MB",AH7="GoPact ","GP",AH7="EZC 100 ","EZ1",AH7="EZC 250 ","EZ2",AH7="CVS/NSX 250 ","CV2",AH7="CVS/NSX/EZC 630 ","CV6",AH7="NS 1600 ","NS1",AH7="NW/MTZ 4000 ","NW4",AH7="Conmutador PEQ. ","CP",AH7="Conmutador MED. ","CM",AH7="Conmutador GRA. ","CG",AH7="Contactores ","CK"),"")} -> MB | AQ7: {=_xlfn.IFS(AI7="Horizontal ","H",AI7="Horizontal COMPUESTA ","HC",AI7="Vertical ","V",AI7="Vertical Compacta ","VC",AI7="Vertical Extendida ","VE")} -> V | AR7: =MID(AJ7,1,1) -> F | AS7: =MID(AK7,1,1) -> P | AT7: {=IFERROR(_xlfn.IFS(AL7="W:200 ","W1",AL7="W:400 ","W2",AL7="W:720 ","W3",AL7="W:800 ","W4",AL7="W:1120 ","W5"),"")} -> W3 | AU7: {=IFERROR(_xlfn.IFS(AM7="D:400 ","D1",AM7="D:600 ","D2",AM7="D:1000 ","D3"),"")} | AV7: 021050 | AW7: 024001 | AX7: 4 | AY7: =AE7&AF7&AH7&AI7&AJ7&AK7&AL7&AM7&AN7 -> UF. de Mini Breaker Vertical Fijo Palanca W:720 - | BF7: =BG7&BH7&BI7&BJ7 -> 1AH | BG7: =BG6 -> 1 | BH7: =BH6 -> A | BI7: =BI6 -> H | BJ7: {=IFERROR(_xlfn.IFS(BP7="400 + 400","X",BP7="720","Y",BP7="1120","Z"),"")} | BP7: - | BQ7: - | BR7: CVS | BS7: - | BT7: - | BU7: - | BV7: - | BW7: - | BX7: - | BY7: - | BZ7: - | CA7: - | CB7: - | CC7: - | CD7: - | CF7: =BG7&BH7&CG7&CH7 -> 1AVN | CG7: V | CH7: {=IFERROR(_xlfn.IFS(CJ7="1/4","M",CJ7="1/2","N",CJ7="3/4","O",CJ7="1","P"),"")} -> N | CJ7: 1/2 | CK7: 037001 | CL7: CVS | CM7: 047005 | CN7: 047006 | CO7: 047007 | CP7: 047008 | CQ7: - | CR7: - | CS7: - | CT7: - | DD7: 017001 | DE7: =IF(DD7<>"",$DD$4&DD7,"") -> 1017001 | DF7: 014001 | DG7: =IF(DF7<>"",$DD$4&DF7,"") -> 1014001 | DH7: 010020 | DI7: =IF(DH7<>"",$DD$4&DH7,"") -> 1010020
A8: 3 | B8: =MID(H8,1,2)&MID(J8,1,2)&MID(L8,1,2)&MID(C8,1,2)&MID(M8,1,1)&MID(N8,1,1)&MID(O8,1,1)&MID(P8,1,3) -> 182010Ma | C8: Marco | D8: 1017002 | E8: 1014002 | F8: 1010020 | G8: =IF(H8<>"","H:","") -> H: | H8: 1800 | I8: =IF(J8<>"","W:","") -> W: | J8: 200 | K8: =IF(L8<>"","D:","") -> D: | L8: 1000 | Q8: =IF(B8<>"",(C8&M8&N8&O8&P8&" / "&G8&H8&I8&J8&K8&L8&" mm"),"") -> Marco / H:1800W:200D:1000 mm | S8: 1.1.3. | T8: Kit paneles laterales | U8: PaL | V8: =Z1&Z3 -> 2260 | W8: Pleno | Z8: =V8&U8&MID(W8,1,1)&MID(X8,1,1)&MID(Y8,1,3) -> 2260PaLP | AA8: =VLOOKUP(Z8,$B$6:$D$526,3,FALSE) -> 1014032 | AD8: =AO8&AP8&AQ8&AR8&AS8&AT8&AN8&AU8 -> ICV2VCFPW3- | AE8: UF. | AF8: de | AG8: Integrada | AH8: CVS/NSX 250 | AI8: Vertical Compacta | AJ8: Fijo | AK8: Palanca | AL8: W:720 | AN8: - | AO8: =MID(AG8,1,1) -> I | AP8: {=IFERROR(_xlfn.IFS(AH8="Mini Breaker ","MB",AH8="GoPact ","GP",AH8="EZC 100 ","EZ1",AH8="EZC 250 ","EZ2",AH8="CVS/NSX 250 ","CV2",AH8="CVS/NSX/EZC 630 ","CV6",AH8="NS 1600 ","NS1",AH8="NW/MTZ 4000 ","NW4",AH8="Conmutador PEQ. ","CP",AH8="Conmutador MED. ","CM",AH8="Conmutador GRA. ","CG",AH8="Contactores ","CK"),"")} -> CV2 | AQ8: {=_xlfn.IFS(AI8="Horizontal ","H",AI8="Horizontal COMPUESTA ","HC",AI8="Vertical ","V",AI8="Vertical Compacta ","VC",AI8="Vertical Extendida ","VE")} -> VC | AR8: =MID(AJ8,1,1) -> F | AS8: =MID(AK8,1,1) -> P | AT8: {=IFERROR(_xlfn.IFS(AL8="W:200 ","W1",AL8="W:400 ","W2",AL8="W:720 ","W3",AL8="W:800 ","W4",AL8="W:1120 ","W5"),"")} -> W3 | AU8: {=IFERROR(_xlfn.IFS(AM8="D:400 ","D1",AM8="D:600 ","D2",AM8="D:1000 ","D3"),"")} | AV8: 021058 | AW8: 024002 | AX8: 7 | AY8: =AE8&AF8&AH8&AI8&AJ8&AK8&AL8&AM8&AN8 -> UF. de CVS/NSX 250 Vertical Compacta Fijo Palanca W:720 - | BF8: =BG8&BH8&BI8&BJ8 -> 1AH | BG8: =BG7 -> 1 | BH8: =BH6 -> A | BI8: =BI7 -> H | BJ8: {=IFERROR(_xlfn.IFS(BP8="400 + 400","X",BP8="720","Y",BP8="1120","Z"),"")} | BP8: - | BQ8: - | BR8: NSX | BS8: - | BT8: - | BU8: - | BV8: - | BW8: - | BX8: - | BY8: - | BZ8: - | CA8: - | CB8: - | CC8: - | CD8: - | CF8: =BG8&BH8&CG8&CH8 -> 1AVO | CG8: V | CH8: {=IFERROR(_xlfn.IFS(CJ8="1/4","M",CJ8="1/2","N",CJ8="3/4","O",CJ8="1","P"),"")} -> O | CJ8: 3/4 | CK8: 037002 | CL8: NSX | DD8: 017002 | DE8: =IF(DD8<>"",$DD$4&DD8,"") -> 1017002 | DF8: 014002 | DG8: =IF(DF8<>"",$DD$4&DF8,"") -> 1014002 | DH8: 010020 | DI8: =IF(DH8<>"",$DD$4&DH8,"") -> 1010020
A9: 4 | B9: =MID(H9,1,2)&MID(J9,1,2)&MID(L9,1,2)&MID(C9,1,2)&MID(M9,1,1)&MID(N9,1,1)&MID(O9,1,1)&MID(P9,1,3) -> 184040Ma | C9: Marco | D9: 1017003 | E9: 1014000 | F9: 1010021 | G9: =IF(H9<>"","H:","") -> H: | H9: 1800 | I9: =IF(J9<>"","W:","") -> W: | J9: 400 | K9: =IF(L9<>"","D:","") -> D: | L9: 400 | Q9: =IF(B9<>"",(C9&M9&N9&O9&P9&" / "&G9&H9&I9&J9&K9&L9&" mm"),"") -> Marco / H:1800W:400D:400 mm | S9: 1.1.4. | T9: Panel posterior | U9: PaP | V9: =Z1&Z2 -> 2272 | W9: Pleno | Z9: =V9&U9&MID(W9,1,1)&MID(X9,1,1)&MID(Y9,1,3) -> 2272PaPP | AA9: =VLOOKUP(Z9,$B$6:$D$526,3,FALSE) -> 1014061 | AD9: =AO9&AP9&AQ9&AR9&AS9&AT9&AN9&AU9 -> ICV2VEFPW3- | AE9: UF. | AF9: de | AG9: Integrada | AH9: CVS/NSX 250 | AI9: Vertical Extendida | AJ9: Fijo | AK9: Palanca | AL9: W:720 | AN9: - | AO9: =MID(AG9,1,1) -> I | AP9: {=IFERROR(_xlfn.IFS(AH9="Mini Breaker ","MB",AH9="GoPact ","GP",AH9="EZC 100 ","EZ1",AH9="EZC 250 ","EZ2",AH9="CVS/NSX 250 ","CV2",AH9="CVS/NSX/EZC 630 ","CV6",AH9="NS 1600 ","NS1",AH9="NW/MTZ 4000 ","NW4",AH9="Conmutador PEQ. ","CP",AH9="Conmutador MED. ","CM",AH9="Conmutador GRA. ","CG",AH9="Contactores ","CK"),"")} -> CV2 | AQ9: {=_xlfn.IFS(AI9="Horizontal ","H",AI9="Horizontal COMPUESTA ","HC",AI9="Vertical ","V",AI9="Vertical Compacta ","VC",AI9="Vertical Extendida ","VE")} -> VE | AR9: =MID(AJ9,1,1) -> F | AS9: =MID(AK9,1,1) -> P | AT9: {=IFERROR(_xlfn.IFS(AL9="W:200 ","W1",AL9="W:400 ","W2",AL9="W:720 ","W3",AL9="W:800 ","W4",AL9="W:1120 ","W5"),"")} -> W3 | AU9: {=IFERROR(_xlfn.IFS(AM9="D:400 ","D1",AM9="D:600 ","D2",AM9="D:1000 ","D3"),"")} | AV9: 021099 | AW9: 024003 | AX9: 7 | AY9: =AE9&AF9&AH9&AI9&AJ9&AK9&AL9&AM9&AN9 -> UF. de CVS/NSX 250 Vertical Extendida Fijo Palanca W:720 - | BF9: =BG9&BH9&BI9&BJ9 -> 1AH | BG9: =BG8 -> 1 | BH9: =BH6 -> A | BI9: =BI8 -> H | BJ9: {=IFERROR(_xlfn.IFS(BP9="400 + 400","X",BP9="720","Y",BP9="1120","Z"),"")} | BP9: - | BQ9: - | BR9: - | BS9: - | BT9: - | BU9: - | BV9: - | BW9: - | BX9: - | BY9: - | BZ9: - | CA9: - | CB9: - | CC9: - | CD9: - | CF9: =BG9&BH9&CG9&CH9 -> 1AVP | CG9: V | CH9: {=IFERROR(_xlfn.IFS(CJ9="1/4","M",CJ9="1/2","N",CJ9="3/4","O",CJ9="1","P"),"")} -> P | CJ9: 1 | CK9: 037003 | CL9: - | CM9: - | CN9: - | CO9: - | CP9: - | CQ9: - | CR9: - | CS9: - | CT9: - | DD9: 017003 | DE9: =IF(DD9<>"",$DD$4&DD9,"") -> 1017003 | DF9: 014000 | DG9: =IF(DF9<>"",$DD$4&DF9,"") -> 1014000 | DH9: 010021 | DI9: =IF(DH9<>"",$DD$4&DH9,"") -> 1010021
A10: 5 | B10: =MID(H10,1,2)&MID(J10,1,2)&MID(L10,1,2)&MID(C10,1,2)&MID(M10,1,1)&MID(N10,1,1)&MID(O10,1,1)&MID(P10,1,3) -> 184060Ma | C10: Marco | D10: 1017004 | E10: 1014001 | F10: 1010021 | G10: =IF(H10<>"","H:","") -> H: | H10: 1800 | I10: =IF(J10<>"","W:","") -> W: | J10: 400 | K10: =IF(L10<>"","D:","") -> D: | L10: 600 | Q10: =IF(B10<>"",(C10&M10&N10&O10&P10&" / "&G10&H10&I10&J10&K10&L10&" mm"),"") -> Marco / H:1800W:400D:600 mm | S10: 1.1.5. | T10: Panel superior | U10: Pa | V10: =Z2&Z3 -> 7260 | W10: Superior | Z10: =V10&U10&MID(W10,1,1)&MID(X10,1,1)&MID(Y10,1,3) -> 7260PaS | AA10: =VLOOKUP(Z10,$B$6:$D$526,3,FALSE) -> 1010057 | AD10: =AO10&AP10&AQ10&AR10&AS10&AT10&AN10&AU10 -> ICV2VCFMW3- | AE10: UF. | AF10: de | AG10: Integrada | AH10: CVS/NSX 250 | AI10: Vertical Compacta | AJ10: Fijo | AK10: Motorizado | AL10: W:720 | AN10: - | AO10: =MID(AG10,1,1) -> I | AP10: {=IFERROR(_xlfn.IFS(AH10="Mini Breaker ","MB",AH10="GoPact ","GP",AH10="EZC 100 ","EZ1",AH10="EZC 250 ","EZ2",AH10="CVS/NSX 250 ","CV2",AH10="CVS/NSX/EZC 630 ","CV6",AH10="NS 1600 ","NS1",AH10="NW/MTZ 4000 ","NW4",AH10="Conmutador PEQ. ","CP",AH10="Conmutador MED. ","CM",AH10="Conmutador GRA. ","CG",AH10="Contactores ","CK"),"")} -> CV2 | AQ10: {=_xlfn.IFS(AI10="Horizontal ","H",AI10="Horizontal COMPUESTA ","HC",AI10="Vertical ","V",AI10="Vertical Compacta ","VC",AI10="Vertical Extendida ","VE")} -> VC | AR10: =MID(AJ10,1,1) -> F | AS10: =MID(AK10,1,1) -> M | AT10: {=IFERROR(_xlfn.IFS(AL10="W:200 ","W1",AL10="W:400 ","W2",AL10="W:720 ","W3",AL10="W:800 ","W4",AL10="W:1120 ","W5"),"")} -> W3 | AU10: {=IFERROR(_xlfn.IFS(AM10="D:400 ","D1",AM10="D:600 ","D2",AM10="D:1000 ","D3"),"")} | AV10: 021129 | AW10: 024002 | AX10: 7 | AY10: =AE10&AF10&AH10&AI10&AJ10&AK10&AL10&AM10&AN10 -> UF. de CVS/NSX 250 Vertical Compacta Fijo Motorizado W:720 - | BF10: =BG10&BH10&BI10&BJ10 -> 2BHY | BG10: {=_xlfn.IFS(BN10="10 - 25",1,BN10="10 - 40",2,BN10="10 - 65",3,BN10="10 - 85",4)} -> 2 | BH10: {=_xlfn.IFS(BO10="630","A",BO10="1250","B",BO10="1600","C",BO10="2000","D",BO10="2500","E",BO10="3200","F",BO10="4000","G",BO10="5000","H",BO10="6300","I",BO10="7000","J")} -> B | BI10: H | BJ10: {=IFERROR(_xlfn.IFS(BP10="400 + 400","X",BP10="720","Y",BP10="1120","Z"),"")} -> Y | BL10: TC | BM10: TM | BN10: 10 - 40 | BO10: 1250 | BP10: 720 | BQ10: 038000 | BR10: EZC | BS10: 048001 | BT10: 048002 | BU10: 048003 | BV10: 048004 | BW10: - | BX10: - | BY10: - | BZ10: - | CA10: - | CB10: - | CC10: - | CD10: - | CF10: =BG10&BH10&CG10&CH10 -> 2BVM | CG10: V | CH10: {=IFERROR(_xlfn.IFS(CJ10="1/4","M",CJ10="1/2","N",CJ10="3/4","O",CJ10="1","P"),"")} -> M | CJ10: 1/4 | CK10: 037004 | CL10: EZC | CM10: 047009 | CN10: 047010 | CO10: 047011 | CP10: 047012 | CQ10: - | CR10: - | CS10: - | CT10: - | DD10: 017004 | DE10: =IF(DD10<>"",$DD$4&DD10,"") -> 1017004 | DF10: 014001 | DG10: =IF(DF10<>"",$DD$4&DF10,"") -> 1014001 | DH10: 010021 | DI10: =IF(DH10<>"",$DD$4&DH10,"") -> 1010021
A11: 6 | B11: =MID(H11,1,2)&MID(J11,1,2)&MID(L11,1,2)&MID(C11,1,2)&MID(M11,1,1)&MID(N11,1,1)&MID(O11,1,1)&MID(P11,1,3) -> 184010Ma | C11: Marco | D11: 1017005 | E11: 1014002 | F11: 1010021 | G11: =IF(H11<>"","H:","") -> H: | H11: 1800 | I11: =IF(J11<>"","W:","") -> W: | J11: 400 | K11: =IF(L11<>"","D:","") -> D: | L11: 1000 | Q11: =IF(B11<>"",(C11&M11&N11&O11&P11&" / "&G11&H11&I11&J11&K11&L11&" mm"),"") -> Marco / H:1800W:400D:1000 mm | S11: 1.1.6. | T11: Base inferior | U11: Ba | V11: =Z2&Z3 -> 7260 | W11: Estructural | Z11: =V11&U11&MID(W11,1,1)&MID(X11,1,1)&MID(Y11,1,3) -> 7260BaE | AA11: =VLOOKUP(Z11,$B$6:$D$526,3,FALSE) -> 1015007 | AD11: =AO11&AP11&AQ11&AR11&AS11&AT11&AN11&AU11 -> ICV2VEFMW3- | AE11: UF. | AF11: de | AG11: Integrada | AH11: CVS/NSX 250 | AI11: Vertical Extendida | AJ11: Fijo | AK11: Motorizado | AL11: W:720 | AN11: - | AO11: =MID(AG11,1,1) -> I | AP11: {=IFERROR(_xlfn.IFS(AH11="Mini Breaker ","MB",AH11="GoPact ","GP",AH11="EZC 100 ","EZ1",AH11="EZC 250 ","EZ2",AH11="CVS/NSX 250 ","CV2",AH11="CVS/NSX/EZC 630 ","CV6",AH11="NS 1600 ","NS1",AH11="NW/MTZ 4000 ","NW4",AH11="Conmutador PEQ. ","CP",AH11="Conmutador MED. ","CM",AH11="Conmutador GRA. ","CG",AH11="Contactores ","CK"),"")} -> CV2 | AQ11: {=_xlfn.IFS(AI11="Horizontal ","H",AI11="Horizontal COMPUESTA ","HC",AI11="Vertical ","V",AI11="Vertical Compacta ","VC",AI11="Vertical Extendida ","VE")} -> VE | AR11: =MID(AJ11,1,1) -> F | AS11: =MID(AK11,1,1) -> M | AT11: {=IFERROR(_xlfn.IFS(AL11="W:200 ","W1",AL11="W:400 ","W2",AL11="W:720 ","W3",AL11="W:800 ","W4",AL11="W:1120 ","W5"),"")} -> W3 | AU11: {=IFERROR(_xlfn.IFS(AM11="D:400 ","D1",AM11="D:600 ","D2",AM11="D:1000 ","D3"),"")} | AV11: 021130 | AW11: 024003 | AX11: 7 | AY11: =AE11&AF11&AH11&AI11&AJ11&AK11&AL11&AM11&AN11 -> UF. de CVS/NSX 250 Vertical Extendida Fijo Motorizado W:720 - | BF11: =BG11&BH11&BI11&BJ11 -> 2BHZ | BG11: =BG10 -> 2 | BH11: =BH10 -> B | BI11: =BI10 -> H | BJ11: {=IFERROR(_xlfn.IFS(BP11="400 + 400","X",BP11="720","Y",BP11="1120","Z"),"")} -> Z | BP11: 1120 | BQ11: 038001 | BR11: CVS | BS11: 048005 | BT11: 048006 | BU11: 048007 | BV11: 048008 | BW11: - | BX11: - | BY11: - | BZ11: - | CA11: - | CB11: - | CC11: - | CD11: - | CF11: =BG11&BH11&CG11&CH11 -> 2BVN | CG11: V | CH11: {=IFERROR(_xlfn.IFS(CJ11="1/4","M",CJ11="1/2","N",CJ11="3/4","O",CJ11="1","P"),"")} -> N | CJ11: 1/2 | CK11: 037005 | CL11: CVS | CM11: 047013 | CN11: 047014 | CO11: 047015 | CP11: 047016 | CQ11: - | CR11: - | CS11: - | CT11: - | DD11: 017005 | DE11: =IF(DD11<>"",$DD$4&DD11,"") -> 1017005 | DF11: 014002 | DG11: =IF(DF11<>"",$DD$4&DF11,"") -> 1014002 | DH11: 010021 | DI11: =IF(DH11<>"",$DD$4&DH11,"") -> 1010021
A12: 7 | B12: =MID(H12,1,2)&MID(J12,1,2)&MID(L12,1,2)&MID(C12,1,2)&MID(M12,1,1)&MID(N12,1,1)&MID(O12,1,1)&MID(P12,1,3) -> 187240Ma | C12: Marco | D12: 1017006 | E12: 1014000 | F12: 1010022 | G12: =IF(H12<>"","H:","") -> H: | H12: 1800 | I12: =IF(J12<>"","W:","") -> W: | J12: 720 | K12: =IF(L12<>"","D:","") -> D: | L12: 400 | Q12: =IF(B12<>"",(C12&M12&N12&O12&P12&" / "&G12&H12&I12&J12&K12&L12&" mm"),"") -> Marco / H:1800W:720D:400 mm | S12: 1.1.7. | T12: Kit tapa zocalos laterales | U12: Zo | V12: =Z3 -> 60 | W12: Laterales | Z12: =V12&U12&MID(W12,1,1)&MID(X12,1,1)&MID(Y12,1,3) -> 60ZoL | AA12: =VLOOKUP(Z12,$B$6:$D$526,3,FALSE) -> 1010177 | AD12: =AO12&AP12&AQ12&AR12&AS12&AT12&AN12&AU12 -> ICV2VFPW2- | AE12: UF. | AF12: de | AG12: Integrada | AH12: CVS/NSX 250 | AI12: Vertical | AJ12: Fijo | AK12: Palanca | AL12: W:400 | AN12: - | AO12: =MID(AG12,1,1) -> I | AP12: {=IFERROR(_xlfn.IFS(AH12="Mini Breaker ","MB",AH12="GoPact ","GP",AH12="EZC 100 ","EZ1",AH12="EZC 250 ","EZ2",AH12="CVS/NSX 250 ","CV2",AH12="CVS/NSX/EZC 630 ","CV6",AH12="NS 1600 ","NS1",AH12="NW/MTZ 4000 ","NW4",AH12="Conmutador PEQ. ","CP",AH12="Conmutador MED. ","CM",AH12="Conmutador GRA. ","CG",AH12="Contactores ","CK"),"")} -> CV2 | AQ12: {=_xlfn.IFS(AI12="Horizontal ","H",AI12="Horizontal COMPUESTA ","HC",AI12="Vertical ","V",AI12="Vertical Compacta ","VC",AI12="Vertical Extendida ","VE")} -> V | AR12: =MID(AJ12,1,1) -> F | AS12: =MID(AK12,1,1) -> P | AT12: {=IFERROR(_xlfn.IFS(AL12="W:200 ","W1",AL12="W:400 ","W2",AL12="W:720 ","W3",AL12="W:800 ","W4",AL12="W:1120 ","W5"),"")} -> W2 | AU12: {=IFERROR(_xlfn.IFS(AM12="D:400 ","D1",AM12="D:600 ","D2",AM12="D:1000 ","D3"),"")} | AV12: 021133 | AW12: 024004 | AX12: 7 | AY12: =AE12&AF12&AH12&AI12&AJ12&AK12&AL12&AM12&AN12 -> UF. de CVS/NSX 250 Vertical Fijo Palanca W:400 - | BF12: =BG12&BH12&BI12&BJ12 -> 2BHX | BG12: =BG11 -> 2 | BH12: =BH10 -> B | BI12: =BI11 -> H | BJ12: {=IFERROR(_xlfn.IFS(BP12="400 + 400","X",BP12="720","Y",BP12="1120","Z"),"")} -> X | BP12: 400 + 400 | BQ12: 038002 | BR12: NSX | BS12: 048005 | BT12: 048006 | BU12: 048007 | BV12: 048008 | BW12: - | BX12: - | BY12: - | BZ12: - | CA12: - | CB12: - | CC12: - | CD12: - | CF12: =BG12&BH12&CG12&CH12 -> 2BVO | CG12: V | CH12: {=IFERROR(_xlfn.IFS(CJ12="1/4","M",CJ12="1/2","N",CJ12="3/4","O",CJ12="1","P"),"")} -> O | CJ12: 3/4 | CK12: 037006 | CL12: NSX | DD12: 017006 | DE12: =IF(DD12<>"",$DD$4&DD12,"") -> 1017006 | DF12: 014000 | DG12: =IF(DF12<>"",$DD$4&DF12,"") -> 1014000 | DH12: 010022 | DI12: =IF(DH12<>"",$DD$4&DH12,"") -> 1010022
A13: 8 | B13: =MID(H13,1,2)&MID(J13,1,2)&MID(L13,1,2)&MID(C13,1,2)&MID(M13,1,1)&MID(N13,1,1)&MID(O13,1,1)&MID(P13,1,3) -> 187260Ma | C13: Marco | D13: 1017007 | E13: 1014001 | F13: 1010022 | G13: =IF(H13<>"","H:","") -> H: | H13: 1800 | I13: =IF(J13<>"","W:","") -> W: | J13: 720 | K13: =IF(L13<>"","D:","") -> D: | L13: 600 | Q13: =IF(B13<>"",(C13&M13&N13&O13&P13&" / "&G13&H13&I13&J13&K13&L13&" mm"),"") -> Marco / H:1800W:720D:600 mm | S13: 1.1.8. | T13: Kit tapa zocalos Frontales | U13: Zo | V13: =Z2 -> 72 | W13: Frontales | Z13: =V13&U13&MID(W13,1,1)&MID(X13,1,1)&MID(Y13,1,3) -> 72ZoF | AA13: =VLOOKUP(Z13,$B$6:$D$526,3,FALSE) -> 1010178 | AD13: =AO13&AP13&AQ13&AR13&AS13&AT13&AN13&AU13 -> ICV2VFMW2- | AE13: UF. | AF13: de | AG13: Integrada | AH13: CVS/NSX 250 | AI13: Vertical | AJ13: Fijo | AK13: Motorizado | AL13: W:400 | AN13: - | AO13: =MID(AG13,1,1) -> I | AP13: {=IFERROR(_xlfn.IFS(AH13="Mini Breaker ","MB",AH13="GoPact ","GP",AH13="EZC 100 ","EZ1",AH13="EZC 250 ","EZ2",AH13="CVS/NSX 250 ","CV2",AH13="CVS/NSX/EZC 630 ","CV6",AH13="NS 1600 ","NS1",AH13="NW/MTZ 4000 ","NW4",AH13="Conmutador PEQ. ","CP",AH13="Conmutador MED. ","CM",AH13="Conmutador GRA. ","CG",AH13="Contactores ","CK"),"")} -> CV2 | AQ13: {=_xlfn.IFS(AI13="Horizontal ","H",AI13="Horizontal COMPUESTA ","HC",AI13="Vertical ","V",AI13="Vertical Compacta ","VC",AI13="Vertical Extendida ","VE")} -> V | AR13: =MID(AJ13,1,1) -> F | AS13: =MID(AK13,1,1) -> M | AT13: {=IFERROR(_xlfn.IFS(AL13="W:200 ","W1",AL13="W:400 ","W2",AL13="W:720 ","W3",AL13="W:800 ","W4",AL13="W:1120 ","W5"),"")} -> W2 | AU13: {=IFERROR(_xlfn.IFS(AM13="D:400 ","D1",AM13="D:600 ","D2",AM13="D:1000 ","D3"),"")} | AV13: 021134 | AW13: 024004 | AX13: 7 | AY13: =AE13&AF13&AH13&AI13&AJ13&AK13&AL13&AM13&AN13 -> UF. de CVS/NSX 250 Vertical Fijo Motorizado W:400 - | BF13: =BG13&BH13&BI13&BJ13 -> 2BH | BG13: =BG12 -> 2 | BH13: =BH10 -> B | BI13: =BI12 -> H | BJ13: {=IFERROR(_xlfn.IFS(BP13="400 + 400","X",BP13="720","Y",BP13="1120","Z"),"")} | BP13: - | BQ13: - | BR13: NS | BS13: - | BT13: - | BU13: - | BV13: - | BW13: 048009 | BX13: 048009 | BY13: 048009 | BZ13: - | CA13: - | CB13: - | CC13: - | CD13: - | CF13: =BG13&BH13&CG13&CH13 -> 2BVP | CG13: V | CH13: {=IFERROR(_xlfn.IFS(CJ13="1/4","M",CJ13="1/2","N",CJ13="3/4","O",CJ13="1","P"),"")} -> P | CJ13: 1 | CK13: 037007 | CL13: NS | CM13: - | CN13: - | CO13: - | CP13: - | CQ13: 047017 | CR13: 047017 | CS13: 047018 | CT13: - | DD13: 017007 | DE13: =IF(DD13<>"",$DD$4&DD13,"") -> 1017007 | DF13: 014001 | DG13: =IF(DF13<>"",$DD$4&DF13,"") -> 1014001 | DH13: 010022 | DI13: =IF(DH13<>"",$DD$4&DH13,"") -> 1010022
A14: 9 | B14: =MID(H14,1,2)&MID(J14,1,2)&MID(L14,1,2)&MID(C14,1,2)&MID(M14,1,1)&MID(N14,1,1)&MID(O14,1,1)&MID(P14,1,3) -> 187210Ma | C14: Marco | D14: 1017008 | E14: 1014002 | F14: 1010022 | G14: =IF(H14<>"","H:","") -> H: | H14: 1800 | I14: =IF(J14<>"","W:","") -> W: | J14: 720 | K14: =IF(L14<>"","D:","") -> D: | L14: 1000 | Q14: =IF(B14<>"",(C14&M14&N14&O14&P14&" / "&G14&H14&I14&J14&K14&L14&" mm"),"") -> Marco / H:1800W:720D:1000 mm | S14: 1.1.9. | T14: Pane linferior | U14: Pa | V14: =Z2&Z3 -> 7260 | W14: Inferior | Z14: =V14&U14&MID(W14,1,1)&MID(X14,1,1)&MID(Y14,1,3) -> 7260PaI | AA14: =VLOOKUP(Z14,$B$6:$D$526,3,FALSE) -> 1014257 | AD14: =AO14&AP14&AQ14&AR14&AS14&AT14&AN14&AU14 -> ICV2HFPW3- | AE14: UF. | AF14: de | AG14: Integrada | AH14: CVS/NSX 250 | AI14: Horizontal | AJ14: Fijo | AK14: Palanca | AL14: W:720 | AN14: - | AO14: =MID(AG14,1,1) -> I | AP14: {=IFERROR(_xlfn.IFS(AH14="Mini Breaker ","MB",AH14="GoPact ","GP",AH14="EZC 100 ","EZ1",AH14="EZC 250 ","EZ2",AH14="CVS/NSX 250 ","CV2",AH14="CVS/NSX/EZC 630 ","CV6",AH14="NS 1600 ","NS1",AH14="NW/MTZ 4000 ","NW4",AH14="Conmutador PEQ. ","CP",AH14="Conmutador MED. ","CM",AH14="Conmutador GRA. ","CG",AH14="Contactores ","CK"),"")} -> CV2 | AQ14: {=_xlfn.IFS(AI14="Horizontal ","H",AI14="Horizontal COMPUESTA ","HC",AI14="Vertical ","V",AI14="Vertical Compacta ","VC",AI14="Vertical Extendida ","VE")} -> H | AR14: =MID(AJ14,1,1) -> F | AS14: =MID(AK14,1,1) -> P | AT14: {=IFERROR(_xlfn.IFS(AL14="W:200 ","W1",AL14="W:400 ","W2",AL14="W:720 ","W3",AL14="W:800 ","W4",AL14="W:1120 ","W5"),"")} -> W3 | AU14: {=IFERROR(_xlfn.IFS(AM14="D:400 ","D1",AM14="D:600 ","D2",AM14="D:1000 ","D3"),"")} | AV14: 021084 | AW14: 024005 | AX14: 4 | AY14: =AE14&AF14&AH14&AI14&AJ14&AK14&AL14&AM14&AN14 -> UF. de CVS/NSX 250 Horizontal Fijo Palanca W:720 - | BF14: =BG14&BH14&BI14&BJ14 -> 2BH | BG14: =BG13 -> 2 | BH14: =BH10 -> B | BI14: =BI13 -> H | BJ14: {=IFERROR(_xlfn.IFS(BP14="400 + 400","X",BP14="720","Y",BP14="1120","Z"),"")} | BP14: - | BQ14: - | BR14: NW | BS14: - | BT14: - | BU14: - | BV14: - | BW14: 048010 | BX14: 048011 | BY14: 048012 | BZ14: - | CA14: - | CB14: - | CC14: - | CD14: - | CF14: =BG14&BH14&CG14&CH14 -> 2BV | CG14: V | CH14: {=IFERROR(_xlfn.IFS(CJ14="1/4","M",CJ14="1/2","N",CJ14="3/4","O",CJ14="1","P"),"")} | CJ14: - | CK14: - | CL14: - | CM14: - | CN14: - | CO14: - | CP14: - | CQ14: - | CR14: - | CS14: - | CT14: - | DD14: 017008 | DE14: =IF(DD14<>"",$DD$4&DD14,"") -> 1017008 | DF14: 014002 | DG14: =IF(DF14<>"",$DD$4&DF14,"") -> 1014002 | DH14: 010022 | DI14: =IF(DH14<>"",$DD$4&DH14,"") -> 1010022
A15: 10 | B15: =MID(H15,1,2)&MID(J15,1,2)&MID(L15,1,2)&MID(C15,1,2)&MID(M15,1,1)&MID(N15,1,1)&MID(O15,1,1)&MID(P15,1,3) -> 181140Ma | C15: Marco | D15: 1017009 | E15: 1014000 | F15: 1010024 | G15: =IF(H15<>"","H:","") -> H: | H15: 1800 | I15: =IF(J15<>"","W:","") -> W: | J15: 1120 | K15: =IF(L15<>"","D:","") -> D: | L15: 400 | Q15: =IF(B15<>"",(C15&M15&N15&O15&P15&" / "&G15&H15&I15&J15&K15&L15&" mm"),"") -> Marco / H:1800W:1120D:400 mm | S15: 1.1.10. | T15: Paral interno vertical total | U15: PaIV | V15: =Z1 -> 22 | W15: Total | Z15: =V15&U15&MID(W15,1,1)&MID(X15,1,1)&MID(Y15,1,3) -> 22PaIVT | AA15: =VLOOKUP(Z15,$B$6:$D$526,3,FALSE) -> 1014154 | AD15: =AO15&AP15&AQ15&AR15&AS15&AT15&AN15&AU15 -> ICV2HFMW3- | AE15: UF. | AF15: de | AG15: Integrada | AH15: CVS/NSX 250 | AI15: Horizontal | AJ15: Fijo | AK15: Motorizado | AL15: W:720 | AN15: - | AO15: =MID(AG15,1,1) -> I | AP15: {=IFERROR(_xlfn.IFS(AH15="Mini Breaker ","MB",AH15="GoPact ","GP",AH15="EZC 100 ","EZ1",AH15="EZC 250 ","EZ2",AH15="CVS/NSX 250 ","CV2",AH15="CVS/NSX/EZC 630 ","CV6",AH15="NS 1600 ","NS1",AH15="NW/MTZ 4000 ","NW4",AH15="Conmutador PEQ. ","CP",AH15="Conmutador MED. ","CM",AH15="Conmutador GRA. ","CG",AH15="Contactores ","CK"),"")} -> CV2 | AQ15: {=_xlfn.IFS(AI15="Horizontal ","H",AI15="Horizontal COMPUESTA ","HC",AI15="Vertical ","V",AI15="Vertical Compacta ","VC",AI15="Vertical Extendida ","VE")} -> H | AR15: =MID(AJ15,1,1) -> F | AS15: =MID(AK15,1,1) -> M | AT15: {=IFERROR(_xlfn.IFS(AL15="W:200 ","W1",AL15="W:400 ","W2",AL15="W:720 ","W3",AL15="W:800 ","W4",AL15="W:1120 ","W5"),"")} -> W3 | AU15: {=IFERROR(_xlfn.IFS(AM15="D:400 ","D1",AM15="D:600 ","D2",AM15="D:1000 ","D3"),"")} | AV15: 025500 | AW15: 024005 | AX15: 4 | AY15: =AE15&AF15&AH15&AI15&AJ15&AK15&AL15&AM15&AN15 -> UF. de CVS/NSX 250 Horizontal Fijo Motorizado W:720 - | BF15: =BG15&BH15&BI15&BJ15 -> 2CHY | BG15: {=_xlfn.IFS(BN15="10 - 25",1,BN15="10 - 40",2,BN15="10 - 65",3,BN15="10 - 85",4)} -> 2 | BH15: {=_xlfn.IFS(BO15="630","A",BO15="1250","B",BO15="1600","C",BO15="2000","D",BO15="2500","E",BO15="3200","F",BO15="4000","G",BO15="5000","H",BO15="6300","I",BO15="7000","J")} -> C | BI15: H | BJ15: {=IFERROR(_xlfn.IFS(BP15="400 + 400","X",BP15="720","Y",BP15="1120","Z"),"")} -> Y | BN15: 10 - 40 | BO15: 1600 | BP15: 720 | BQ15: 038003 | BR15: EZC | BS15: 048001 | BT15: 048002 | BU15: 048003 | BV15: 048004 | BW15: - | BX15: - | BY15: - | BZ15: - | CA15: - | CB15: - | CC15: - | CD15: - | CF15: =BG15&BH15&CG15&CH15 -> 2CVM | CG15: V | CH15: {=IFERROR(_xlfn.IFS(CJ15="1/4","M",CJ15="1/2","N",CJ15="3/4","O",CJ15="1","P"),"")} -> M | CJ15: 1/4 | CK15: 037008 | CL15: EZC | CM15: 047009 | CN15: 047010 | CO15: 047011 | CP15: 047012 | CQ15: - | CR15: - | CS15: - | CT15: - | DD15: 017009 | DE15: =IF(DD15<>"",$DD$4&DD15,"") -> 1017009 | DF15: 014000 | DG15: =IF(DF15<>"",$DD$4&DF15,"") -> 1014000 | DH15: 010024 | DI15: =IF(DH15<>"",$DD$4&DH15,"") -> 1010024
A16: 11 | B16: =MID(H16,1,2)&MID(J16,1,2)&MID(L16,1,2)&MID(C16,1,2)&MID(M16,1,1)&MID(N16,1,1)&MID(O16,1,1)&MID(P16,1,3) -> 181160Ma | C16: Marco | D16: 1017010 | E16: 1014001 | F16: 1010024 | G16: =IF(H16<>"","H:","") -> H: | H16: 1800 | I16: =IF(J16<>"","W:","") -> W: | J16: 1120 | K16: =IF(L16<>"","D:","") -> D: | L16: 600 | Q16: =IF(B16<>"",(C16&M16&N16&O16&P16&" / "&G16&H16&I16&J16&K16&L16&" mm"),"") -> Marco / H:1800W:1120D:600 mm | S16: 1.1.11. | T16: Paral interno vertical intermedio | U16: PaI | V16: 600 | W16: Vertical | Z16: =MID(V16,1,2)&U16&MID(W16,1,1)&MID(X16,1,1)&MID(Y16,1,3) -> 60PaIV | AA16: =VLOOKUP(Z16,$B$6:$D$526,3,FALSE) -> #N/A | AD16: =AO16&AP16&AQ16&AR16&AS16&AT16&AN16&AU16 -> ICV2HFPW3DPS | AE16: UF. | AF16: de | AG16: Integrada | AH16: CVS/NSX 250 | AI16: Horizontal | AJ16: Fijo | AK16: Palanca | AL16: W:720 | AN16: DPS | AO16: =MID(AG16,1,1) -> I | AP16: {=IFERROR(_xlfn.IFS(AH16="Mini Breaker ","MB",AH16="GoPact ","GP",AH16="EZC 100 ","EZ1",AH16="EZC 250 ","EZ2",AH16="CVS/NSX 250 ","CV2",AH16="CVS/NSX/EZC 630 ","CV6",AH16="NS 1600 ","NS1",AH16="NW/MTZ 4000 ","NW4",AH16="Conmutador PEQ. ","CP",AH16="Conmutador MED. ","CM",AH16="Conmutador GRA. ","CG",AH16="Contactores ","CK"),"")} -> CV2 | AQ16: {=_xlfn.IFS(AI16="Horizontal ","H",AI16="Horizontal COMPUESTA ","HC",AI16="Vertical ","V",AI16="Vertical Compacta ","VC",AI16="Vertical Extendida ","VE")} -> H | AR16: =MID(AJ16,1,1) -> F | AS16: =MID(AK16,1,1) -> P | AT16: {=IFERROR(_xlfn.IFS(AL16="W:200 ","W1",AL16="W:400 ","W2",AL16="W:720 ","W3",AL16="W:800 ","W4",AL16="W:1120 ","W5"),"")} -> W3 | AU16: {=IFERROR(_xlfn.IFS(AM16="D:400 ","D1",AM16="D:600 ","D2",AM16="D:1000 ","D3"),"")} | AV16: 021085 | AW16: 024006 | AX16: 4 | AY16: =AE16&AF16&AH16&AI16&AJ16&AK16&AL16&AM16&AN16 -> UF. de CVS/NSX 250 Horizontal Fijo Palanca W:720 DPS | BF16: =BG16&BH16&BI16&BJ16 -> 2CHZ | BG16: =BG15 -> 2 | BH16: =BH15 -> C | BI16: =BI15 -> H | BJ16: {=IFERROR(_xlfn.IFS(BP16="400 + 400","X",BP16="720","Y",BP16="1120","Z"),"")} -> Z | BP16: 1120 | BQ16: 038004 | BR16: CVS | BS16: 048005 | BT16: 048006 | BU16: 048007 | BV16: 048008 | BW16: - | BX16: - | BY16: - | BZ16: - | CA16: - | CB16: - | CC16: - | CD16: - | CF16: =BG16&BH16&CG16&CH16 -> 2CVN | CG16: V | CH16: {=IFERROR(_xlfn.IFS(CJ16="1/4","M",CJ16="1/2","N",CJ16="3/4","O",CJ16="1","P"),"")} -> N | CJ16: 1/2 | CK16: 037009 | CL16: CVS | CM16: 047013 | CN16: 047014 | CO16: 047015 | CP16: 047016 | CQ16: - | CR16: - | CS16: - | CT16: - | DD16: 017010 | DE16: =IF(DD16<>"",$DD$4&DD16,"") -> 1017010 | DF16: 014001 | DG16: =IF(DF16<>"",$DD$4&DF16,"") -> 1014001 | DH16: 010024 | DI16: =IF(DH16<>"",$DD$4&DH16,"") -> 1010024
A17: 12 | B17: =MID(H17,1,2)&MID(J17,1,2)&MID(L17,1,2)&MID(C17,1,2)&MID(M17,1,1)&MID(N17,1,1)&MID(O17,1,1)&MID(P17,1,3) -> 181110Ma | C17: Marco | D17: 1017011 | E17: 1014002 | F17: 1010024 | G17: =IF(H17<>"","H:","") -> H: | H17: 1800 | I17: =IF(J17<>"","W:","") -> W: | J17: 1120 | K17: =IF(L17<>"","D:","") -> D: | L17: 1000 | Q17: =IF(B17<>"",(C17&M17&N17&O17&P17&" / "&G17&H17&I17&J17&K17&L17&" mm"),"") -> Marco / H:1800W:1120D:1000 mm | S17: 1.1.12. | T17: Paral interno horizontal | U17: PaI | V17: 600 | W17: Horizontal | Z17: =MID(V17,1,2)&U17&MID(W17,1,1)&MID(X17,1,1)&MID(Y17,1,3) -> 60PaIH | AA17: =VLOOKUP(Z17,$B$6:$D$526,3,FALSE) -> 1010285 | AD17: =AO17&AP17&AQ17&AR17&AS17&AT17&AN17&AU17 -> ICV2HFPW3HWA | AE17: UF. | AF17: de | AG17: Integrada | AH17: CVS/NSX 250 | AI17: Horizontal | AJ17: Fijo | AK17: Palanca | AL17: W:720 | AN17: HWA | AO17: =MID(AG17,1,1) -> I | AP17: {=IFERROR(_xlfn.IFS(AH17="Mini Breaker ","MB",AH17="GoPact ","GP",AH17="EZC 100 ","EZ1",AH17="EZC 250 ","EZ2",AH17="CVS/NSX 250 ","CV2",AH17="CVS/NSX/EZC 630 ","CV6",AH17="NS 1600 ","NS1",AH17="NW/MTZ 4000 ","NW4",AH17="Conmutador PEQ. ","CP",AH17="Conmutador MED. ","CM",AH17="Conmutador GRA. ","CG",AH17="Contactores ","CK"),"")} -> CV2 | AQ17: {=_xlfn.IFS(AI17="Horizontal ","H",AI17="Horizontal COMPUESTA ","HC",AI17="Vertical ","V",AI17="Vertical Compacta ","VC",AI17="Vertical Extendida ","VE")} -> H | AR17: =MID(AJ17,1,1) -> F | AS17: =MID(AK17,1,1) -> P | AT17: {=IFERROR(_xlfn.IFS(AL17="W:200 ","W1",AL17="W:400 ","W2",AL17="W:720 ","W3",AL17="W:800 ","W4",AL17="W:1120 ","W5"),"")} -> W3 | AU17: {=IFERROR(_xlfn.IFS(AM17="D:400 ","D1",AM17="D:600 ","D2",AM17="D:1000 ","D3"),"")} | AV17: 021087 | AW17: 024007 | AX17: 4 | AY17: =AE17&AF17&AH17&AI17&AJ17&AK17&AL17&AM17&AN17 -> UF. de CVS/NSX 250 Horizontal Fijo Palanca W:720 HWA | BF17: =BG17&BH17&BI17&BJ17 -> 2CHX | BG17: =BG16 -> 2 | BH17: =BH16 -> C | BI17: =BI16 -> H | BJ17: {=IFERROR(_xlfn.IFS(BP17="400 + 400","X",BP17="720","Y",BP17="1120","Z"),"")} -> X | BP17: 400 + 400 | BQ17: 038005 | BR17: NSX | BS17: 048005 | BT17: 048006 | BU17: 048007 | BV17: 048008 | BW17: - | BX17: - | BY17: - | BZ17: - | CA17: - | CB17: - | CC17: - | CD17: - | CF17: =BG17&BH17&CG17&CH17 -> 2CVO | CG17: V | CH17: {=IFERROR(_xlfn.IFS(CJ17="1/4","M",CJ17="1/2","N",CJ17="3/4","O",CJ17="1","P"),"")} -> O | CJ17: 3/4 | CK17: 037010 | CL17: NSX | DD17: 017011 | DE17: =IF(DD17<>"",$DD$4&DD17,"") -> 1017011 | DF17: 014002 | DG17: =IF(DF17<>"",$DD$4&DF17,"") -> 1014002 | DH17: 010024 | DI17: =IF(DH17<>"",$DD$4&DH17,"") -> 1010024
A18: 13 | B18: =MID(H18,1,2)&MID(J18,1,2)&MID(L18,1,2)&MID(C18,1,2)&MID(M18,1,1)&MID(N18,1,1)&MID(O18,1,1)&MID(P18,1,3) -> 202040Ma | C18: Marco | D18: 1017012 | E18: 1014003 | F18: 1010020 | G18: =IF(H18<>"","H:","") -> H: | H18: 2000 | I18: =IF(J18<>"","W:","") -> W: | J18: 200 | K18: =IF(L18<>"","D:","") -> D: | L18: 400 | Q18: =IF(B18<>"",(C18&M18&N18&O18&P18&" / "&G18&H18&I18&J18&K18&L18&" mm"),"") -> Marco / H:2000W:200D:400 mm | S18: 1.1.13. | T18: Ducto de cables | U18: DuC | V18: =Z2 -> 72 | Z18: =V18&U18&MID(W18,1,1)&MID(X18,1,1)&MID(Y18,1,3) -> 72DuC | AA18: =VLOOKUP(Z18,$B$6:$D$526,3,FALSE) -> 1014301 | AD18: =AO18&AP18&AQ18&AR18&AS18&AT18&AN18&AU18 -> ICV2HCFPW3- | AE18: UF. | AF18: de | AG18: Integrada | AH18: CVS/NSX 250 | AI18: Horizontal COMPUESTA | AJ18: Fijo | AK18: Palanca | AL18: W:720 | AN18: - | AO18: =MID(AG18,1,1) -> I | AP18: {=IFERROR(_xlfn.IFS(AH18="Mini Breaker ","MB",AH18="GoPact ","GP",AH18="EZC 100 ","EZ1",AH18="EZC 250 ","EZ2",AH18="CVS/NSX 250 ","CV2",AH18="CVS/NSX/EZC 630 ","CV6",AH18="NS 1600 ","NS1",AH18="NW/MTZ 4000 ","NW4",AH18="Conmutador PEQ. ","CP",AH18="Conmutador MED. ","CM",AH18="Conmutador GRA. ","CG",AH18="Contactores ","CK"),"")} -> CV2 | AQ18: {=_xlfn.IFS(AI18="Horizontal ","H",AI18="Horizontal COMPUESTA ","HC",AI18="Vertical ","V",AI18="Vertical Compacta ","VC",AI18="Vertical Extendida ","VE")} -> HC | AR18: =MID(AJ18,1,1) -> F | AS18: =MID(AK18,1,1) -> P | AT18: {=IFERROR(_xlfn.IFS(AL18="W:200 ","W1",AL18="W:400 ","W2",AL18="W:720 ","W3",AL18="W:800 ","W4",AL18="W:1120 ","W5"),"")} -> W3 | AU18: {=IFERROR(_xlfn.IFS(AM18="D:400 ","D1",AM18="D:600 ","D2",AM18="D:1000 ","D3"),"")} | AV18: 021061 | AW18: 024005 | AX18: 4 | AY18: =AE18&AF18&AH18&AI18&AJ18&AK18&AL18&AM18&AN18 -> UF. de CVS/NSX 250 Horizontal COMPUESTA Fijo Palanca W:720 - | BF18: =BG18&BH18&BI18&BJ18 -> 2CH | BG18: =BG17 -> 2 | BH18: =BH17 -> C | BI18: =BI17 -> H | BJ18: {=IFERROR(_xlfn.IFS(BP18="400 + 400","X",BP18="720","Y",BP18="1120","Z"),"")} | BP18: - | BQ18: - | BR18: NS | BS18: - | BT18: - | BU18: - | BV18: - | BW18: 048009 | BX18: 048009 | BY18: 048009 | BZ18: 048013 | CA18: - | CB18: - | CC18: - | CD18: - | CF18: =BG18&BH18&CG18&CH18 -> 2CVP | CG18: V | CH18: {=IFERROR(_xlfn.IFS(CJ18="1/4","M",CJ18="1/2","N",CJ18="3/4","O",CJ18="1","P"),"")} -> P | CJ18: 1 | CK18: 037011 | CL18: NS | CM18: - | CN18: - | CO18: - | CP18: - | CQ18: 047017 | CR18: 047017 | CS18: 047018 | CT18: 047019 | DD18: 017012 | DE18: =IF(DD18<>"",$DD$4&DD18,"") -> 1017012 | DF18: 014003 | DG18: =IF(DF18<>"",$DD$4&DF18,"") -> 1014003 | DH18: 010020 | DI18: =IF(DH18<>"",$DD$4&DH18,"") -> 1010020
A19: 14 | B19: =MID(H19,1,2)&MID(J19,1,2)&MID(L19,1,2)&MID(C19,1,2)&MID(M19,1,1)&MID(N19,1,1)&MID(O19,1,1)&MID(P19,1,3) -> 202060Ma | C19: Marco | D19: 1017013 | E19: 1014004 | F19: 1010020 | G19: =IF(H19<>"","H:","") -> H: | H19: 2000 | I19: =IF(J19<>"","W:","") -> W: | J19: 200 | K19: =IF(L19<>"","D:","") -> D: | L19: 600 | Q19: =IF(B19<>"",(C19&M19&N19&O19&P19&" / "&G19&H19&I19&J19&K19&L19&" mm"),"") -> Marco / H:2000W:200D:600 mm | S19: 1.1.14. | T19: Kit union posterior | U19: Ki | W19: Union | Z19: =V19&U19&MID(W19,1,1)&MID(X19,1,1)&MID(Y19,1,3) -> KiU | AA19: =VLOOKUP(Z19,$B$6:$D$526,3,FALSE) -> #N/A | AD19: =AO19&AP19&AQ19&AR19&AS19&AT19&AN19&AU19 -> ICV2HCFMW3- | AE19: UF. | AF19: de | AG19: Integrada | AH19: CVS/NSX 250 | AI19: Horizontal COMPUESTA | AJ19: Fijo | AK19: Motorizado | AL19: W:720 | AN19: - | AO19: =MID(AG19,1,1) -> I | AP19: {=IFERROR(_xlfn.IFS(AH19="Mini Breaker ","MB",AH19="GoPact ","GP",AH19="EZC 100 ","EZ1",AH19="EZC 250 ","EZ2",AH19="CVS/NSX 250 ","CV2",AH19="CVS/NSX/EZC 630 ","CV6",AH19="NS 1600 ","NS1",AH19="NW/MTZ 4000 ","NW4",AH19="Conmutador PEQ. ","CP",AH19="Conmutador MED. ","CM",AH19="Conmutador GRA. ","CG",AH19="Contactores ","CK"),"")} -> CV2 | AQ19: {=_xlfn.IFS(AI19="Horizontal ","H",AI19="Horizontal COMPUESTA ","HC",AI19="Vertical ","V",AI19="Vertical Compacta ","VC",AI19="Vertical Extendida ","VE")} -> HC | AR19: =MID(AJ19,1,1) -> F | AS19: =MID(AK19,1,1) -> M | AT19: {=IFERROR(_xlfn.IFS(AL19="W:200 ","W1",AL19="W:400 ","W2",AL19="W:720 ","W3",AL19="W:800 ","W4",AL19="W:1120 ","W5"),"")} -> W3 | AU19: {=IFERROR(_xlfn.IFS(AM19="D:400 ","D1",AM19="D:600 ","D2",AM19="D:1000 ","D3"),"")} | AV19: 025501 | AW19: 024005 | AX19: 4 | AY19: =AE19&AF19&AH19&AI19&AJ19&AK19&AL19&AM19&AN19 -> UF. de CVS/NSX 250 Horizontal COMPUESTA Fijo Motorizado W:720 - | BF19: =BG19&BH19&BI19&BJ19 -> 2CH | BG19: =BG18 -> 2 | BH19: =BH18 -> C | BI19: =BI18 -> H | BJ19: {=IFERROR(_xlfn.IFS(BP19="400 + 400","X",BP19="720","Y",BP19="1120","Z"),"")} | BP19: - | BQ19: - | BR19: NW | BS19: - | BT19: - | BU19: - | BV19: - | BW19: 048010 | BX19: 048011 | BY19: 048012 | BZ19: - | CA19: - | CB19: - | CC19: - | CD19: - | CF19: =BG19&BH19&CG19&CH19 -> 2CV | CG19: V | CH19: {=IFERROR(_xlfn.IFS(CJ19="1/4","M",CJ19="1/2","N",CJ19="3/4","O",CJ19="1","P"),"")} | CJ19: - | CK19: - | CL19: - | CM19: - | CN19: - | CO19: - | CP19: - | CQ19: - | CR19: - | CS19: - | CT19: - | DD19: 017013 | DE19: =IF(DD19<>"",$DD$4&DD19,"") -> 1017013 | DF19: 014004 | DG19: =IF(DF19<>"",$DD$4&DF19,"") -> 1014004 | DH19: 010020 | DI19: =IF(DH19<>"",$DD$4&DH19,"") -> 1010020
A20: 15 | B20: =MID(H20,1,2)&MID(J20,1,2)&MID(L20,1,2)&MID(C20,1,2)&MID(M20,1,1)&MID(N20,1,1)&MID(O20,1,1)&MID(P20,1,3) -> 202010Ma | C20: Marco | D20: 1017014 | E20: 1014005 | F20: 1010020 | G20: =IF(H20<>"","H:","") -> H: | H20: 2000 | I20: =IF(J20<>"","W:","") -> W: | J20: 200 | K20: =IF(L20<>"","D:","") -> D: | L20: 1000 | Q20: =IF(B20<>"",(C20&M20&N20&O20&P20&" / "&G20&H20&I20&J20&K20&L20&" mm"),"") -> Marco / H:2000W:200D:1000 mm | S20: 1.1.15. | T20: Segregación frontal* | U20: Se | V20: =Z1&Z2 -> 2272 | W20: Frontales | Z20: =V20&U20&MID(W20,1,1)&MID(X20,1,1)&MID(Y20,1,3) -> 2272SeF | AA20: =VLOOKUP(Z20,$B$6:$D$526,3,FALSE) -> #N/A | AD20: =AO20&AP20&AQ20&AR20&AS20&AT20&AN20&AU20 -> IEZ1VCFPW3- | AE20: UF. | AF20: de | AG20: Integrada | AH20: EZC 100 | AI20: Vertical Compacta | AJ20: Fijo | AK20: Palanca | AL20: W:720 | AN20: - | AO20: =MID(AG20,1,1) -> I | AP20: {=IFERROR(_xlfn.IFS(AH20="Mini Breaker ","MB",AH20="GoPact ","GP",AH20="EZC 100 ","EZ1",AH20="EZC 250 ","EZ2",AH20="CVS/NSX 250 ","CV2",AH20="CVS/NSX/EZC 630 ","CV6",AH20="NS 1600 ","NS1",AH20="NW/MTZ 4000 ","NW4",AH20="Conmutador PEQ. ","CP",AH20="Conmutador MED. ","CM",AH20="Conmutador GRA. ","CG",AH20="Contactores ","CK"),"")} -> EZ1 | AQ20: {=_xlfn.IFS(AI20="Horizontal ","H",AI20="Horizontal COMPUESTA ","HC",AI20="Vertical ","V",AI20="Vertical Compacta ","VC",AI20="Vertical Extendida ","VE")} -> VC | AR20: =MID(AJ20,1,1) -> F | AS20: =MID(AK20,1,1) -> P | AT20: {=IFERROR(_xlfn.IFS(AL20="W:200 ","W1",AL20="W:400 ","W2",AL20="W:720 ","W3",AL20="W:800 ","W4",AL20="W:1120 ","W5"),"")} -> W3 | AU20: {=IFERROR(_xlfn.IFS(AM20="D:400 ","D1",AM20="D:600 ","D2",AM20="D:1000 ","D3"),"")} | AV20: 021102 | AW20: 024008 | AX20: 6 | AY20: =AE20&AF20&AH20&AI20&AJ20&AK20&AL20&AM20&AN20 -> UF. de EZC 100 Vertical Compacta Fijo Palanca W:720 - | BF20: =BG20&BH20&BI20&BJ20 -> 3DHY | BG20: {=_xlfn.IFS(BN20="10 - 25",1,BN20="10 - 40",2,BN20="10 - 65",3,BN20="10 - 85",4)} -> 3 | BH20: {=_xlfn.IFS(BO20="630","A",BO20="1250","B",BO20="1600","C",BO20="2000","D",BO20="2500","E",BO20="3200","F",BO20="4000","G",BO20="5000","H",BO20="6300","I",BO20="7000","J")} -> D | BI20: H | BJ20: {=IFERROR(_xlfn.IFS(BP20="400 + 400","X",BP20="720","Y",BP20="1120","Z"),"")} -> Y | BL20: TM | BN20: 10 - 65 | BO20: 2000 | BP20: 720 | BQ20: 038006 | BR20: - | BS20: - | BT20: - | BU20: - | BV20: - | BW20: - | BX20: - | BY20: - | BZ20: - | CA20: - | CB20: - | CC20: - | CD20: - | CF20: =BG20&BH20&CG20&CH20 -> 3DVM | CG20: V | CH20: {=IFERROR(_xlfn.IFS(CJ20="1/4","M",CJ20="1/2","N",CJ20="3/4","O",CJ20="1","P"),"")} -> M | CJ20: 1/4 | CK20: 037012 | CL20: EZC | CM20: 047020 | CN20: 047021 | CO20: 047022 | CP20: 047023 | CQ20: - | CR20: - | CS20: - | CT20: - | DD20: 017014 | DE20: =IF(DD20<>"",$DD$4&DD20,"") -> 1017014 | DF20: 014005 | DG20: =IF(DF20<>"",$DD$4&DF20,"") -> 1014005 | DH20: 010020 | DI20: =IF(DH20<>"",$DD$4&DH20,"") -> 1010020
A21: 16 | B21: =MID(H21,1,2)&MID(J21,1,2)&MID(L21,1,2)&MID(C21,1,2)&MID(M21,1,1)&MID(N21,1,1)&MID(O21,1,1)&MID(P21,1,3) -> 204040Ma | C21: Marco | D21: 1017015 | E21: 1014003 | F21: 1010021 | G21: =IF(H21<>"","H:","") -> H: | H21: 2000 | I21: =IF(J21<>"","W:","") -> W: | J21: 400 | K21: =IF(L21<>"","D:","") -> D: | L21: 400 | Q21: =IF(B21<>"",(C21&M21&N21&O21&P21&" / "&G21&H21&I21&J21&K21&L21&" mm"),"") -> Marco / H:2000W:400D:400 mm | AD21: =AO21&AP21&AQ21&AR21&AS21&AT21&AN21&AU21 -> IEZ1VEFPW3- | AE21: UF. | AF21: de | AG21: Integrada | AH21: EZC 100 | AI21: Vertical Extendida | AJ21: Fijo | AK21: Palanca | AL21: W:720 | AN21: - | AO21: =MID(AG21,1,1) -> I | AP21: {=IFERROR(_xlfn.IFS(AH21="Mini Breaker ","MB",AH21="GoPact ","GP",AH21="EZC 100 ","EZ1",AH21="EZC 250 ","EZ2",AH21="CVS/NSX 250 ","CV2",AH21="CVS/NSX/EZC 630 ","CV6",AH21="NS 1600 ","NS1",AH21="NW/MTZ 4000 ","NW4",AH21="Conmutador PEQ. ","CP",AH21="Conmutador MED. ","CM",AH21="Conmutador GRA. ","CG",AH21="Contactores ","CK"),"")} -> EZ1 | AQ21: {=_xlfn.IFS(AI21="Horizontal ","H",AI21="Horizontal COMPUESTA ","HC",AI21="Vertical ","V",AI21="Vertical Compacta ","VC",AI21="Vertical Extendida ","VE")} -> VE | AR21: =MID(AJ21,1,1) -> F | AS21: =MID(AK21,1,1) -> P | AT21: {=IFERROR(_xlfn.IFS(AL21="W:200 ","W1",AL21="W:400 ","W2",AL21="W:720 ","W3",AL21="W:800 ","W4",AL21="W:1120 ","W5"),"")} -> W3 | AU21: {=IFERROR(_xlfn.IFS(AM21="D:400 ","D1",AM21="D:600 ","D2",AM21="D:1000 ","D3"),"")} | AV21: 021104 | AW21: 024009 | AX21: 6 | AY21: =AE21&AF21&AH21&AI21&AJ21&AK21&AL21&AM21&AN21 -> UF. de EZC 100 Vertical Extendida Fijo Palanca W:720 - | BF21: =BG21&BH21&BI21&BJ21 -> 3DHZ | BG21: =BG20 -> 3 | BH21: =BH20 -> D | BI21: =BI20 -> H | BJ21: {=IFERROR(_xlfn.IFS(BP21="400 + 400","X",BP21="720","Y",BP21="1120","Z"),"")} -> Z | BP21: 1120 | BQ21: 038007 | BR21: - | BS21: - | BT21: - | BU21: - | BV21: - | BW21: - | BX21: - | BY21: - | BZ21: - | CA21: - | CB21: - | CC21: - | CD21: - | CF21: =BG21&BH21&CG21&CH21 -> 3DVN | CG21: V | CH21: {=IFERROR(_xlfn.IFS(CJ21="1/4","M",CJ21="1/2","N",CJ21="3/4","O",CJ21="1","P"),"")} -> N | CJ21: 1/2 | CK21: 037013 | CL21: CVS | CM21: 047024 | CN21: 047025 | CO21: 047026 | CP21: 047027 | CQ21: - | CR21: - | CS21: - | CT21: - | DD21: 017015 | DE21: =IF(DD21<>"",$DD$4&DD21,"") -> 1017015 | DF21: 014003 | DG21: =IF(DF21<>"",$DD$4&DF21,"") -> 1014003 | DH21: 010021 | DI21: =IF(DH21<>"",$DD$4&DH21,"") -> 1010021
A22: 17 | B22: =MID(H22,1,2)&MID(J22,1,2)&MID(L22,1,2)&MID(C22,1,2)&MID(M22,1,1)&MID(N22,1,1)&MID(O22,1,1)&MID(P22,1,3) -> 204060Ma | C22: Marco | D22: 1017016 | E22: 1014004 | F22: 1010021 | G22: =IF(H22<>"","H:","") -> H: | H22: 2000 | I22: =IF(J22<>"","W:","") -> W: | J22: 400 | K22: =IF(L22<>"","D:","") -> D: | L22: 600 | Q22: =IF(B22<>"",(C22&M22&N22&O22&P22&" / "&G22&H22&I22&J22&K22&L22&" mm"),"") -> Marco / H:2000W:400D:600 mm | S22: 1.2.1. | T22: Hablador | Z22: =V22&U22&MID(W22,1,1)&MID(X22,1,1)&MID(Y22,1,3) | AA22: SinReferencia | AD22: =AO22&AP22&AQ22&AR22&AS22&AT22&AN22&AU22 -> IEZ1HFPW3- | AE22: UF. | AF22: de | AG22: Integrada | AH22: EZC 100 | AI22: Horizontal | AJ22: Fijo | AK22: Palanca | AL22: W:720 | AN22: - | AO22: =MID(AG22,1,1) -> I | AP22: {=IFERROR(_xlfn.IFS(AH22="Mini Breaker ","MB",AH22="GoPact ","GP",AH22="EZC 100 ","EZ1",AH22="EZC 250 ","EZ2",AH22="CVS/NSX 250 ","CV2",AH22="CVS/NSX/EZC 630 ","CV6",AH22="NS 1600 ","NS1",AH22="NW/MTZ 4000 ","NW4",AH22="Conmutador PEQ. ","CP",AH22="Conmutador MED. ","CM",AH22="Conmutador GRA. ","CG",AH22="Contactores ","CK"),"")} -> EZ1 | AQ22: {=_xlfn.IFS(AI22="Horizontal ","H",AI22="Horizontal COMPUESTA ","HC",AI22="Vertical ","V",AI22="Vertical Compacta ","VC",AI22="Vertical Extendida ","VE")} -> H | AR22: =MID(AJ22,1,1) -> F | AS22: =MID(AK22,1,1) -> P | AT22: {=IFERROR(_xlfn.IFS(AL22="W:200 ","W1",AL22="W:400 ","W2",AL22="W:720 ","W3",AL22="W:800 ","W4",AL22="W:1120 ","W5"),"")} -> W3 | AU22: {=IFERROR(_xlfn.IFS(AM22="D:400 ","D1",AM22="D:600 ","D2",AM22="D:1000 ","D3"),"")} | AV22: 021075 | AW22: 024010 | AX22: 3 | AY22: =AE22&AF22&AH22&AI22&AJ22&AK22&AL22&AM22&AN22 -> UF. de EZC 100 Horizontal Fijo Palanca W:720 - | BF22: =BG22&BH22&BI22&BJ22 -> 3DH | BG22: =BG21 -> 3 | BH22: =BH21 -> D | BI22: =BI21 -> H | BJ22: {=IFERROR(_xlfn.IFS(BP22="400 + 400","X",BP22="720","Y",BP22="1120","Z"),"")} | BP22: - | BQ22: - | BR22: - | BS22: - | BT22: - | BU22: - | BV22: - | BW22: - | BX22: - | BY22: - | BZ22: - | CA22: - | CB22: - | CC22: - | CD22: - | CF22: =BG22&BH22&CG22&CH22 -> 3DVO | CG22: V | CH22: {=IFERROR(_xlfn.IFS(CJ22="1/4","M",CJ22="1/2","N",CJ22="3/4","O",CJ22="1","P"),"")} -> O | CJ22: 3/4 | CK22: 037014 | CL22: NSX | DD22: 017016 | DE22: =IF(DD22<>"",$DD$4&DD22,"") -> 1017016 | DF22: 014004 | DG22: =IF(DF22<>"",$DD$4&DF22,"") -> 1014004 | DH22: 010021 | DI22: =IF(DH22<>"",$DD$4&DH22,"") -> 1010021
A23: 18 | B23: =MID(H23,1,2)&MID(J23,1,2)&MID(L23,1,2)&MID(C23,1,2)&MID(M23,1,1)&MID(N23,1,1)&MID(O23,1,1)&MID(P23,1,3) -> 204010Ma | C23: Marco | D23: 1017017 | E23: 1014005 | F23: 1010021 | G23: =IF(H23<>"","H:","") -> H: | H23: 2000 | I23: =IF(J23<>"","W:","") -> W: | J23: 400 | K23: =IF(L23<>"","D:","") -> D: | L23: 1000 | Q23: =IF(B23<>"",(C23&M23&N23&O23&P23&" / "&G23&H23&I23&J23&K23&L23&" mm"),"") -> Marco / H:2000W:400D:1000 mm | S23: 1.2.2. | T23: Kit de cancamos | U23: CaE | Z23: =V23&U23&MID(W23,1,1)&MID(X23,1,1)&MID(Y23,1,3) -> CaE | AA23: =VLOOKUP(Z23,$B$6:$D$526,3,FALSE) -> 1014501 | AD23: =AO23&AP23&AQ23&AR23&AS23&AT23&AN23&AU23 -> IEZ1HFPW3DPS | AE23: UF. | AF23: de | AG23: Integrada | AH23: EZC 100 | AI23: Horizontal | AJ23: Fijo | AK23: Palanca | AL23: W:720 | AN23: DPS | AO23: =MID(AG23,1,1) -> I | AP23: {=IFERROR(_xlfn.IFS(AH23="Mini Breaker ","MB",AH23="GoPact ","GP",AH23="EZC 100 ","EZ1",AH23="EZC 250 ","EZ2",AH23="CVS/NSX 250 ","CV2",AH23="CVS/NSX/EZC 630 ","CV6",AH23="NS 1600 ","NS1",AH23="NW/MTZ 4000 ","NW4",AH23="Conmutador PEQ. ","CP",AH23="Conmutador MED. ","CM",AH23="Conmutador GRA. ","CG",AH23="Contactores ","CK"),"")} -> EZ1 | AQ23: {=_xlfn.IFS(AI23="Horizontal ","H",AI23="Horizontal COMPUESTA ","HC",AI23="Vertical ","V",AI23="Vertical Compacta ","VC",AI23="Vertical Extendida ","VE")} -> H | AR23: =MID(AJ23,1,1) -> F | AS23: =MID(AK23,1,1) -> P | AT23: {=IFERROR(_xlfn.IFS(AL23="W:200 ","W1",AL23="W:400 ","W2",AL23="W:720 ","W3",AL23="W:800 ","W4",AL23="W:1120 ","W5"),"")} -> W3 | AU23: {=IFERROR(_xlfn.IFS(AM23="D:400 ","D1",AM23="D:600 ","D2",AM23="D:1000 ","D3"),"")} | AV23: 021055 | AW23: 024011 | AX23: 4 | AY23: =AE23&AF23&AH23&AI23&AJ23&AK23&AL23&AM23&AN23 -> UF. de EZC 100 Horizontal Fijo Palanca W:720 DPS | BF23: =BG23&BH23&BI23&BJ23 -> 3DH | BG23: =BG22 -> 3 | BH23: =BH22 -> D | BI23: =BI22 -> H | BJ23: {=IFERROR(_xlfn.IFS(BP23="400 + 400","X",BP23="720","Y",BP23="1120","Z"),"")} | BP23: - | BQ23: - | BR23: - | BS23: - | BT23: - | BU23: - | BV23: - | BW23: - | BX23: - | BY23: - | BZ23: - | CA23: - | CB23: - | CC23: - | CD23: - | CF23: =BG23&BH23&CG23&CH23 -> 3DVP | CG23: V | CH23: {=IFERROR(_xlfn.IFS(CJ23="1/4","M",CJ23="1/2","N",CJ23="3/4","O",CJ23="1","P"),"")} -> P | CJ23: 1 | CK23: 037015 | CL23: NS | CM23: - | CN23: - | CO23: - | CP23: - | CQ23: 047028 | CR23: 047028 | CS23: 047029 | CT23: 047030 | DD23: 017017 | DE23: =IF(DD23<>"",$DD$4&DD23,"") -> 1017017 | DF23: 014005 | DG23: =IF(DF23<>"",$DD$4&DF23,"") -> 1014005 | DH23: 010021 | DI23: =IF(DH23<>"",$DD$4&DH23,"") -> 1010021
A24: 19 | B24: =MID(H24,1,2)&MID(J24,1,2)&MID(L24,1,2)&MID(C24,1,2)&MID(M24,1,1)&MID(N24,1,1)&MID(O24,1,1)&MID(P24,1,3) -> 207240Ma | C24: Marco | D24: 1017018 | E24: 1014003 | F24: 1010022 | G24: =IF(H24<>"","H:","") -> H: | H24: 2000 | I24: =IF(J24<>"","W:","") -> W: | J24: 720 | K24: =IF(L24<>"","D:","") -> D: | L24: 400 | Q24: =IF(B24<>"",(C24&M24&N24&O24&P24&" / "&G24&H24&I24&J24&K24&L24&" mm"),"") -> Marco / H:2000W:720D:400 mm | S24: 1.2.3. | T24: Angulo de izaje | U24: AnI | Z24: =V24&U24&MID(W24,1,1)&MID(X24,1,1)&MID(Y24,1,3) -> AnI | AA24: =VLOOKUP(Z24,$B$6:$D$526,3,FALSE) -> 1014502 | AD24: =AO24&AP24&AQ24&AR24&AS24&AT24&AN24&AU24 -> IEZ1HFPW3HWA | AE24: UF. | AF24: de | AG24: Integrada | AH24: EZC 100 | AI24: Horizontal | AJ24: Fijo | AK24: Palanca | AL24: W:720 | AN24: HWA | AO24: =MID(AG24,1,1) -> I | AP24: {=IFERROR(_xlfn.IFS(AH24="Mini Breaker ","MB",AH24="GoPact ","GP",AH24="EZC 100 ","EZ1",AH24="EZC 250 ","EZ2",AH24="CVS/NSX 250 ","CV2",AH24="CVS/NSX/EZC 630 ","CV6",AH24="NS 1600 ","NS1",AH24="NW/MTZ 4000 ","NW4",AH24="Conmutador PEQ. ","CP",AH24="Conmutador MED. ","CM",AH24="Conmutador GRA. ","CG",AH24="Contactores ","CK"),"")} -> EZ1 | AQ24: {=_xlfn.IFS(AI24="Horizontal ","H",AI24="Horizontal COMPUESTA ","HC",AI24="Vertical ","V",AI24="Vertical Compacta ","VC",AI24="Vertical Extendida ","VE")} -> H | AR24: =MID(AJ24,1,1) -> F | AS24: =MID(AK24,1,1) -> P | AT24: {=IFERROR(_xlfn.IFS(AL24="W:200 ","W1",AL24="W:400 ","W2",AL24="W:720 ","W3",AL24="W:800 ","W4",AL24="W:1120 ","W5"),"")} -> W3 | AU24: {=IFERROR(_xlfn.IFS(AM24="D:400 ","D1",AM24="D:600 ","D2",AM24="D:1000 ","D3"),"")} | AV24: 021076 | AW24: 024012 | AX24: 4 | AY24: =AE24&AF24&AH24&AI24&AJ24&AK24&AL24&AM24&AN24 -> UF. de EZC 100 Horizontal Fijo Palanca W:720 HWA | BF24: =BG24&BH24&BI24&BJ24 -> 3DH | BG24: =BG23 -> 3 | BH24: =BH23 -> D | BI24: =BI23 -> H | BJ24: {=IFERROR(_xlfn.IFS(BP24="400 + 400","X",BP24="720","Y",BP24="1120","Z"),"")} | BR24: NW | BS24: - | BT24: - | BU24: - | BV24: - | BW24: 048014 | BX24: 048015 | BY24: 048016 | BZ24: 048017 | CA24: 048018 | CB24: - | CC24: - | CD24: - | CF24: =BG24&BH24&CG24&CH24 -> 3DV | CG24: V | CH24: {=IFERROR(_xlfn.IFS(CJ24="1/4","M",CJ24="1/2","N",CJ24="3/4","O",CJ24="1","P"),"")} | CJ24: - | CK24: - | CL24: - | CM24: - | CN24: - | CO24: - | CP24: - | CQ24: - | CR24: - | CS24: - | CT24: - | DD24: 017018 | DE24: =IF(DD24<>"",$DD$4&DD24,"") -> 1017018 | DF24: 014003 | DG24: =IF(DF24<>"",$DD$4&DF24,"") -> 1014003 | DH24: 010022 | DI24: =IF(DH24<>"",$DD$4&DH24,"") -> 1010022
A25: 20 | B25: =MID(H25,1,2)&MID(J25,1,2)&MID(L25,1,2)&MID(C25,1,2)&MID(M25,1,1)&MID(N25,1,1)&MID(O25,1,1)&MID(P25,1,3) -> 207260Ma | C25: Marco | D25: 1017019 | E25: 1014004 | F25: 1010022 | G25: =IF(H25<>"","H:","") -> H: | H25: 2000 | I25: =IF(J25<>"","W:","") -> W: | J25: 720 | K25: =IF(L25<>"","D:","") -> D: | L25: 600 | Q25: =IF(B25<>"",(C25&M25&N25&O25&P25&" / "&G25&H25&I25&J25&K25&L25&" mm"),"") -> Marco / H:2000W:720D:600 mm | S25: 1.2.4. | T25: Grua | Z25: =V25&U25&MID(W25,1,1)&MID(X25,1,1)&MID(Y25,1,3) | AA25: SinReferencia | AD25: =AO25&AP25&AQ25&AR25&AS25&AT25&AN25&AU25 -> IEZ2VCFPW3- | AE25: UF. | AF25: de | AG25: Integrada | AH25: EZC 250 | AI25: Vertical Compacta | AJ25: Fijo | AK25: Palanca | AL25: W:720 | AN25: - | AO25: =MID(AG25,1,1) -> I | AP25: {=IFERROR(_xlfn.IFS(AH25="Mini Breaker ","MB",AH25="GoPact ","GP",AH25="EZC 100 ","EZ1",AH25="EZC 250 ","EZ2",AH25="CVS/NSX 250 ","CV2",AH25="CVS/NSX/EZC 630 ","CV6",AH25="NS 1600 ","NS1",AH25="NW/MTZ 4000 ","NW4",AH25="Conmutador PEQ. ","CP",AH25="Conmutador MED. ","CM",AH25="Conmutador GRA. ","CG",AH25="Contactores ","CK"),"")} -> EZ2 | AQ25: {=_xlfn.IFS(AI25="Horizontal ","H",AI25="Horizontal COMPUESTA ","HC",AI25="Vertical ","V",AI25="Vertical Compacta ","VC",AI25="Vertical Extendida ","VE")} -> VC | AR25: =MID(AJ25,1,1) -> F | AS25: =MID(AK25,1,1) -> P | AT25: {=IFERROR(_xlfn.IFS(AL25="W:200 ","W1",AL25="W:400 ","W2",AL25="W:720 ","W3",AL25="W:800 ","W4",AL25="W:1120 ","W5"),"")} -> W3 | AU25: {=IFERROR(_xlfn.IFS(AM25="D:400 ","D1",AM25="D:600 ","D2",AM25="D:1000 ","D3"),"")} | AV25: 021106 | AW25: 024013 | AX25: 7 | AY25: =AE25&AF25&AH25&AI25&AJ25&AK25&AL25&AM25&AN25 -> UF. de EZC 250 Vertical Compacta Fijo Palanca W:720 - | BF25: =BG25&BH25&BI25&BJ25 -> 3EHY | BG25: {=_xlfn.IFS(BN25="10 - 25",1,BN25="10 - 40",2,BN25="10 - 65",3,BN25="10 - 85",4)} -> 3 | BH25: {=_xlfn.IFS(BO25="630","A",BO25="1250","B",BO25="1600","C",BO25="2000","D",BO25="2500","E",BO25="3200","F",BO25="4000","G",BO25="5000","H",BO25="6300","I",BO25="7000","J")} -> E | BI25: H | BJ25: {=IFERROR(_xlfn.IFS(BP25="400 + 400","X",BP25="720","Y",BP25="1120","Z"),"")} -> Y | BN25: 10 - 65 | BO25: 2500 | BP25: 720 | BQ25: 038008 | BR25: - | BS25: - | BT25: - | BU25: - | BV25: - | BW25: - | BX25: - | BY25: - | BZ25: - | CA25: - | CB25: - | CC25: - | CD25: - | CF25: =BG25&BH25&CG25&CH25 -> 3EVM | CG25: V | CH25: {=IFERROR(_xlfn.IFS(CJ25="1/4","M",CJ25="1/2","N",CJ25="3/4","O",CJ25="1","P"),"")} -> M | CJ25: 1/4 | CK25: 037016 | CL25: EZC | CM25: 047020 | CN25: 047021 | CO25: 047022 | CP25: 047023 | CQ25: - | CR25: - | CS25: - | CT25: - | DD25: 017019 | DE25: =IF(DD25<>"",$DD$4&DD25,"") -> 1017019 | DF25: 014004 | DG25: =IF(DF25<>"",$DD$4&DF25,"") -> 1014004 | DH25: 010022 | DI25: =IF(DH25<>"",$DD$4&DH25,"") -> 1010022
A26: 21 | B26: =MID(H26,1,2)&MID(J26,1,2)&MID(L26,1,2)&MID(C26,1,2)&MID(M26,1,1)&MID(N26,1,1)&MID(O26,1,1)&MID(P26,1,3) -> 207210Ma | C26: Marco | D26: 1017020 | E26: 1014005 | F26: 1010022 | G26: =IF(H26<>"","H:","") -> H: | H26: 2000 | I26: =IF(J26<>"","W:","") -> W: | J26: 720 | K26: =IF(L26<>"","D:","") -> D: | L26: 1000 | Q26: =IF(B26<>"",(C26&M26&N26&O26&P26&" / "&G26&H26&I26&J26&K26&L26&" mm"),"") -> Marco / H:2000W:720D:1000 mm | AD26: =AO26&AP26&AQ26&AR26&AS26&AT26&AN26&AU26 -> IEZ2VEFPW3- | AE26: UF. | AF26: de | AG26: Integrada | AH26: EZC 250 | AI26: Vertical Extendida | AJ26: Fijo | AK26: Palanca | AL26: W:720 | AN26: - | AO26: =MID(AG26,1,1) -> I | AP26: {=IFERROR(_xlfn.IFS(AH26="Mini Breaker ","MB",AH26="GoPact ","GP",AH26="EZC 100 ","EZ1",AH26="EZC 250 ","EZ2",AH26="CVS/NSX 250 ","CV2",AH26="CVS/NSX/EZC 630 ","CV6",AH26="NS 1600 ","NS1",AH26="NW/MTZ 4000 ","NW4",AH26="Conmutador PEQ. ","CP",AH26="Conmutador MED. ","CM",AH26="Conmutador GRA. ","CG",AH26="Contactores ","CK"),"")} -> EZ2 | AQ26: {=_xlfn.IFS(AI26="Horizontal ","H",AI26="Horizontal COMPUESTA ","HC",AI26="Vertical ","V",AI26="Vertical Compacta ","VC",AI26="Vertical Extendida ","VE")} -> VE | AR26: =MID(AJ26,1,1) -> F | AS26: =MID(AK26,1,1) -> P | AT26: {=IFERROR(_xlfn.IFS(AL26="W:200 ","W1",AL26="W:400 ","W2",AL26="W:720 ","W3",AL26="W:800 ","W4",AL26="W:1120 ","W5"),"")} -> W3 | AU26: {=IFERROR(_xlfn.IFS(AM26="D:400 ","D1",AM26="D:600 ","D2",AM26="D:1000 ","D3"),"")} | AV26: 021108 | AW26: 024014 | AX26: 7 | AY26: =AE26&AF26&AH26&AI26&AJ26&AK26&AL26&AM26&AN26 -> UF. de EZC 250 Vertical Extendida Fijo Palanca W:720 - | BF26: =BG26&BH26&BI26&BJ26 -> 3EHZ | BG26: =BG25 -> 3 | BH26: =BH25 -> E | BI26: =BI25 -> H | BJ26: {=IFERROR(_xlfn.IFS(BP26="400 + 400","X",BP26="720","Y",BP26="1120","Z"),"")} -> Z | BP26: 1120 | BQ26: 038009 | BR26: - | BS26: - | BT26: - | BU26: - | BV26: - | BW26: - | BX26: - | BY26: - | BZ26: - | CA26: - | CB26: - | CC26: - | CD26: - | CF26: =BG26&BH26&CG26&CH26 -> 3EVN | CG26: V | CH26: {=IFERROR(_xlfn.IFS(CJ26="1/4","M",CJ26="1/2","N",CJ26="3/4","O",CJ26="1","P"),"")} -> N | CJ26: 1/2 | CK26: 037017 | CL26: CVS | CM26: 047024 | CN26: 047025 | CO26: 047026 | CP26: 047027 | CQ26: - | CR26: - | CS26: - | CT26: - | DD26: 017020 | DE26: =IF(DD26<>"",$DD$4&DD26,"") -> 1017020 | DF26: 014005 | DG26: =IF(DF26<>"",$DD$4&DF26,"") -> 1014005 | DH26: 010022 | DI26: =IF(DH26<>"",$DD$4&DH26,"") -> 1010022
A27: 22 | B27: =MID(H27,1,2)&MID(J27,1,2)&MID(L27,1,2)&MID(C27,1,2)&MID(M27,1,1)&MID(N27,1,1)&MID(O27,1,1)&MID(P27,1,3) -> 208060Ma | C27: Marco | D27: 1017021 | E27: 1014004 | F27: 1010023 | G27: =IF(H27<>"","H:","") -> H: | H27: 2000 | I27: =IF(J27<>"","W:","") -> W: | J27: 800 | K27: =IF(L27<>"","D:","") -> D: | L27: 600 | Q27: =IF(B27<>"",(C27&M27&N27&O27&P27&" / "&G27&H27&I27&J27&K27&L27&" mm"),"") -> Marco / H:2000W:800D:600 mm | S27: 1.3.1. | T27: Cubierta para modulo | AA27: SinReferencia | AD27: =AO27&AP27&AQ27&AR27&AS27&AT27&AN27&AU27 -> IEZ2HFPW3- | AE27: UF. | AF27: de | AG27: Integrada | AH27: EZC 250 | AI27: Horizontal | AJ27: Fijo | AK27: Palanca | AL27: W:720 | AN27: - | AO27: =MID(AG27,1,1) -> I | AP27: {=IFERROR(_xlfn.IFS(AH27="Mini Breaker ","MB",AH27="GoPact ","GP",AH27="EZC 100 ","EZ1",AH27="EZC 250 ","EZ2",AH27="CVS/NSX 250 ","CV2",AH27="CVS/NSX/EZC 630 ","CV6",AH27="NS 1600 ","NS1",AH27="NW/MTZ 4000 ","NW4",AH27="Conmutador PEQ. ","CP",AH27="Conmutador MED. ","CM",AH27="Conmutador GRA. ","CG",AH27="Contactores ","CK"),"")} -> EZ2 | AQ27: {=_xlfn.IFS(AI27="Horizontal ","H",AI27="Horizontal COMPUESTA ","HC",AI27="Vertical ","V",AI27="Vertical Compacta ","VC",AI27="Vertical Extendida ","VE")} -> H | AR27: =MID(AJ27,1,1) -> F | AS27: =MID(AK27,1,1) -> P | AT27: {=IFERROR(_xlfn.IFS(AL27="W:200 ","W1",AL27="W:400 ","W2",AL27="W:720 ","W3",AL27="W:800 ","W4",AL27="W:1120 ","W5"),"")} -> W3 | AU27: {=IFERROR(_xlfn.IFS(AM27="D:400 ","D1",AM27="D:600 ","D2",AM27="D:1000 ","D3"),"")} | AV27: 021078 | AW27: 024015 | AX27: 4 | AY27: =AE27&AF27&AH27&AI27&AJ27&AK27&AL27&AM27&AN27 -> UF. de EZC 250 Horizontal Fijo Palanca W:720 - | BF27: =BG27&BH27&BI27&BJ27 -> 3EH | BG27: =BG26 -> 3 | BH27: =BH26 -> E | BI27: =BI26 -> H | BJ27: {=IFERROR(_xlfn.IFS(BP27="400 + 400","X",BP27="720","Y",BP27="1120","Z"),"")} | BP27: - | BQ27: - | BR27: - | BS27: - | BT27: - | BU27: - | BV27: - | BW27: - | BX27: - | BY27: - | BZ27: - | CA27: - | CB27: - | CC27: - | CD27: - | CF27: =BG27&BH27&CG27&CH27 -> 3EVO | CG27: V | CH27: {=IFERROR(_xlfn.IFS(CJ27="1/4","M",CJ27="1/2","N",CJ27="3/4","O",CJ27="1","P"),"")} -> O | CJ27: 3/4 | CK27: 037018 | CL27: NSX | DD27: 017021 | DE27: =IF(DD27<>"",$DD$4&DD27,"") -> 1017021 | DF27: 014004 | DG27: =IF(DF27<>"",$DD$4&DF27,"") -> 1014004 | DH27: 010023 | DI27: =IF(DH27<>"",$DD$4&DH27,"") -> 1010023
